Workbook

Sheet BAPR 
B10: BERITA ACARA PEMBAYARAN RETENSI (BAPR)
B11: =DATA!$B$32
Q12: =DATA!$B$35 | R12: ="("&TEXT($Q$12,"[$-21]dd mmmm yyyy")&")"
B13: ="Pada hari ini "&Q13&" tanggal "&Q14&" bulan "&Q15&" tahun "&Q16&" "&R12&", kami yang bertandatangan di bawah ini:" | Q13: =DATA!$B$55
Q14: =DATA!$B$56
B15: 1. | C15: =DATA!$B$69 | F15: : | G15: ="Selaku "&DATA!$B$70&", "&DATA!$B$7&", dalam hal ini bertindak untuk dan atas nama "&DATA!$B$17&", yang berkedudukan di "&DATA!$B$18&", (selanjutnya disebut sebagai PIHAK PERTAMA)." | Q15: =DATA!$B$57
Q16: =DATA!$B$58
B17: 2. | C17: =DATA!$B$22 | F17: : | G17: ="Selaku "&DATA!$B$23&" "&DATA!$B$24&", dalam hal ini bertindak untuk dan atas nama "&DATA!$B$24&" yang berkedudukan di "&DATA!$B$25&", (selanjutnya disebut sebagai PIHAK KEDUA)."
B19: ="Menerangkan bahwa kedua belah pihak telah melakukan pemeriksaan atas "&DATA!$B$6&" untuk "&DATA!$B$7&", dan berdasarkan :"
B21: - | C21: Kontrak dan Tanggal | F21: : | G21: =DATA!$B$4 | K21: Tanggal : | L21: =TEXT(DATA!$B$5,"[$-21]dd mmmm yyyy")
B22: - | C22: Nilai Kontrak | F22: : | G22: =#REF!
B23: - | C23: Waktu Pelaksanaan | F23: : | G23: =TEXT(DATA!$B$8,"[$-21]dd mmmm yyyy") | I23: s/d | J23: =TEXT(DATA!$B$9,"[$-21]dd mmmm yyyy")
B24: - | C24: Berita Acara Serah Terima Pertama | F24: : | G24: ="01/BAST/"&G21 | K24: Tanggal : | L24: =TEXT(DATA!$B$34,"[$-21]dd mmmm yyyy")
B26: - | C26: Uang Muka | F26: : | G26: =DATA!$B$45 | H26: x | I26: =G22 | K26: = | L26: =+G26*I26
B27: - | C27: Retensi | F27: : | G27: =DATA!$B$44 | H27: x | I27: =$I$26 | K27: = | L27: =+G27*I27
B29: ="Menyatakan bahwa masa pemeliharaan atas Surat Perjanjian Konsultan Perencana (SPKP) tersebut diatas telah selesai sesuai BAST, maka Pihak Kedua berhak menerima pembayaran Retensi "&TEXT(DATA!$B$44*100,"General")&" % dengan perincian sebagai berikut :"
B30: Pembayaran Retensi : | G30: BAP | H30: TGL | J30: PROGRESS BAP | O30: Retensi
J31: Saat ini | L31: S/d. Saat Ini | N31: Progress | O31: =DATA!$B$44
B32: - | C32: Atas Potongan Retensi pada : | G32: BAP 1 | H32: =INDEX(DATA!$B$99:$B$104,1) | J32: ='BAP 1'!Q33 | L32: =J32 | N32: =+L32/$I$26 | O32: =+J32*$O$31
G33: BAP 2 | H33: =INDEX(DATA!$B$99:$B$104,2) | J33: ='BAP 2'!Q33 | L33: =J33+L32 | N33: =+L33/$I$26 | O33: =+J33*$O$31
G34: BAP 3 | H34: =INDEX(DATA!$B$99:$B$104,3) | J34: ='BAP 3'!Q33 | L34: =J34+L33 | N34: =+L34/$I$26 | O34: =+J34*$O$31
G35: BAP 4 | H35: =INDEX(DATA!$B$99:$B$104,4) | J35: ='BAP 4'!Q33 | L35: =J35+L34 | N35: =+L35/$I$26 | O35: =+J35*$O$31
G36: BAP 5 | H36: =INDEX(DATA!$B$99:$B$104,5) | J36: ='BAP 5'!Q33 | L36: =J36+L35 | N36: =+L36/$I$26 | O36: =+J36*$O$31
G37: BAP 6 | H37: =INDEX(DATA!$B$99:$B$104,6) | J37: ='BAP 6'!Q33 | L37: =J37+L36 | N37: =+L37/$I$26 | O37: =+J37*$O$31
G38: JUMLAH RETENSI | O38: =SUM(O32:O37)
B40: a) | C40: Perhitungan Pembayaran Retensi :
C41: Hutang Retensi s/d saat ini | H41: : | I41: 1 | J41: x | K41: =O38 | N41: = | O41: =I41*K41
C42: Pembayaran Retensi Periode yang lalu | H42: : | I42: =O42/K42 | J42: x | K42: =K41 | N42: = | O42: 0
C43: Pembayaran Retensi saat ini | H43: : | I43: =I41-I42 | J43: x | K43: =K42 | N43: = | O43: =O41-O42
C44: Pajak Pertambahan Nilai (PPN) | H44: : | N44: = | O44: =ROUNDDOWN($O$43*DATA!$B$11,0)
C46: Jumlah | O46: =O43+O44
B49: Terbilang | D49: : | E49: =" == "&PROPER(IF(O46=0,"nol",IF(O46<0,"minus ","")& SUBSTITUTE(TRIM(SUBSTITUTE(SUBSTITUTE(SUBSTITUTE(SUBSTITUTE(SUBSTITUTE(SUBSTITUTE(SUBSTITUTE(SUBSTITUTE(SUBSTITUTE(SUBSTITUTE(SUBSTITUTE(SUBSTITUTE(SUBSTITUTE(SUBSTITUTE(SUBSTITUTE(SUBSTITUTE(SUBSTITUTE(SUBSTITUTE(SUBSTITUTE(SUBSTITUTE(SUBSTITUTE(SUBSTITUTE(SUBSTITUTE(SUBSTITUTE( IF(--MID(TEXT(ABS(O46),"000000000000000"),1,3)=0,"",MID(TEXT(ABS(O46),"000000000000000"),1,1)&" ratus "&MID(TEXT(ABS(O46),"000000000000000"),2,1)&" puluh "&MID(TEXT(ABS(O46),"000000000000000"),3,1)&" trilyun ")& IF(--MID(TEXT(ABS(O46),"000000000000000"),4,3)=0,"",MID(TEXT(ABS(O46),"000000000000000"),4,1)&" ratus "&MID(TEXT(ABS(O46),"000000000000000"),5,1)&" puluh "&MID(TEXT(ABS(O46),"000000000000000"),6,1)&" milyar ")& IF(--MID(TEXT(ABS(O46),"000000000000000"),7,3)=0,"",MID(TEXT(ABS(O46),"000000000000000"),7,1)&" ratus "&MID(TEXT(ABS(O46),"000000000000000"),8,1)&" puluh "&MID(TEXT(ABS(O46),"000000000000000"),9,1)&" juta ")& IF(--MID(TEXT(ABS(O46),"000000000000000"),10,3)=0,"",IF(--MID(TEXT(ABS(O46),"000000000000000"),10,3)=1,"*",MID(TEXT(ABS(O46),"000000000000000"),10,1)&" ratus "&MID(TEXT(ABS(O46),"000000000000000"),11,1)&" puluh ")&MID(TEXT(ABS(O46),"000000000000000"),12,1)&" ribu ")& IF(--MID(TEXT(ABS(O46),"000000000000000"),13,3)=0,"",MID(TEXT(ABS(O46),"000000000000000"),13,1)&" ratus "&MID(TEXT(ABS(O46),"000000000000000"),14,1)&" puluh "&MID(TEXT(ABS(O46),"000000000000000"),15,1)),1,"satu"),2,"dua"),3,"tiga"),4,"empat"),5,"lima"),6,"enam"),7,"tujuh"),8,"delapan"),9,"sembilan"),"0 ratus",""),"0 puluh",""),"satu puluh 0","sepuluh"),"satu puluh satu","sebelas"),"satu puluh dua","dua belas"),"satu puluh tiga","tiga belas"),"satu puluh empat","empat belas"),"satu puluh lima","lima belas"),"satu puluh enam","enam belas"),"satu puluh tujuh","tujuh belas"),"satu puluh delapan","delapan belas"),"satu puluh sembilan","sembilan belas"),"satu ratus","seratus"),"*satu ribu","seribu"),0,""))," "," ")))&" Rupiah =="
B51: Demikian Berita Acara Pembayaran Retensi ini dibuat untuk dapat dipergunakan sebagaimana mestinya.
B55: PIHAK KEDUA | M55: PIHAK PERTAMA
B56: =UPPER(DATA!$B$24) | M56: =UPPER(DATA!$B$17)
B67: =DATA!$B$22 | M67: =DATA!$B$69
B68: =DATA!$B$23 | M68: =DATA!$B$70
Q71: =O46 | R71: Masukan data
R73: bil asli
R74: =ROUNDUP(Q71,0)
...

Sheet BAP  1
T3: {=INDEX(DATA!$B$99:$B$104,$T$9)} | V3: =TEXT($T$3,"[$-21]dd mmmm yyyy") | W3: =TEXT($T3,"[$-21]dd mmmm yyyy")
T4: =TEXT($T$3,"[$-21]dddd")
T5: =VLOOKUP(DAY($T$3),HELPER!$A$2:$B$100,2,0)
T6: =TEXT($T$3,"[$-21]mmmm")
T7: ="Dua Ribu"&IF(MOD(YEAR($T$3),100)=0,""," "&VLOOKUP(MOD(YEAR($T$3),100),HELPER!$A$2:$B$100,2,0))
T8: TERMIN SHEET INI (1-6)
T9: 1
C10: BERITA ACARA PEMBAYARAN (BAP)
C11: =TEXT($T$9,"00")&"/BAP/"&DATA!$B$4
C13: ="Pada hari ini "&T4&" tanggal "&T5&" bulan "&T6&" tahun "&T7&" ("&V3&"), kami yang bertandatangan di bawah ini:"
C15: 1 | D15: =DATA!$B$69 | I15: : | J15: ="Selaku "&DATA!$B$70&", "&DATA!$B$7&", dalam hal ini bertindak untuk dan atas nama "&DATA!$B$17&" yang berkedudukan di "&DATA!$B$18&" (selanjutnya disebut sebagai PIHAK PERTAMA)."
C16: 2 | D16: =DATA!$B$22 | I16: : | J16: ="Selaku "&DATA!$B$23&" "&DATA!$B$24&", dalam hal ini bertindak untuk dan atas nama "&DATA!$B$24&" yang berkedudukan di "&DATA!$B$25&" (selanjutnya disebut sebagai PIHAK KEDUA)."
C18: ="Menerangkan bahwa kedua belah pihak, telah melakukan pemeriksaan atas "&DATA!$B$6&" pada "&DATA!$B$7&", dan berdasarkan :"
D20: Kontrak / SPK No. dan Tanggal | J20: : | K20: =DATA!$B$4 | N20: Tanggal : | P20: =TEXT(DATA!$B$5,"[$-21]dd mmmm yyyy")
D21: Addendum | J21: : | K21: -
D22: Pekerjaan / Pengadaan | J22: : | K22: =DATA!$B$6
D23: Jangka Waktu Pelaksanaan | J23: : | K23: =TEXT(DATA!$B$8,"[$-21]dd mmmm yyyy") | M23: s/d. | N23: =TEXT(DATA!$B$9,"[$-21]dd mmmm yyyy")
D24: Nilai Kontrak | J24: : | K24: =lamp1!K41 | P24: (Exclude PPN)
D25: Nilai Addendum I | J25: : | K25: 0 | P25: (Exclude PPN 10%)
D26: Uang Muka | J26: : | K26: =DATA!$B$46
D27: Retensi | J27: : | K27: =DATA!$B$47
C28: ="Menyatakan bahwa prestasi pekerjaan yang dicapai oleh PIHAK KEDUA sampai dengan tanggal "&TEXT($T$3,"[$-21]dd mmmm yyyy")&" adalah "&TEXT(BAPP!$K$66,"0.00%")&" sesuai dengan Berita Acara Pemeriksaan Pekerjaan No. "&BAPP!$B$10&", dengan rincian sebagai berikut :"
C29: a | D29: Perhitungan Pembayaran | M29: `
C30: - | D30: Prestasi s/d saat ini | I30: = | J30: =J32+J31 | L30: x | M30: =$K$24 | N30: = | P30: =J30*M30
C31: - | D31: Prestasi yang lalu | I31: = | J31: ='rincian '!T38 | L31: x | M31: =$K$24 | N31: = | P31: =J31*M31
C32: - | D32: Prestasi saat ini | I32: = | J32: =BAPP!K66 | L32: x | M32: =$K$24 | N32: = | P32: =J32*M32
Q33: =P32
C34: b | D34: Potongan Retensi
D35: Potongan Retensi s/d saat ini | I35: = | J35: =$K$27 | L35: x | M35: =M36+M37 | N35: = | P35: =ROUND(J35*M35,0)
D36: Potongan Retensi yang lalu | I36: = | J36: 0 | L36: x | M36: 0 | N36: = | P36: =J36*M36
D37: Potongan Retensi saat ini | I37: = | J37: 0.05 | L37: x | M37: =P32 | N37: = | P37: =ROUND(J37*M37,0)
Q38: =P37
C39: c | D39: Pengembalian Uang Muka
D40: Pengembalian Uang Muka s/d saat ini | I40: = | J40: =$K$26 | L40: x | M40: =M42+M41 | N40: = | P40: =ROUND(J40*M40,0)
D41: Pengembalian Uang Muka yang lalu | I41: = | J41: 0 | L41: x | M41: 0 | N41: = | P41: =J41*M41
D42: Pengembalian Uang saat ini | I42: = | J42: 0 | L42: x | M42: =Q33 | N42: = | P42: =ROUND(J42*M42,0)
Q43: =P42
C45: d. | D45: Potongan Pembayaran
Q47: =SUM(P46)
D48: JUMLAH SETELAH DIKURANGI RETENSI, UANG MUKA (a-b-c) | Q48: =ROUND((Q33-Q38-Q43-Q47),0)
...

Sheet BAP  2
T3: {=INDEX(DATA!$B$99:$B$104,$T$9)} | V3: =TEXT($T$3,"[$-21]dd mmmm yyyy") | W3: =TEXT($T3,"[$-21]dd mmmm yyyy")
T4: =TEXT($T$3,"[$-21]dddd")
T5: =VLOOKUP(DAY($T$3),HELPER!$A$2:$B$100,2,0)
T6: =TEXT($T$3,"[$-21]mmmm")
T7: ="Dua Ribu"&IF(MOD(YEAR($T$3),100)=0,""," "&VLOOKUP(MOD(YEAR($T$3),100),HELPER!$A$2:$B$100,2,0))
T8: TERMIN SHEET INI (1-6)
T9: 2
C10: BERITA ACARA PEMBAYARAN (BAP)
C11: =TEXT($T$9,"00")&"/BAP/"&DATA!$B$4
C13: ="Pada hari ini "&T4&" tanggal "&T5&" bulan "&T6&" tahun "&T7&" ("&V3&"), kami yang bertandatangan di bawah ini:"
C15: 1 | D15: =DATA!$B$69 | I15: : | J15: ="Selaku "&DATA!$B$70&", "&DATA!$B$7&", dalam hal ini bertindak untuk dan atas nama "&DATA!$B$17&" yang berkedudukan di "&DATA!$B$18&" (selanjutnya disebut sebagai PIHAK PERTAMA)."
C16: 2 | D16: =DATA!$B$22 | I16: : | J16: ="Selaku "&DATA!$B$23&" "&DATA!$B$24&", dalam hal ini bertindak untuk dan atas nama "&DATA!$B$24&" yang berkedudukan di "&DATA!$B$25&" (selanjutnya disebut sebagai PIHAK KEDUA)."
C18: ="Menerangkan bahwa kedua belah pihak, telah melakukan pemeriksaan atas "&DATA!$B$6&" pada "&DATA!$B$7&", dan berdasarkan :"
D20: Kontrak / SPK No. dan Tanggal | J20: : | K20: =DATA!$B$4 | N20: Tanggal : | P20: =TEXT(DATA!$B$5,"[$-21]dd mmmm yyyy")
D21: Addendum | J21: : | K21: -
D22: Pekerjaan / Pengadaan | J22: : | K22: =DATA!$B$6
D23: Jangka Waktu Pelaksanaan | J23: : | K23: =TEXT(DATA!$B$8,"[$-21]dd mmmm yyyy") | M23: s/d. | N23: =TEXT(DATA!$B$9,"[$-21]dd mmmm yyyy")
D24: Nilai Kontrak | J24: : | K24: =#REF! | P24: (Exclude PPN)
D25: Nilai Addendum I | J25: : | K25: 0 | P25: (Exclude PPN 10%)
D26: Uang Muka | J26: : | K26: =DATA!$B$46
D27: Retensi | J27: : | K27: =DATA!$B$47
C28: ="Menyatakan bahwa prestasi pekerjaan yang dicapai oleh PIHAK KEDUA sampai dengan tanggal "&TEXT($T$3,"[$-21]dd mmmm yyyy")&" adalah "&TEXT('BAPP 2'!$K$194,"0.00%")&" sesuai dengan Berita Acara Pemeriksaan Pekerjaan No. "&'BAPP 2'!$B$10&", dengan rincian sebagai berikut :"
C29: a | D29: Perhitungan Pembayaran | M29: `
C30: - | D30: Prestasi s/d saat ini | I30: = | J30: =J32+J31 | L30: x | M30: =$K$24 | N30: = | P30: =J30*M30
C31: - | D31: Prestasi yang lalu | I31: = | J31: ='rincian 2'!T166 | L31: x | M31: =$K$24 | N31: = | P31: =J31*M31
C32: - | D32: Prestasi saat ini | I32: = | J32: ='BAPP 2'!K194 | L32: x | M32: =$K$24 | N32: = | P32: =J32*M32
Q33: =P32
C34: b | D34: Potongan Retensi
D35: Potongan Retensi s/d saat ini | I35: = | J35: =$K$27 | L35: x | M35: =M36+M37 | N35: = | P35: =ROUND(J35*M35,0)
D36: Potongan Retensi yang lalu | I36: = | J36: 0 | L36: x | M36: 0 | N36: = | P36: =J36*M36
D37: Potongan Retensi saat ini | I37: = | J37: 0 | L37: x | M37: =P32 | N37: = | P37: =ROUND(J37*M37,0)
Q38: =P37
C39: c | D39: Pengembalian Uang Muka
D40: Pengembalian Uang Muka s/d saat ini | I40: = | J40: =$K$26 | L40: x | M40: =M42+M41 | N40: = | P40: =ROUND(J40*M40,0)
D41: Pengembalian Uang Muka yang lalu | I41: = | J41: 0 | L41: x | M41: 0 | N41: = | P41: =J41*M41
D42: Pengembalian Uang saat ini | I42: = | J42: 0 | L42: x | M42: =Q33 | N42: = | P42: =ROUND(J42*M42,0)
Q43: =P42
C45: d. | D45: Potongan Pembayaran
Q47: =SUM(P46)
D48: JUMLAH SETELAH DIKURANGI RETENSI, UANG MUKA (a-b-c) | Q48: =ROUND((Q33-Q38-Q43-Q47),0)
...

Sheet BAP  3
T3: {=INDEX(DATA!$B$99:$B$104,$T$9)} | V3: =TEXT($T$3,"[$-21]dd mmmm yyyy") | W3: =TEXT($T3,"[$-21]dd mmmm yyyy")
T4: =TEXT($T$3,"[$-21]dddd")
T5: =VLOOKUP(DAY($T$3),HELPER!$A$2:$B$100,2,0)
T6: =TEXT($T$3,"[$-21]mmmm")
T7: ="Dua Ribu"&IF(MOD(YEAR($T$3),100)=0,""," "&VLOOKUP(MOD(YEAR($T$3),100),HELPER!$A$2:$B$100,2,0))
T8: TERMIN SHEET INI (1-6)
T9: 3
C10: BERITA ACARA PEMBAYARAN (BAP)
C11: =TEXT($T$9,"00")&"/BAP/"&DATA!$B$4
C13: ="Pada hari ini "&T4&" tanggal "&T5&" bulan "&T6&" tahun "&T7&" ("&V3&"), kami yang bertandatangan di bawah ini:"
C15: 1 | D15: =DATA!$B$69 | I15: : | J15: ="Selaku "&DATA!$B$70&", "&DATA!$B$7&", dalam hal ini bertindak untuk dan atas nama "&DATA!$B$17&" yang berkedudukan di "&DATA!$B$18&" (selanjutnya disebut sebagai PIHAK PERTAMA)."
C16: 2 | D16: =DATA!$B$22 | I16: : | J16: ="Selaku "&DATA!$B$23&" "&DATA!$B$24&", dalam hal ini bertindak untuk dan atas nama "&DATA!$B$24&" yang berkedudukan di "&DATA!$B$25&" (selanjutnya disebut sebagai PIHAK KEDUA)."
C18: ="Menerangkan bahwa kedua belah pihak, telah melakukan pemeriksaan atas "&DATA!$B$6&" pada "&DATA!$B$7&", dan berdasarkan :"
D20: Kontrak / SPK No. dan Tanggal | J20: : | K20: =DATA!$B$4 | N20: Tanggal : | P20: =TEXT(DATA!$B$5,"[$-21]dd mmmm yyyy")
D21: Addendum | J21: : | K21: -
D22: Pekerjaan / Pengadaan | J22: : | K22: =DATA!$B$6
D23: Jangka Waktu Pelaksanaan | J23: : | K23: =TEXT(DATA!$B$8,"[$-21]dd mmmm yyyy") | M23: s/d. | N23: =TEXT(DATA!$B$9,"[$-21]dd mmmm yyyy")
D24: Nilai Kontrak | J24: : | K24: =#REF! | P24: (Exclude PPN)
D25: Nilai Addendum I | J25: : | K25: 0 | P25: (Exclude PPN 10%)
D26: Uang Muka | J26: : | K26: =DATA!$B$46
D27: Retensi | J27: : | K27: =DATA!$B$47
C28: ="Menyatakan bahwa prestasi pekerjaan yang dicapai oleh PIHAK KEDUA sampai dengan tanggal "&TEXT($T$3,"[$-21]dd mmmm yyyy")&" adalah "&TEXT('BAPP 3'!$K$194,"0.00%")&" sesuai dengan Berita Acara Pemeriksaan Pekerjaan No. "&'BAPP 3'!$B$10&", dengan rincian sebagai berikut :"
C29: a | D29: Perhitungan Pembayaran | M29: `
C30: - | D30: Prestasi s/d saat ini | I30: = | J30: =J32+J31 | L30: x | M30: =$K$24 | N30: = | P30: =J30*M30
C31: - | D31: Prestasi yang lalu | I31: = | J31: ='rincian 3'!T166 | L31: x | M31: =$K$24 | N31: = | P31: =J31*M31
C32: - | D32: Prestasi saat ini | I32: = | J32: ='BAPP 3'!K194 | L32: x | M32: =$K$24 | N32: = | P32: =J32*M32
Q33: =P32
C34: b | D34: Potongan Retensi
D35: Potongan Retensi s/d saat ini | I35: = | J35: =$K$27 | L35: x | M35: =M36+M37 | N35: = | P35: =ROUND(J35*M35,0)
D36: Potongan Retensi yang lalu | I36: = | J36: 0 | L36: x | M36: 0 | N36: = | P36: =J36*M36
D37: Potongan Retensi saat ini | I37: = | J37: 0 | L37: x | M37: =P32 | N37: = | P37: =ROUND(J37*M37,0)
Q38: =P37
C39: c | D39: Pengembalian Uang Muka
D40: Pengembalian Uang Muka s/d saat ini | I40: = | J40: =$K$26 | L40: x | M40: =M42+M41 | N40: = | P40: =ROUND(J40*M40,0)
D41: Pengembalian Uang Muka yang lalu | I41: = | J41: 0 | L41: x | M41: 0 | N41: = | P41: =J41*M41
D42: Pengembalian Uang saat ini | I42: = | J42: 0 | L42: x | M42: =Q33 | N42: = | P42: =ROUND(J42*M42,0)
Q43: =P42
C45: d. | D45: Potongan Pembayaran
Q47: =SUM(P46)
D48: JUMLAH SETELAH DIKURANGI RETENSI, UANG MUKA (a-b-c) | Q48: =ROUND((Q33-Q38-Q43-Q47),0)
...

Sheet BAP  4
T3: {=INDEX(DATA!$B$99:$B$104,$T$9)} | V3: =TEXT($T$3,"[$-21]dd mmmm yyyy") | W3: =TEXT($T3,"[$-21]dd mmmm yyyy")
T4: =TEXT($T$3,"[$-21]dddd")
T5: =VLOOKUP(DAY($T$3),HELPER!$A$2:$B$100,2,0)
T6: =TEXT($T$3,"[$-21]mmmm")
T7: ="Dua Ribu"&IF(MOD(YEAR($T$3),100)=0,""," "&VLOOKUP(MOD(YEAR($T$3),100),HELPER!$A$2:$B$100,2,0))
T8: TERMIN SHEET INI (1-6)
T9: 4
C10: BERITA ACARA PEMBAYARAN (BAP)
C11: =TEXT($T$9,"00")&"/BAP/"&DATA!$B$4
C13: ="Pada hari ini "&T4&" tanggal "&T5&" bulan "&T6&" tahun "&T7&" ("&V3&"), kami yang bertandatangan di bawah ini:"
C15: 1 | D15: =DATA!$B$69 | I15: : | J15: ="Selaku "&DATA!$B$70&", "&DATA!$B$7&", dalam hal ini bertindak untuk dan atas nama "&DATA!$B$17&" yang berkedudukan di "&DATA!$B$18&" (selanjutnya disebut sebagai PIHAK PERTAMA)."
C16: 2 | D16: =DATA!$B$22 | I16: : | J16: ="Selaku "&DATA!$B$23&" "&DATA!$B$24&", dalam hal ini bertindak untuk dan atas nama "&DATA!$B$24&" yang berkedudukan di "&DATA!$B$25&" (selanjutnya disebut sebagai PIHAK KEDUA)."
C18: ="Menerangkan bahwa kedua belah pihak, telah melakukan pemeriksaan atas "&DATA!$B$6&" pada "&DATA!$B$7&", dan berdasarkan :"
D20: Kontrak / SPK No. dan Tanggal | J20: : | K20: =DATA!$B$4 | N20: Tanggal : | P20: =TEXT(DATA!$B$5,"[$-21]dd mmmm yyyy")
D21: Addendum | J21: : | K21: -
D22: Pekerjaan / Pengadaan | J22: : | K22: =DATA!$B$6
D23: Jangka Waktu Pelaksanaan | J23: : | K23: =TEXT(DATA!$B$8,"[$-21]dd mmmm yyyy") | M23: s/d. | N23: =TEXT(DATA!$B$9,"[$-21]dd mmmm yyyy")
D24: Nilai Kontrak | J24: : | K24: =#REF! | P24: (Exclude PPN)
D25: Nilai Addendum I | J25: : | K25: 0 | P25: (Exclude PPN 10%)
D26: Uang Muka | J26: : | K26: =DATA!$B$46
D27: Retensi | J27: : | K27: =DATA!$B$47
C28: ="Menyatakan bahwa prestasi pekerjaan yang dicapai oleh PIHAK KEDUA sampai dengan tanggal "&TEXT($T$3,"[$-21]dd mmmm yyyy")&" adalah "&TEXT('BAPP 4'!$K$194,"0.00%")&" sesuai dengan Berita Acara Pemeriksaan Pekerjaan No. "&'BAPP 4'!$B$10&", dengan rincian sebagai berikut :"
C29: a | D29: Perhitungan Pembayaran | M29: `
C30: - | D30: Prestasi s/d saat ini | I30: = | J30: =J32+J31 | L30: x | M30: =$K$24 | N30: = | P30: =J30*M30
C31: - | D31: Prestasi yang lalu | I31: = | J31: ='rincian 4'!T166 | L31: x | M31: =$K$24 | N31: = | P31: =J31*M31
C32: - | D32: Prestasi saat ini | I32: = | J32: ='BAPP 4'!K194 | L32: x | M32: =$K$24 | N32: = | P32: =J32*M32
Q33: =P32
C34: b | D34: Potongan Retensi
D35: Potongan Retensi s/d saat ini | I35: = | J35: =$K$27 | L35: x | M35: =M36+M37 | N35: = | P35: =ROUND(J35*M35,0)
D36: Potongan Retensi yang lalu | I36: = | J36: 0 | L36: x | M36: 0 | N36: = | P36: =J36*M36
D37: Potongan Retensi saat ini | I37: = | J37: 0 | L37: x | M37: =P32 | N37: = | P37: =ROUND(J37*M37,0)
Q38: =P37
C39: c | D39: Pengembalian Uang Muka
D40: Pengembalian Uang Muka s/d saat ini | I40: = | J40: =$K$26 | L40: x | M40: =M42+M41 | N40: = | P40: =ROUND(J40*M40,0)
D41: Pengembalian Uang Muka yang lalu | I41: = | J41: 0 | L41: x | M41: 0 | N41: = | P41: =J41*M41
D42: Pengembalian Uang saat ini | I42: = | J42: 0 | L42: x | M42: =Q33 | N42: = | P42: =ROUND(J42*M42,0)
Q43: =P42
C45: d. | D45: Potongan Pembayaran
Q47: =SUM(P46)
D48: JUMLAH SETELAH DIKURANGI RETENSI, UANG MUKA (a-b-c) | Q48: =ROUND((Q33-Q38-Q43-Q47),0)
...

Sheet BAP  5
T3: {=INDEX(DATA!$B$99:$B$104,$T$9)} | V3: =TEXT($T$3,"[$-21]dd mmmm yyyy") | W3: =TEXT($T3,"[$-21]dd mmmm yyyy")
T4: =TEXT($T$3,"[$-21]dddd")
T5: =VLOOKUP(DAY($T$3),HELPER!$A$2:$B$100,2,0)
T6: =TEXT($T$3,"[$-21]mmmm")
T7: ="Dua Ribu"&IF(MOD(YEAR($T$3),100)=0,""," "&VLOOKUP(MOD(YEAR($T$3),100),HELPER!$A$2:$B$100,2,0))
T8: TERMIN SHEET INI (1-6)
T9: 5
C10: BERITA ACARA PEMBAYARAN (BAP)
C11: =TEXT($T$9,"00")&"/BAP/"&DATA!$B$4
C13: ="Pada hari ini "&T4&" tanggal "&T5&" bulan "&T6&" tahun "&T7&" ("&V3&"), kami yang bertandatangan di bawah ini:"
C15: 1 | D15: =DATA!$B$69 | I15: : | J15: ="Selaku "&DATA!$B$70&", "&DATA!$B$7&", dalam hal ini bertindak untuk dan atas nama "&DATA!$B$17&" yang berkedudukan di "&DATA!$B$18&" (selanjutnya disebut sebagai PIHAK PERTAMA)."
C16: 2 | D16: =DATA!$B$22 | I16: : | J16: ="Selaku "&DATA!$B$23&" "&DATA!$B$24&", dalam hal ini bertindak untuk dan atas nama "&DATA!$B$24&" yang berkedudukan di "&DATA!$B$25&" (selanjutnya disebut sebagai PIHAK KEDUA)."
C18: ="Menerangkan bahwa kedua belah pihak, telah melakukan pemeriksaan atas "&DATA!$B$6&" pada "&DATA!$B$7&", dan berdasarkan :"
D20: Kontrak / SPK No. dan Tanggal | J20: : | K20: =DATA!$B$4 | N20: Tanggal : | P20: =TEXT(DATA!$B$5,"[$-21]dd mmmm yyyy")
D21: Addendum | J21: : | K21: -
D22: Pekerjaan / Pengadaan | J22: : | K22: =DATA!$B$6
D23: Jangka Waktu Pelaksanaan | J23: : | K23: =TEXT(DATA!$B$8,"[$-21]dd mmmm yyyy") | M23: s/d. | N23: =TEXT(DATA!$B$9,"[$-21]dd mmmm yyyy")
D24: Nilai Kontrak | J24: : | K24: =#REF! | P24: (Exclude PPN)
D25: Nilai Addendum I | J25: : | K25: 0 | P25: (Exclude PPN 10%)
D26: Uang Muka | J26: : | K26: =DATA!$B$46
D27: Retensi | J27: : | K27: =DATA!$B$47
C28: ="Menyatakan bahwa prestasi pekerjaan yang dicapai oleh PIHAK KEDUA sampai dengan tanggal "&TEXT($T$3,"[$-21]dd mmmm yyyy")&" adalah "&TEXT('BAPP 5'!$K$194,"0.00%")&" sesuai dengan Berita Acara Pemeriksaan Pekerjaan No. "&'BAPP 5'!$B$10&", dengan rincian sebagai berikut :"
C29: a | D29: Perhitungan Pembayaran | M29: `
C30: - | D30: Prestasi s/d saat ini | I30: = | J30: =J32+J31 | L30: x | M30: =$K$24 | N30: = | P30: =J30*M30
C31: - | D31: Prestasi yang lalu | I31: = | J31: ='rincian 5'!T166 | L31: x | M31: =$K$24 | N31: = | P31: =J31*M31
C32: - | D32: Prestasi saat ini | I32: = | J32: ='BAPP 5'!K194 | L32: x | M32: =$K$24 | N32: = | P32: =J32*M32
Q33: =P32
C34: b | D34: Potongan Retensi
D35: Potongan Retensi s/d saat ini | I35: = | J35: =$K$27 | L35: x | M35: =M36+M37 | N35: = | P35: =ROUND(J35*M35,0)
D36: Potongan Retensi yang lalu | I36: = | J36: 0 | L36: x | M36: 0 | N36: = | P36: =J36*M36
D37: Potongan Retensi saat ini | I37: = | J37: 0 | L37: x | M37: =P32 | N37: = | P37: =ROUND(J37*M37,0)
Q38: =P37
C39: c | D39: Pengembalian Uang Muka
D40: Pengembalian Uang Muka s/d saat ini | I40: = | J40: =$K$26 | L40: x | M40: =M42+M41 | N40: = | P40: =ROUND(J40*M40,0)
D41: Pengembalian Uang Muka yang lalu | I41: = | J41: 0 | L41: x | M41: 0 | N41: = | P41: =J41*M41
D42: Pengembalian Uang saat ini | I42: = | J42: 0 | L42: x | M42: =Q33 | N42: = | P42: =ROUND(J42*M42,0)
Q43: =P42
C45: d. | D45: Potongan Pembayaran
Q47: =SUM(P46)
D48: JUMLAH SETELAH DIKURANGI RETENSI, UANG MUKA (a-b-c) | Q48: =ROUND((Q33-Q38-Q43-Q47),0)
...

Sheet BAP  6
T3: {=INDEX(DATA!$B$99:$B$104,$T$9)} | V3: =TEXT($T$3,"[$-21]dd mmmm yyyy") | W3: =TEXT($T3,"[$-21]dd mmmm yyyy")
T4: =TEXT($T$3,"[$-21]dddd")
T5: =VLOOKUP(DAY($T$3),HELPER!$A$2:$B$100,2,0)
T6: =TEXT($T$3,"[$-21]mmmm")
T7: ="Dua Ribu"&IF(MOD(YEAR($T$3),100)=0,""," "&VLOOKUP(MOD(YEAR($T$3),100),HELPER!$A$2:$B$100,2,0))
T8: TERMIN SHEET INI (1-6)
T9: 6
C10: BERITA ACARA PEMBAYARAN (BAP)
C11: =TEXT($T$9,"00")&"/BAP/"&DATA!$B$4
C13: ="Pada hari ini "&T4&" tanggal "&T5&" bulan "&T6&" tahun "&T7&" ("&V3&"), kami yang bertandatangan di bawah ini:"
C15: 1 | D15: =DATA!$B$69 | I15: : | J15: ="Selaku "&DATA!$B$70&", "&DATA!$B$7&", dalam hal ini bertindak untuk dan atas nama "&DATA!$B$17&" yang berkedudukan di "&DATA!$B$18&" (selanjutnya disebut sebagai PIHAK PERTAMA)."
C16: 2 | D16: =DATA!$B$22 | I16: : | J16: ="Selaku "&DATA!$B$23&" "&DATA!$B$24&", dalam hal ini bertindak untuk dan atas nama "&DATA!$B$24&" yang berkedudukan di "&DATA!$B$25&" (selanjutnya disebut sebagai PIHAK KEDUA)."
C18: ="Menerangkan bahwa kedua belah pihak, telah melakukan pemeriksaan atas "&DATA!$B$6&" pada "&DATA!$B$7&", dan berdasarkan :"
D20: Kontrak / SPK No. dan Tanggal | J20: : | K20: =DATA!$B$4 | N20: Tanggal : | P20: =TEXT(DATA!$B$5,"[$-21]dd mmmm yyyy")
D21: Addendum | J21: : | K21: -
D22: Pekerjaan / Pengadaan | J22: : | K22: =DATA!$B$6
D23: Jangka Waktu Pelaksanaan | J23: : | K23: =TEXT(DATA!$B$8,"[$-21]dd mmmm yyyy") | M23: s/d. | N23: =TEXT(DATA!$B$9,"[$-21]dd mmmm yyyy")
D24: Nilai Kontrak | J24: : | K24: =#REF! | P24: (Exclude PPN)
D25: Nilai Addendum I | J25: : | K25: 0 | P25: (Exclude PPN 10%)
D26: Uang Muka | J26: : | K26: =DATA!$B$46
D27: Retensi | J27: : | K27: =DATA!$B$47
C28: ="Menyatakan bahwa prestasi pekerjaan yang dicapai oleh PIHAK KEDUA sampai dengan tanggal "&TEXT($T$3,"[$-21]dd mmmm yyyy")&" adalah "&TEXT('BAPP 6'!$K$194,"0.00%")&" sesuai dengan Berita Acara Pemeriksaan Pekerjaan No. "&'BAPP 6'!$B$10&", dengan rincian sebagai berikut :"
C29: a | D29: Perhitungan Pembayaran | M29: `
C30: - | D30: Prestasi s/d saat ini | I30: = | J30: =J32+J31 | L30: x | M30: =$K$24 | N30: = | P30: =J30*M30
C31: - | D31: Prestasi yang lalu | I31: = | J31: ='rincian 6'!T166 | L31: x | M31: =$K$24 | N31: = | P31: =J31*M31
C32: - | D32: Prestasi saat ini | I32: = | J32: ='BAPP 6'!K194 | L32: x | M32: =$K$24 | N32: = | P32: =J32*M32
Q33: =P32
C34: b | D34: Potongan Retensi
D35: Potongan Retensi s/d saat ini | I35: = | J35: =$K$27 | L35: x | M35: =M36+M37 | N35: = | P35: =ROUND(J35*M35,0)
D36: Potongan Retensi yang lalu | I36: = | J36: 0 | L36: x | M36: 0 | N36: = | P36: =J36*M36
D37: Potongan Retensi saat ini | I37: = | J37: 0 | L37: x | M37: =P32 | N37: = | P37: =ROUND(J37*M37,0)
Q38: =P37
C39: c | D39: Pengembalian Uang Muka
D40: Pengembalian Uang Muka s/d saat ini | I40: = | J40: =$K$26 | L40: x | M40: =M42+M41 | N40: = | P40: =ROUND(J40*M40,0)
D41: Pengembalian Uang Muka yang lalu | I41: = | J41: 0 | L41: x | M41: 0 | N41: = | P41: =J41*M41
D42: Pengembalian Uang saat ini | I42: = | J42: 0 | L42: x | M42: =Q33 | N42: = | P42: =ROUND(J42*M42,0)
Q43: =P42
C45: d. | D45: Potongan Pembayaran
Q47: =SUM(P46)
D48: JUMLAH SETELAH DIKURANGI RETENSI, UANG MUKA (a-b-c) | Q48: =ROUND((Q33-Q38-Q43-Q47),0)
...

Sheet BAPP
T2: {=INDEX(DATA!$B$99:$B$104,$T$8)} | V2: =TEXT($T$2,"[$-21]dd mmmm yyyy") | W2: =TEXT(T2,"[$-21]dd mmmm yyyy")
T3: =TEXT($T$2,"[$-21]dddd")
T4: =VLOOKUP(DAY($T$2),HELPER!$A$2:$B$100,2,0)
T5: =TEXT($T$2,"[$-21]mmmm")
T6: ="Dua Ribu"&IF(MOD(YEAR($T$2),100)=0,""," "&VLOOKUP(MOD(YEAR($T$2),100),HELPER!$A$2:$B$100,2,0))
T7: TERMIN SHEET INI (1-6)
T8: 1
B9: BERITA ACARA PRESTASI PEKERJAAN
B10: =TEXT($T$8,"00")&"/BAPP/"&DATA!$B$4
C12: ="Pada hari ini "&T3&" tanggal "&T4&" bulan "&T5&" tahun "&T6&" ("&V2&"), kami yang bertandatangan di bawah ini:"
C14: I | D14: =DATA!$B$14 | E14: : | F14: ="Selaku "&DATA!$B$16&", Proyek "&DATA!$B$7&", dalam hal ini bertindak untuk dan atas nama "&DATA!$B$17&", yang berkedudukan di "&DATA!$B$18
U15: Selaku Project Coordinator, Proyek Design and Build Perkuatan Dermaga Barat JICT Pelabuhan Tanjung Priok, dalam hal ini bertindak untuk dan atas nama Waskita - Nindya KSO, yang berkedudukan di Gedung Waskita IDSurvey TowerJl. M.T. Haryono Kavling No.10, Jatinegara, Jakarta Timur
F16: yang selanjutnya disebut PIHAK PERTAMA
C18: II | D18: =DATA!$B$22 | E18: : | F18: ="Selaku "&DATA!$B$23&" "&DATA!$B$24&", dalam hal ini bertindak untuk dan atas nama "&DATA!$B$24&" yang berkedudukan di "&DATA!$B$25
F19: yang selanjutnya disebut PIHAK KEDUA
C21: ="Menerangkan bahwa kedua belah pihak telah setuju dan sepakat melakukan pemeriksaan pekerjaan sesuai dengan lampiran SPPP Nomor "&DATA!$B$4&", dan menyetujui prestasi pekerjaan berdasakan :"
C23: 1 | D23: Kontrak / SPK No. dan Tanggal | G23: : | H23: =DATA!$B$4 | L23: , tanggal : | M23: =TEXT(DATA!$B$5,"[$-21]dd mmmm yyyy")
C24: 2 | D24: Nilai Kontrak | G24: : | H24: Rp. | I24: =lamp1!K41 | K24: (Exclude PPN)
C25: 3 | D25: Waktu pelaksanaan | G25: : | H25: =TEXT(DATA!$B$8,"[$-21]dd mmmm yyyy") | J25: s.d. | K25: =TEXT(DATA!$B$9,"[$-21]dd mmmm yyyy")
C26: Dengan rincian sebagai berikut :
J28: Volume | K28: Realisasi Volume Pekerjaan | Q28: Jumlah
J29: sesuai | K29: B A | L29: Periode Ini | M29: B A | N29: B A | O29: Sisa yang | P29: Harga | Q29: Harga
B30: No | C30: Macam Pekerjaan | J30: SPK / | K30: s / d | M30: s / d | N30: yang | O30: belum | P30: Satuan | Q30: yang
J31: Kontrak | K31: yang lalu | M31: Saat Ini | N31: ditagihkan | O31: di BA kan | Q31: ditagihkan
B32: 1 | C32: 2 | J32: 3 | K32: 4 | L32: 5 | M32: 6 = 4+5 | N32: 7 | O32: 8 = 3 - 6 | P32: 9 | Q32: 10 = 7 x 9
C34: ='rincian '!C11
C35: =lamp1!C14
B36: =lamp1!B15 | C36: ='rincian '!C13
C37: =lamp1!C16
B38: =lamp1!B17 | D38: =lamp1!D17 | J38: =lamp1!H17 | K38: ='rincian '!S15 | L38: ='rincian '!U15 | M38: =K38+L38 | N38: =L38 | O38: =J38-M38 | P38: =lamp1!J17 | Q38: =N38*P38
B39: =lamp1!B18 | D39: =lamp1!D18 | J39: =lamp1!H18 | K39: ='rincian '!S16 | L39: ='rincian '!U16 | M39: =K39+L39 | N39: =L39 | O39: =J39-M39 | P39: =lamp1!J18 | Q39: =N39*P39
B40: =lamp1!B19 | D40: =lamp1!D19 | J40: =lamp1!H19 | K40: ='rincian '!S17 | L40: ='rincian '!U17 | M40: =K40+L40 | N40: =L40 | O40: =J40-M40 | P40: =lamp1!J19 | Q40: =N40*P40
B41: =lamp1!B20 | D41: =lamp1!D20 | J41: =lamp1!H20 | K41: ='rincian '!S18 | L41: ='rincian '!U18 | M41: =K41+L41 | N41: =L41 | O41: =J41-M41 | P41: =lamp1!J20 | Q41: =N41*P41
B42: =lamp1!B21 | D42: =lamp1!D21 | J42: =lamp1!H21 | K42: ='rincian '!S19 | L42: ='rincian '!U19 | M42: =K42+L42 | N42: =L42 | O42: =J42-M42 | P42: =lamp1!J21 | Q42: =N42*P42
B43: =lamp1!B22 | D43: =lamp1!D22 | J43: =lamp1!H22 | K43: ='rincian '!S20 | L43: ='rincian '!U20 | M43: =K43+L43 | N43: =L43 | O43: =J43-M43 | P43: =lamp1!J22 | Q43: =N43*P43
B44: =lamp1!B23 | D44: =lamp1!D23 | J44: - | K44: - | L44: - | M44: - | N44: - | O44: - | P44: =lamp1!J23 | Q44: 0
B45: =lamp1!B24 | D45: =lamp1!D24 | J45: =lamp1!H24 | K45: ='rincian '!S22 | L45: ='rincian '!U22 | M45: =K45+L45 | N45: =L45 | O45: =J45-M45 | P45: =lamp1!J24 | Q45: =N45*P45
B47: =lamp1!B26 | C47: =lamp1!C26
C48: =lamp1!C27
B49: =lamp1!B28 | D49: =lamp1!D28 | J49: =lamp1!H28 | K49: ='rincian '!S36 | L49: ='rincian '!U36 | M49: =K49+L49 | N49: =L49 | O49: =J49-M49 | P49: =lamp1!J28 | Q49: =N49*P49
...

Sheet BAPP 2
T2: {=INDEX(DATA!$B$99:$B$104,$T$8)} | V2: =TEXT($T$2,"[$-21]dd mmmm yyyy") | W2: =TEXT(T2,"[$-21]dd mmmm yyyy")
T3: =TEXT($T$2,"[$-21]dddd")
T4: =VLOOKUP(DAY($T$2),HELPER!$A$2:$B$100,2,0)
T5: =TEXT($T$2,"[$-21]mmmm")
T6: ="Dua Ribu"&IF(MOD(YEAR($T$2),100)=0,""," "&VLOOKUP(MOD(YEAR($T$2),100),HELPER!$A$2:$B$100,2,0))
T7: TERMIN SHEET INI (1-6)
T8: 2
B9: BERITA ACARA PRESTASI PEKERJAAN
B10: =TEXT($T$8,"00")&"/BAPP/"&DATA!$B$4
C12: ="Pada hari ini "&T3&" tanggal "&T4&" bulan "&T5&" tahun "&T6&" ("&V2&"), kami yang bertandatangan di bawah ini:"
C14: I | D14: =DATA!$B$14 | E14: : | F14: ="Selaku "&DATA!$B$16&", Proyek "&DATA!$B$7&", dalam hal ini bertindak untuk dan atas nama "&DATA!$B$17&", yang berkedudukan di "&DATA!$B$18
U15: Selaku Project Coordinator, Proyek Design and Build Perkuatan Dermaga Barat JICT Pelabuhan Tanjung Priok, dalam hal ini bertindak untuk dan atas nama Waskita - Nindya KSO, yang berkedudukan di Gedung Waskita IDSurvey TowerJl. M.T. Haryono Kavling No.10, Jatinegara, Jakarta Timur
F16: yang selanjutnya disebut PIHAK PERTAMA
C18: II | D18: =DATA!$B$22 | E18: : | F18: ="Selaku "&DATA!$B$23&" "&DATA!$B$24&", dalam hal ini bertindak untuk dan atas nama "&DATA!$B$24&" yang berkedudukan di "&DATA!$B$25
F19: yang selanjutnya disebut PIHAK KEDUA
C21: ="Menerangkan bahwa kedua belah pihak telah setuju dan sepakat melakukan pemeriksaan pekerjaan sesuai dengan lampiran SPKP Nomor "&DATA!$B$4&", dan menyetujui prestasi pekerjaan berdasakan :"
C23: 1 | D23: Kontrak / SPK No. dan Tanggal | G23: : | H23: =DATA!$B$4 | L23: , tanggal : | M23: =TEXT(DATA!$B$5,"[$-21]dd mmmm yyyy")
C24: 2 | D24: Nilai Kontrak | G24: : | H24: Rp. | I24: =#REF! | K24: (Exclude PPN)
C25: 3 | D25: Waktu pelaksanaan | G25: : | H25: =TEXT(DATA!$B$8,"[$-21]dd mmmm yyyy") | J25: s.d. | K25: =TEXT(DATA!$B$9,"[$-21]dd mmmm yyyy")
C26: Dengan rincian sebagai berikut :
J28: Volume | K28: Realisasi Volume Pekerjaan | Q28: Jumlah
J29: sesuai | K29: B A | L29: Periode Ini | M29: B A | N29: B A | O29: Sisa yang | P29: Harga | Q29: Harga
B30: No | C30: Macam Pekerjaan | J30: SPK / | K30: s / d | M30: s / d | N30: yang | O30: belum | P30: Satuan | Q30: yang
J31: Kontrak | K31: yang lalu | M31: Saat Ini | N31: ditagihkan | O31: di BA kan | Q31: ditagihkan
B32: 1 | C32: 2 | J32: 3 | K32: 4 | L32: 5 | M32: 6 = 4+5 | N32: 7 | O32: 8 = 3 - 6 | P32: 9 | Q32: 10 = 7 x 9
C34: ='rincian 2'!C11
B35: =#REF! | D35: =IF(#REF!<>"",#REF!,IF(#REF!<>"",#REF!,""))
B36: =#REF! | D36: =IF(#REF!<>"",#REF!,IF(#REF!<>"",#REF!,""))
B37: =#REF! | D37: =IF(#REF!<>"",#REF!,IF(#REF!<>"",#REF!,"")) | J37: =#REF! | K37: ='rincian 2'!S14 | L37: ='rincian 2'!U14 | M37: =K37+L37 | N37: =L37 | O37: =J37-M37 | P37: =#REF! | Q37: =N37*P37
B38: =#REF! | D38: =IF(#REF!<>"",#REF!,IF(#REF!<>"",#REF!,"")) | J38: =#REF! | K38: ='rincian 2'!S15 | L38: ='rincian 2'!U15 | M38: =K38+L38 | N38: =L38 | O38: =J38-M38 | P38: =#REF! | Q38: =N38*P38
B39: =#REF! | D39: =IF(#REF!<>"",#REF!,IF(#REF!<>"",#REF!,"")) | J39: =#REF! | K39: ='rincian 2'!S16 | L39: ='rincian 2'!U16 | M39: =K39+L39 | N39: =L39 | O39: =J39-M39 | P39: =#REF! | Q39: =N39*P39
B40: =#REF! | D40: =IF(#REF!<>"",#REF!,IF(#REF!<>"",#REF!,"")) | J40: =#REF! | K40: ='rincian 2'!S17 | L40: ='rincian 2'!U17 | M40: =K40+L40 | N40: =L40 | O40: =J40-M40 | P40: =#REF! | Q40: =N40*P40
B41: =#REF! | D41: =IF(#REF!<>"",#REF!,IF(#REF!<>"",#REF!,""))
B42: =#REF! | D42: =IF(#REF!<>"",#REF!,IF(#REF!<>"",#REF!,"")) | J42: =#REF! | K42: ='rincian 2'!S19 | L42: ='rincian 2'!U19 | M42: =K42+L42 | N42: =L42 | O42: =J42-M42 | P42: =#REF! | Q42: =N42*P42
B43: =#REF! | D43: =IF(#REF!<>"",#REF!,IF(#REF!<>"",#REF!,"")) | J43: =#REF! | K43: ='rincian 2'!S20 | L43: ='rincian 2'!U20 | M43: =K43+L43 | N43: =L43 | O43: =J43-M43 | P43: =#REF! | Q43: =N43*P43
B44: =#REF! | D44: =IF(#REF!<>"",#REF!,IF(#REF!<>"",#REF!,"")) | J44: =#REF! | K44: ='rincian 2'!S21 | L44: ='rincian 2'!U21 | M44: =K44+L44 | N44: =L44 | O44: =J44-M44 | P44: =#REF! | Q44: =N44*P44
B45: =#REF! | D45: =IF(#REF!<>"",#REF!,IF(#REF!<>"",#REF!,"")) | J45: =#REF! | K45: ='rincian 2'!S22 | L45: ='rincian 2'!U22 | M45: =K45+L45 | N45: =L45 | O45: =J45-M45 | P45: =#REF! | Q45: =N45*P45
B46: =#REF! | D46: =IF(#REF!<>"",#REF!,IF(#REF!<>"",#REF!,"")) | J46: =#REF! | K46: ='rincian 2'!S23 | L46: ='rincian 2'!U23 | M46: =K46+L46 | N46: =L46 | O46: =J46-M46 | P46: =#REF! | Q46: =N46*P46
B47: =#REF! | D47: =IF(#REF!<>"",#REF!,IF(#REF!<>"",#REF!,"")) | J47: =#REF! | K47: ='rincian 2'!S24 | L47: ='rincian 2'!U24 | M47: =K47+L47 | N47: =L47 | O47: =J47-M47 | P47: =#REF! | Q47: =N47*P47
B48: =#REF! | D48: =IF(#REF!<>"",#REF!,IF(#REF!<>"",#REF!,""))
...

Sheet BAPP 3
T2: {=INDEX(DATA!$B$99:$B$104,$T$8)} | V2: =TEXT($T$2,"[$-21]dd mmmm yyyy") | W2: =TEXT(T2,"[$-21]dd mmmm yyyy")
T3: =TEXT($T$2,"[$-21]dddd")
T4: =VLOOKUP(DAY($T$2),HELPER!$A$2:$B$100,2,0)
T5: =TEXT($T$2,"[$-21]mmmm")
T6: ="Dua Ribu"&IF(MOD(YEAR($T$2),100)=0,""," "&VLOOKUP(MOD(YEAR($T$2),100),HELPER!$A$2:$B$100,2,0))
T7: TERMIN SHEET INI (1-6)
T8: 3
B9: BERITA ACARA PRESTASI PEKERJAAN
B10: =TEXT($T$8,"00")&"/BAPP/"&DATA!$B$4
C12: ="Pada hari ini "&T3&" tanggal "&T4&" bulan "&T5&" tahun "&T6&" ("&V2&"), kami yang bertandatangan di bawah ini:"
C14: I | D14: =DATA!$B$14 | E14: : | F14: ="Selaku "&DATA!$B$16&", Proyek "&DATA!$B$7&", dalam hal ini bertindak untuk dan atas nama "&DATA!$B$17&", yang berkedudukan di "&DATA!$B$18
U15: Selaku Project Coordinator, Proyek Design and Build Perkuatan Dermaga Barat JICT Pelabuhan Tanjung Priok, dalam hal ini bertindak untuk dan atas nama Waskita - Nindya KSO, yang berkedudukan di Gedung Waskita IDSurvey TowerJl. M.T. Haryono Kavling No.10, Jatinegara, Jakarta Timur
F16: yang selanjutnya disebut PIHAK PERTAMA
C18: II | D18: =DATA!$B$22 | E18: : | F18: ="Selaku "&DATA!$B$23&" "&DATA!$B$24&", dalam hal ini bertindak untuk dan atas nama "&DATA!$B$24&" yang berkedudukan di "&DATA!$B$25
F19: yang selanjutnya disebut PIHAK KEDUA
C21: ="Menerangkan bahwa kedua belah pihak telah setuju dan sepakat melakukan pemeriksaan pekerjaan sesuai dengan lampiran SPKP Nomor "&DATA!$B$4&", dan menyetujui prestasi pekerjaan berdasakan :"
C23: 1 | D23: Kontrak / SPK No. dan Tanggal | G23: : | H23: =DATA!$B$4 | L23: , tanggal : | M23: =TEXT(DATA!$B$5,"[$-21]dd mmmm yyyy")
C24: 2 | D24: Nilai Kontrak | G24: : | H24: Rp. | I24: =#REF! | K24: (Exclude PPN)
C25: 3 | D25: Waktu pelaksanaan | G25: : | H25: =TEXT(DATA!$B$8,"[$-21]dd mmmm yyyy") | J25: s.d. | K25: =TEXT(DATA!$B$9,"[$-21]dd mmmm yyyy")
C26: Dengan rincian sebagai berikut :
J28: Volume | K28: Realisasi Volume Pekerjaan | Q28: Jumlah
J29: sesuai | K29: B A | L29: Periode Ini | M29: B A | N29: B A | O29: Sisa yang | P29: Harga | Q29: Harga
B30: No | C30: Macam Pekerjaan | J30: SPK / | K30: s / d | M30: s / d | N30: yang | O30: belum | P30: Satuan | Q30: yang
J31: Kontrak | K31: yang lalu | M31: Saat Ini | N31: ditagihkan | O31: di BA kan | Q31: ditagihkan
B32: 1 | C32: 2 | J32: 3 | K32: 4 | L32: 5 | M32: 6 = 4+5 | N32: 7 | O32: 8 = 3 - 6 | P32: 9 | Q32: 10 = 7 x 9
C34: ='rincian 3'!C11
B35: =#REF! | D35: =IF(#REF!<>"",#REF!,IF(#REF!<>"",#REF!,""))
B36: =#REF! | D36: =IF(#REF!<>"",#REF!,IF(#REF!<>"",#REF!,""))
B37: =#REF! | D37: =IF(#REF!<>"",#REF!,IF(#REF!<>"",#REF!,"")) | J37: =#REF! | K37: ='rincian 3'!S14 | L37: ='rincian 3'!U14 | M37: =K37+L37 | N37: =L37 | O37: =J37-M37 | P37: =#REF! | Q37: =N37*P37
B38: =#REF! | D38: =IF(#REF!<>"",#REF!,IF(#REF!<>"",#REF!,"")) | J38: =#REF! | K38: ='rincian 3'!S15 | L38: ='rincian 3'!U15 | M38: =K38+L38 | N38: =L38 | O38: =J38-M38 | P38: =#REF! | Q38: =N38*P38
B39: =#REF! | D39: =IF(#REF!<>"",#REF!,IF(#REF!<>"",#REF!,"")) | J39: =#REF! | K39: ='rincian 3'!S16 | L39: ='rincian 3'!U16 | M39: =K39+L39 | N39: =L39 | O39: =J39-M39 | P39: =#REF! | Q39: =N39*P39
B40: =#REF! | D40: =IF(#REF!<>"",#REF!,IF(#REF!<>"",#REF!,"")) | J40: =#REF! | K40: ='rincian 3'!S17 | L40: ='rincian 3'!U17 | M40: =K40+L40 | N40: =L40 | O40: =J40-M40 | P40: =#REF! | Q40: =N40*P40
B41: =#REF! | D41: =IF(#REF!<>"",#REF!,IF(#REF!<>"",#REF!,""))
B42: =#REF! | D42: =IF(#REF!<>"",#REF!,IF(#REF!<>"",#REF!,"")) | J42: =#REF! | K42: ='rincian 3'!S19 | L42: ='rincian 3'!U19 | M42: =K42+L42 | N42: =L42 | O42: =J42-M42 | P42: =#REF! | Q42: =N42*P42
B43: =#REF! | D43: =IF(#REF!<>"",#REF!,IF(#REF!<>"",#REF!,"")) | J43: =#REF! | K43: ='rincian 3'!S20 | L43: ='rincian 3'!U20 | M43: =K43+L43 | N43: =L43 | O43: =J43-M43 | P43: =#REF! | Q43: =N43*P43
B44: =#REF! | D44: =IF(#REF!<>"",#REF!,IF(#REF!<>"",#REF!,"")) | J44: =#REF! | K44: ='rincian 3'!S21 | L44: ='rincian 3'!U21 | M44: =K44+L44 | N44: =L44 | O44: =J44-M44 | P44: =#REF! | Q44: =N44*P44
B45: =#REF! | D45: =IF(#REF!<>"",#REF!,IF(#REF!<>"",#REF!,"")) | J45: =#REF! | K45: ='rincian 3'!S22 | L45: ='rincian 3'!U22 | M45: =K45+L45 | N45: =L45 | O45: =J45-M45 | P45: =#REF! | Q45: =N45*P45
B46: =#REF! | D46: =IF(#REF!<>"",#REF!,IF(#REF!<>"",#REF!,"")) | J46: =#REF! | K46: ='rincian 3'!S23 | L46: ='rincian 3'!U23 | M46: =K46+L46 | N46: =L46 | O46: =J46-M46 | P46: =#REF! | Q46: =N46*P46
B47: =#REF! | D47: =IF(#REF!<>"",#REF!,IF(#REF!<>"",#REF!,"")) | J47: =#REF! | K47: ='rincian 3'!S24 | L47: ='rincian 3'!U24 | M47: =K47+L47 | N47: =L47 | O47: =J47-M47 | P47: =#REF! | Q47: =N47*P47
B48: =#REF! | D48: =IF(#REF!<>"",#REF!,IF(#REF!<>"",#REF!,""))
...

Sheet BAPP 4
T2: {=INDEX(DATA!$B$99:$B$104,$T$8)} | V2: =TEXT($T$2,"[$-21]dd mmmm yyyy") | W2: =TEXT(T2,"[$-21]dd mmmm yyyy")
T3: =TEXT($T$2,"[$-21]dddd")
T4: =VLOOKUP(DAY($T$2),HELPER!$A$2:$B$100,2,0)
T5: =TEXT($T$2,"[$-21]mmmm")
T6: ="Dua Ribu"&IF(MOD(YEAR($T$2),100)=0,""," "&VLOOKUP(MOD(YEAR($T$2),100),HELPER!$A$2:$B$100,2,0))
T7: TERMIN SHEET INI (1-6)
T8: 4
B9: BERITA ACARA PRESTASI PEKERJAAN
B10: =TEXT($T$8,"00")&"/BAPP/"&DATA!$B$4
C12: ="Pada hari ini "&T3&" tanggal "&T4&" bulan "&T5&" tahun "&T6&" ("&V2&"), kami yang bertandatangan di bawah ini:"
C14: I | D14: =DATA!$B$14 | E14: : | F14: ="Selaku "&DATA!$B$16&", Proyek "&DATA!$B$7&", dalam hal ini bertindak untuk dan atas nama "&DATA!$B$17&", yang berkedudukan di "&DATA!$B$18
U15: Selaku Project Coordinator, Proyek Design and Build Perkuatan Dermaga Barat JICT Pelabuhan Tanjung Priok, dalam hal ini bertindak untuk dan atas nama Waskita - Nindya KSO, yang berkedudukan di Gedung Waskita IDSurvey TowerJl. M.T. Haryono Kavling No.10, Jatinegara, Jakarta Timur
F16: yang selanjutnya disebut PIHAK PERTAMA
C18: II | D18: =DATA!$B$22 | E18: : | F18: ="Selaku "&DATA!$B$23&" "&DATA!$B$24&", dalam hal ini bertindak untuk dan atas nama "&DATA!$B$24&" yang berkedudukan di "&DATA!$B$25
F19: yang selanjutnya disebut PIHAK KEDUA
C21: ="Menerangkan bahwa kedua belah pihak telah setuju dan sepakat melakukan pemeriksaan pekerjaan sesuai dengan lampiran SPKP Nomor "&DATA!$B$4&", dan menyetujui prestasi pekerjaan berdasakan :"
C23: 1 | D23: Kontrak / SPK No. dan Tanggal | G23: : | H23: =DATA!$B$4 | L23: , tanggal : | M23: =TEXT(DATA!$B$5,"[$-21]dd mmmm yyyy")
C24: 2 | D24: Nilai Kontrak | G24: : | H24: Rp. | I24: =#REF! | K24: (Exclude PPN)
C25: 3 | D25: Waktu pelaksanaan | G25: : | H25: =TEXT(DATA!$B$8,"[$-21]dd mmmm yyyy") | J25: s.d. | K25: =TEXT(DATA!$B$9,"[$-21]dd mmmm yyyy")
C26: Dengan rincian sebagai berikut :
J28: Volume | K28: Realisasi Volume Pekerjaan | Q28: Jumlah
J29: sesuai | K29: B A | L29: Periode Ini | M29: B A | N29: B A | O29: Sisa yang | P29: Harga | Q29: Harga
B30: No | C30: Macam Pekerjaan | J30: SPK / | K30: s / d | M30: s / d | N30: yang | O30: belum | P30: Satuan | Q30: yang
J31: Kontrak | K31: yang lalu | M31: Saat Ini | N31: ditagihkan | O31: di BA kan | Q31: ditagihkan
B32: 1 | C32: 2 | J32: 3 | K32: 4 | L32: 5 | M32: 6 = 4+5 | N32: 7 | O32: 8 = 3 - 6 | P32: 9 | Q32: 10 = 7 x 9
C34: ='rincian 4'!C11
B35: =#REF! | D35: =IF(#REF!<>"",#REF!,IF(#REF!<>"",#REF!,""))
B36: =#REF! | D36: =IF(#REF!<>"",#REF!,IF(#REF!<>"",#REF!,""))
B37: =#REF! | D37: =IF(#REF!<>"",#REF!,IF(#REF!<>"",#REF!,"")) | J37: =#REF! | K37: ='rincian 4'!S14 | L37: ='rincian 4'!U14 | M37: =K37+L37 | N37: =L37 | O37: =J37-M37 | P37: =#REF! | Q37: =N37*P37
B38: =#REF! | D38: =IF(#REF!<>"",#REF!,IF(#REF!<>"",#REF!,"")) | J38: =#REF! | K38: ='rincian 4'!S15 | L38: ='rincian 4'!U15 | M38: =K38+L38 | N38: =L38 | O38: =J38-M38 | P38: =#REF! | Q38: =N38*P38
B39: =#REF! | D39: =IF(#REF!<>"",#REF!,IF(#REF!<>"",#REF!,"")) | J39: =#REF! | K39: ='rincian 4'!S16 | L39: ='rincian 4'!U16 | M39: =K39+L39 | N39: =L39 | O39: =J39-M39 | P39: =#REF! | Q39: =N39*P39
B40: =#REF! | D40: =IF(#REF!<>"",#REF!,IF(#REF!<>"",#REF!,"")) | J40: =#REF! | K40: ='rincian 4'!S17 | L40: ='rincian 4'!U17 | M40: =K40+L40 | N40: =L40 | O40: =J40-M40 | P40: =#REF! | Q40: =N40*P40
B41: =#REF! | D41: =IF(#REF!<>"",#REF!,IF(#REF!<>"",#REF!,""))
B42: =#REF! | D42: =IF(#REF!<>"",#REF!,IF(#REF!<>"",#REF!,"")) | J42: =#REF! | K42: ='rincian 4'!S19 | L42: ='rincian 4'!U19 | M42: =K42+L42 | N42: =L42 | O42: =J42-M42 | P42: =#REF! | Q42: =N42*P42
B43: =#REF! | D43: =IF(#REF!<>"",#REF!,IF(#REF!<>"",#REF!,"")) | J43: =#REF! | K43: ='rincian 4'!S20 | L43: ='rincian 4'!U20 | M43: =K43+L43 | N43: =L43 | O43: =J43-M43 | P43: =#REF! | Q43: =N43*P43
B44: =#REF! | D44: =IF(#REF!<>"",#REF!,IF(#REF!<>"",#REF!,"")) | J44: =#REF! | K44: ='rincian 4'!S21 | L44: ='rincian 4'!U21 | M44: =K44+L44 | N44: =L44 | O44: =J44-M44 | P44: =#REF! | Q44: =N44*P44
B45: =#REF! | D45: =IF(#REF!<>"",#REF!,IF(#REF!<>"",#REF!,"")) | J45: =#REF! | K45: ='rincian 4'!S22 | L45: ='rincian 4'!U22 | M45: =K45+L45 | N45: =L45 | O45: =J45-M45 | P45: =#REF! | Q45: =N45*P45
B46: =#REF! | D46: =IF(#REF!<>"",#REF!,IF(#REF!<>"",#REF!,"")) | J46: =#REF! | K46: ='rincian 4'!S23 | L46: ='rincian 4'!U23 | M46: =K46+L46 | N46: =L46 | O46: =J46-M46 | P46: =#REF! | Q46: =N46*P46
B47: =#REF! | D47: =IF(#REF!<>"",#REF!,IF(#REF!<>"",#REF!,"")) | J47: =#REF! | K47: ='rincian 4'!S24 | L47: ='rincian 4'!U24 | M47: =K47+L47 | N47: =L47 | O47: =J47-M47 | P47: =#REF! | Q47: =N47*P47
B48: =#REF! | D48: =IF(#REF!<>"",#REF!,IF(#REF!<>"",#REF!,""))
...

Sheet BAPP 5
T2: {=INDEX(DATA!$B$99:$B$104,$T$8)} | V2: =TEXT($T$2,"[$-21]dd mmmm yyyy") | W2: =TEXT(T2,"[$-21]dd mmmm yyyy")
T3: =TEXT($T$2,"[$-21]dddd")
T4: =VLOOKUP(DAY($T$2),HELPER!$A$2:$B$100,2,0)
T5: =TEXT($T$2,"[$-21]mmmm")
T6: ="Dua Ribu"&IF(MOD(YEAR($T$2),100)=0,""," "&VLOOKUP(MOD(YEAR($T$2),100),HELPER!$A$2:$B$100,2,0))
T7: TERMIN SHEET INI (1-6)
T8: 5
B9: BERITA ACARA PRESTASI PEKERJAAN
B10: =TEXT($T$8,"00")&"/BAPP/"&DATA!$B$4
C12: ="Pada hari ini "&T3&" tanggal "&T4&" bulan "&T5&" tahun "&T6&" ("&V2&"), kami yang bertandatangan di bawah ini:"
C14: I | D14: =DATA!$B$14 | E14: : | F14: ="Selaku "&DATA!$B$16&", Proyek "&DATA!$B$7&", dalam hal ini bertindak untuk dan atas nama "&DATA!$B$17&", yang berkedudukan di "&DATA!$B$18
U15: Selaku Project Coordinator, Proyek Design and Build Perkuatan Dermaga Barat JICT Pelabuhan Tanjung Priok, dalam hal ini bertindak untuk dan atas nama Waskita - Nindya KSO, yang berkedudukan di Gedung Waskita IDSurvey TowerJl. M.T. Haryono Kavling No.10, Jatinegara, Jakarta Timur
F16: yang selanjutnya disebut PIHAK PERTAMA
C18: II | D18: =DATA!$B$22 | E18: : | F18: ="Selaku "&DATA!$B$23&" "&DATA!$B$24&", dalam hal ini bertindak untuk dan atas nama "&DATA!$B$24&" yang berkedudukan di "&DATA!$B$25
F19: yang selanjutnya disebut PIHAK KEDUA
C21: ="Menerangkan bahwa kedua belah pihak telah setuju dan sepakat melakukan pemeriksaan pekerjaan sesuai dengan lampiran SPKP Nomor "&DATA!$B$4&", dan menyetujui prestasi pekerjaan berdasakan :"
C23: 1 | D23: Kontrak / SPK No. dan Tanggal | G23: : | H23: =DATA!$B$4 | L23: , tanggal : | M23: =TEXT(DATA!$B$5,"[$-21]dd mmmm yyyy")
C24: 2 | D24: Nilai Kontrak | G24: : | H24: Rp. | I24: =#REF! | K24: (Exclude PPN)
C25: 3 | D25: Waktu pelaksanaan | G25: : | H25: =TEXT(DATA!$B$8,"[$-21]dd mmmm yyyy") | J25: s.d. | K25: =TEXT(DATA!$B$9,"[$-21]dd mmmm yyyy")
C26: Dengan rincian sebagai berikut :
J28: Volume | K28: Realisasi Volume Pekerjaan | Q28: Jumlah
J29: sesuai | K29: B A | L29: Periode Ini | M29: B A | N29: B A | O29: Sisa yang | P29: Harga | Q29: Harga
B30: No | C30: Macam Pekerjaan | J30: SPK / | K30: s / d | M30: s / d | N30: yang | O30: belum | P30: Satuan | Q30: yang
J31: Kontrak | K31: yang lalu | M31: Saat Ini | N31: ditagihkan | O31: di BA kan | Q31: ditagihkan
B32: 1 | C32: 2 | J32: 3 | K32: 4 | L32: 5 | M32: 6 = 4+5 | N32: 7 | O32: 8 = 3 - 6 | P32: 9 | Q32: 10 = 7 x 9
C34: ='rincian 5'!C11
B35: =#REF! | D35: =IF(#REF!<>"",#REF!,IF(#REF!<>"",#REF!,""))
B36: =#REF! | D36: =IF(#REF!<>"",#REF!,IF(#REF!<>"",#REF!,""))
B37: =#REF! | D37: =IF(#REF!<>"",#REF!,IF(#REF!<>"",#REF!,"")) | J37: =#REF! | K37: ='rincian 5'!S14 | L37: ='rincian 5'!U14 | M37: =K37+L37 | N37: =L37 | O37: =J37-M37 | P37: =#REF! | Q37: =N37*P37
B38: =#REF! | D38: =IF(#REF!<>"",#REF!,IF(#REF!<>"",#REF!,"")) | J38: =#REF! | K38: ='rincian 5'!S15 | L38: ='rincian 5'!U15 | M38: =K38+L38 | N38: =L38 | O38: =J38-M38 | P38: =#REF! | Q38: =N38*P38
B39: =#REF! | D39: =IF(#REF!<>"",#REF!,IF(#REF!<>"",#REF!,"")) | J39: =#REF! | K39: ='rincian 5'!S16 | L39: ='rincian 5'!U16 | M39: =K39+L39 | N39: =L39 | O39: =J39-M39 | P39: =#REF! | Q39: =N39*P39
B40: =#REF! | D40: =IF(#REF!<>"",#REF!,IF(#REF!<>"",#REF!,"")) | J40: =#REF! | K40: ='rincian 5'!S17 | L40: ='rincian 5'!U17 | M40: =K40+L40 | N40: =L40 | O40: =J40-M40 | P40: =#REF! | Q40: =N40*P40
B41: =#REF! | D41: =IF(#REF!<>"",#REF!,IF(#REF!<>"",#REF!,""))
B42: =#REF! | D42: =IF(#REF!<>"",#REF!,IF(#REF!<>"",#REF!,"")) | J42: =#REF! | K42: ='rincian 5'!S19 | L42: ='rincian 5'!U19 | M42: =K42+L42 | N42: =L42 | O42: =J42-M42 | P42: =#REF! | Q42: =N42*P42
B43: =#REF! | D43: =IF(#REF!<>"",#REF!,IF(#REF!<>"",#REF!,"")) | J43: =#REF! | K43: ='rincian 5'!S20 | L43: ='rincian 5'!U20 | M43: =K43+L43 | N43: =L43 | O43: =J43-M43 | P43: =#REF! | Q43: =N43*P43
B44: =#REF! | D44: =IF(#REF!<>"",#REF!,IF(#REF!<>"",#REF!,"")) | J44: =#REF! | K44: ='rincian 5'!S21 | L44: ='rincian 5'!U21 | M44: =K44+L44 | N44: =L44 | O44: =J44-M44 | P44: =#REF! | Q44: =N44*P44
B45: =#REF! | D45: =IF(#REF!<>"",#REF!,IF(#REF!<>"",#REF!,"")) | J45: =#REF! | K45: ='rincian 5'!S22 | L45: ='rincian 5'!U22 | M45: =K45+L45 | N45: =L45 | O45: =J45-M45 | P45: =#REF! | Q45: =N45*P45
B46: =#REF! | D46: =IF(#REF!<>"",#REF!,IF(#REF!<>"",#REF!,"")) | J46: =#REF! | K46: ='rincian 5'!S23 | L46: ='rincian 5'!U23 | M46: =K46+L46 | N46: =L46 | O46: =J46-M46 | P46: =#REF! | Q46: =N46*P46
B47: =#REF! | D47: =IF(#REF!<>"",#REF!,IF(#REF!<>"",#REF!,"")) | J47: =#REF! | K47: ='rincian 5'!S24 | L47: ='rincian 5'!U24 | M47: =K47+L47 | N47: =L47 | O47: =J47-M47 | P47: =#REF! | Q47: =N47*P47
B48: =#REF! | D48: =IF(#REF!<>"",#REF!,IF(#REF!<>"",#REF!,""))
...

Sheet BAPP 6
T2: {=INDEX(DATA!$B$99:$B$104,$T$8)} | V2: =TEXT($T$2,"[$-21]dd mmmm yyyy") | W2: =TEXT(T2,"[$-21]dd mmmm yyyy")
T3: =TEXT($T$2,"[$-21]dddd")
T4: =VLOOKUP(DAY($T$2),HELPER!$A$2:$B$100,2,0)
T5: =TEXT($T$2,"[$-21]mmmm")
T6: ="Dua Ribu"&IF(MOD(YEAR($T$2),100)=0,""," "&VLOOKUP(MOD(YEAR($T$2),100),HELPER!$A$2:$B$100,2,0))
T7: TERMIN SHEET INI (1-6)
T8: 6
B9: BERITA ACARA PRESTASI PEKERJAAN
B10: =TEXT($T$8,"00")&"/BAPP/"&DATA!$B$4
C12: ="Pada hari ini "&T3&" tanggal "&T4&" bulan "&T5&" tahun "&T6&" ("&V2&"), kami yang bertandatangan di bawah ini:"
C14: I | D14: =DATA!$B$14 | E14: : | F14: ="Selaku "&DATA!$B$16&", Proyek "&DATA!$B$7&", dalam hal ini bertindak untuk dan atas nama "&DATA!$B$17&", yang berkedudukan di "&DATA!$B$18
U15: Selaku Project Coordinator, Proyek Design and Build Perkuatan Dermaga Barat JICT Pelabuhan Tanjung Priok, dalam hal ini bertindak untuk dan atas nama Waskita - Nindya KSO, yang berkedudukan di Gedung Waskita IDSurvey TowerJl. M.T. Haryono Kavling No.10, Jatinegara, Jakarta Timur
F16: yang selanjutnya disebut PIHAK PERTAMA
C18: II | D18: =DATA!$B$22 | E18: : | F18: ="Selaku "&DATA!$B$23&" "&DATA!$B$24&", dalam hal ini bertindak untuk dan atas nama "&DATA!$B$24&" yang berkedudukan di "&DATA!$B$25
F19: yang selanjutnya disebut PIHAK KEDUA
C21: ="Menerangkan bahwa kedua belah pihak telah setuju dan sepakat melakukan pemeriksaan pekerjaan sesuai dengan lampiran SPKP Nomor "&DATA!$B$4&", dan menyetujui prestasi pekerjaan berdasakan :"
C23: 1 | D23: Kontrak / SPK No. dan Tanggal | G23: : | H23: =DATA!$B$4 | L23: , tanggal : | M23: =TEXT(DATA!$B$5,"[$-21]dd mmmm yyyy")
C24: 2 | D24: Nilai Kontrak | G24: : | H24: Rp. | I24: =#REF! | K24: (Exclude PPN)
C25: 3 | D25: Waktu pelaksanaan | G25: : | H25: =TEXT(DATA!$B$8,"[$-21]dd mmmm yyyy") | J25: s.d. | K25: =TEXT(DATA!$B$9,"[$-21]dd mmmm yyyy")
C26: Dengan rincian sebagai berikut :
J28: Volume | K28: Realisasi Volume Pekerjaan | Q28: Jumlah
J29: sesuai | K29: B A | L29: Periode Ini | M29: B A | N29: B A | O29: Sisa yang | P29: Harga | Q29: Harga
B30: No | C30: Macam Pekerjaan | J30: SPK / | K30: s / d | M30: s / d | N30: yang | O30: belum | P30: Satuan | Q30: yang
J31: Kontrak | K31: yang lalu | M31: Saat Ini | N31: ditagihkan | O31: di BA kan | Q31: ditagihkan
B32: 1 | C32: 2 | J32: 3 | K32: 4 | L32: 5 | M32: 6 = 4+5 | N32: 7 | O32: 8 = 3 - 6 | P32: 9 | Q32: 10 = 7 x 9
C34: ='rincian 6'!C11
B35: =#REF! | D35: =IF(#REF!<>"",#REF!,IF(#REF!<>"",#REF!,""))
B36: =#REF! | D36: =IF(#REF!<>"",#REF!,IF(#REF!<>"",#REF!,""))
B37: =#REF! | D37: =IF(#REF!<>"",#REF!,IF(#REF!<>"",#REF!,"")) | J37: =#REF! | K37: ='rincian 6'!S14 | L37: ='rincian 6'!U14 | M37: =K37+L37 | N37: =L37 | O37: =J37-M37 | P37: =#REF! | Q37: =N37*P37
B38: =#REF! | D38: =IF(#REF!<>"",#REF!,IF(#REF!<>"",#REF!,"")) | J38: =#REF! | K38: ='rincian 6'!S15 | L38: ='rincian 6'!U15 | M38: =K38+L38 | N38: =L38 | O38: =J38-M38 | P38: =#REF! | Q38: =N38*P38
B39: =#REF! | D39: =IF(#REF!<>"",#REF!,IF(#REF!<>"",#REF!,"")) | J39: =#REF! | K39: ='rincian 6'!S16 | L39: ='rincian 6'!U16 | M39: =K39+L39 | N39: =L39 | O39: =J39-M39 | P39: =#REF! | Q39: =N39*P39
B40: =#REF! | D40: =IF(#REF!<>"",#REF!,IF(#REF!<>"",#REF!,"")) | J40: =#REF! | K40: ='rincian 6'!S17 | L40: ='rincian 6'!U17 | M40: =K40+L40 | N40: =L40 | O40: =J40-M40 | P40: =#REF! | Q40: =N40*P40
B41: =#REF! | D41: =IF(#REF!<>"",#REF!,IF(#REF!<>"",#REF!,""))
B42: =#REF! | D42: =IF(#REF!<>"",#REF!,IF(#REF!<>"",#REF!,"")) | J42: =#REF! | K42: ='rincian 6'!S19 | L42: ='rincian 6'!U19 | M42: =K42+L42 | N42: =L42 | O42: =J42-M42 | P42: =#REF! | Q42: =N42*P42
B43: =#REF! | D43: =IF(#REF!<>"",#REF!,IF(#REF!<>"",#REF!,"")) | J43: =#REF! | K43: ='rincian 6'!S20 | L43: ='rincian 6'!U20 | M43: =K43+L43 | N43: =L43 | O43: =J43-M43 | P43: =#REF! | Q43: =N43*P43
B44: =#REF! | D44: =IF(#REF!<>"",#REF!,IF(#REF!<>"",#REF!,"")) | J44: =#REF! | K44: ='rincian 6'!S21 | L44: ='rincian 6'!U21 | M44: =K44+L44 | N44: =L44 | O44: =J44-M44 | P44: =#REF! | Q44: =N44*P44
B45: =#REF! | D45: =IF(#REF!<>"",#REF!,IF(#REF!<>"",#REF!,"")) | J45: =#REF! | K45: ='rincian 6'!S22 | L45: ='rincian 6'!U22 | M45: =K45+L45 | N45: =L45 | O45: =J45-M45 | P45: =#REF! | Q45: =N45*P45
B46: =#REF! | D46: =IF(#REF!<>"",#REF!,IF(#REF!<>"",#REF!,"")) | J46: =#REF! | K46: ='rincian 6'!S23 | L46: ='rincian 6'!U23 | M46: =K46+L46 | N46: =L46 | O46: =J46-M46 | P46: =#REF! | Q46: =N46*P46
B47: =#REF! | D47: =IF(#REF!<>"",#REF!,IF(#REF!<>"",#REF!,"")) | J47: =#REF! | K47: ='rincian 6'!S24 | L47: ='rincian 6'!U24 | M47: =K47+L47 | N47: =L47 | O47: =J47-M47 | P47: =#REF! | Q47: =N47*P47
B48: =#REF! | D48: =IF(#REF!<>"",#REF!,IF(#REF!<>"",#REF!,""))
...

Sheet rincian 
AL1: =IF(COUNTIF($AT$13:$AT$37,"DITOLAK*")>0,"DITOLAK: ada item yang volumenya MELEBIHI kontrak - cek kolom STATUS (AT) yang merah",IF(ROUND($AS$7,6)>1,"DITOLAK: total bobot "&TEXT($AS$7,"0.00%")&" sudah melebihi 100% kontrak",IF(ROUND($AS$7,6)=1,"PROGRES SUDAH 100% - VOLUME KONTRAK HABIS. Penambahan progres akan ditolak.","AMAN - sisa bobot yang belum dialokasikan "&TEXT(1-$AS$7,"0.00%"))))
B3: RINCIAN PROGRES PEKERJAAN
B4: =UPPER(""&DATA!$B$6) | AL4: TERMIN SHEET INI (1-6)
B5: PROYEK DESIGN AND BUILD PERKUATAN DERMAGA BARAT JICT PELABUHAN TANJUNG PRIOK | AL5: 1
B7: NO. | C7: URAIAN | J7: SAT | K7: SESUAI DENGAN RAB | N7: VOLUME | O7: SAT | P7: HARGA SATUAN (Rp) | Q7: JUMLAH HARGA (Rp) | R7: BOBOT | S7: S/D PERIODE LALU | U7: PERIODE INI | W7: S/D PERIODE INI | AL7: ALOKASI VOLUME PROGRES PER TERMIN - OTOMATIS dari sheet 'REKAP PROGRES' kolom J:O (TERMIN 1-6). Jangan diisi manual di sini. | AR7: TOTAL BOBOT TERALOKASI | AS7: {=SUMPRODUCT(IFERROR($AR$13:$AR$37/$N$13:$N$37*$R$13:$R$37,0))}
R8: ( % ) | S8: PROGRES | T8: BOBOT | U8: PROGRES | V8: BOBOT | W8: PROGRES | X8: BOBOT
K9: VOLUME | L9: HARGA SATUAN | M9: JUMLAH HARGA | AL9: TERMIN 1 | AM9: TERMIN 2 | AN9: TERMIN 3 | AO9: TERMIN 4 | AP9: TERMIN 5 | AQ9: TERMIN 6 | AR9: TOTAL ALOKASI | AS9: SISA VOLUME | AT9: STATUS
C11: =DATA!$B$6 | AC11: PROYEK DESIGN AND BUILD PERKUATAN DERMAGA BARAT JICT PELABUHAN TANJUNG PRIOK
C12: =lamp1!C14
B13: =lamp1!B15 | C13: =lamp1!C15 | AL13: ='REKAP PROGRES'!J5 | AM13: ='REKAP PROGRES'!K5 | AN13: ='REKAP PROGRES'!L5 | AO13: ='REKAP PROGRES'!M5 | AP13: ='REKAP PROGRES'!N5 | AQ13: ='REKAP PROGRES'!O5 | AR13: =SUM($AL13:$AQ13) | AS13: =IF(N(N15)=0,"",N15-AR13) | AT13: =IF(N(N15)=0,IF(AR13>0,"DITOLAK - BARIS BUKAN ITEM",""),IF(AR13>N15,"DITOLAK - MELEBIHI KONTRAK",IF(AR13=N15,"HABIS - 100%","")))
C14: =lamp1!C16 | AL14: ='REKAP PROGRES'!J6 | AM14: ='REKAP PROGRES'!K6 | AN14: ='REKAP PROGRES'!L6 | AO14: ='REKAP PROGRES'!M6 | AP14: ='REKAP PROGRES'!N6 | AQ14: ='REKAP PROGRES'!O6 | AR14: =SUM($AL14:$AQ14) | AS14: =IF(N(N16)=0,"",N16-AR14) | AT14: =IF(N(N16)=0,IF(AR14>0,"DITOLAK - BARIS BUKAN ITEM",""),IF(AR14>N16,"DITOLAK - MELEBIHI KONTRAK",IF(AR14=N16,"HABIS - 100%","")))
B15: =lamp1!B17 | D15: =lamp1!D17 | N15: =lamp1!H17 | O15: =lamp1!I17 | P15: =lamp1!J17 | Q15: =P15*N15 | R15: =IFERROR(Q15/$Q$38,0) | S15: =IF($AL$5<=1,0,SUM(OFFSET($AL15,0,0,1,$AL$5-1))) | T15: =IFERROR(S15/N15*R15,0) | U15: {=IFERROR(INDEX($AL15:$AQ15,$AL$5),0)} | V15: =IFERROR(U15/N15*R15,0) | W15: =S15+U15 | X15: =T15+V15 | AL15: ='REKAP PROGRES'!J7 | AM15: ='REKAP PROGRES'!K7 | AN15: ='REKAP PROGRES'!L7 | AO15: ='REKAP PROGRES'!M7 | AP15: ='REKAP PROGRES'!N7 | AQ15: ='REKAP PROGRES'!O7 | AR15: =SUM($AL15:$AQ15) | AS15: =IF(N(N17)=0,"",N17-AR15) | AT15: =IF(N(N17)=0,IF(AR15>0,"DITOLAK - BARIS BUKAN ITEM",""),IF(AR15>N17,"DITOLAK - MELEBIHI KONTRAK",IF(AR15=N17,"HABIS - 100%","")))
B16: =lamp1!B18 | D16: =lamp1!D18 | N16: =lamp1!H18 | O16: =lamp1!I18 | P16: =lamp1!J18 | Q16: =P16*N16 | R16: =IFERROR(Q16/$Q$38,0) | S16: =IF($AL$5<=1,0,SUM(OFFSET($AL16,0,0,1,$AL$5-1))) | T16: =IFERROR(S16/N16*R16,0) | U16: {=IFERROR(INDEX($AL16:$AQ16,$AL$5),0)} | V16: =IFERROR(U16/N16*R16,0) | W16: =S16+U16 | X16: =T16+V16 | AL16: ='REKAP PROGRES'!J8 | AM16: ='REKAP PROGRES'!K8 | AN16: ='REKAP PROGRES'!L8 | AO16: ='REKAP PROGRES'!M8 | AP16: ='REKAP PROGRES'!N8 | AQ16: ='REKAP PROGRES'!O8 | AR16: =SUM($AL16:$AQ16) | AS16: =IF(N(N18)=0,"",N18-AR16) | AT16: =IF(N(N18)=0,IF(AR16>0,"DITOLAK - BARIS BUKAN ITEM",""),IF(AR16>N18,"DITOLAK - MELEBIHI KONTRAK",IF(AR16=N18,"HABIS - 100%","")))
B17: =lamp1!B19 | D17: =lamp1!D19 | N17: =lamp1!H19 | O17: =lamp1!I19 | P17: =lamp1!J19 | Q17: =P17*N17 | R17: =IFERROR(Q17/$Q$38,0) | S17: =IF($AL$5<=1,0,SUM(OFFSET($AL17,0,0,1,$AL$5-1))) | T17: =IFERROR(S17/N17*R17,0) | U17: {=IFERROR(INDEX($AL17:$AQ17,$AL$5),0)} | V17: =IFERROR(U17/N17*R17,0) | W17: =S17+U17 | X17: =T17+V17 | AL17: ='REKAP PROGRES'!J9 | AM17: ='REKAP PROGRES'!K9 | AN17: ='REKAP PROGRES'!L9 | AO17: ='REKAP PROGRES'!M9 | AP17: ='REKAP PROGRES'!N9 | AQ17: ='REKAP PROGRES'!O9 | AR17: =SUM($AL17:$AQ17) | AS17: =IF(N(N19)=0,"",N19-AR17) | AT17: =IF(N(N19)=0,IF(AR17>0,"DITOLAK - BARIS BUKAN ITEM",""),IF(AR17>N19,"DITOLAK - MELEBIHI KONTRAK",IF(AR17=N19,"HABIS - 100%","")))
B18: =lamp1!B20 | D18: =lamp1!D20 | N18: =lamp1!H20 | O18: =lamp1!I20 | P18: =lamp1!J20 | Q18: =P18*N18 | R18: =IFERROR(Q18/$Q$38,0) | S18: =IF($AL$5<=1,0,SUM(OFFSET($AL18,0,0,1,$AL$5-1))) | T18: =IFERROR(S18/N18*R18,0) | U18: {=IFERROR(INDEX($AL18:$AQ18,$AL$5),0)} | V18: =IFERROR(U18/N18*R18,0) | W18: =S18+U18 | X18: =T18+V18 | AL18: ='REKAP PROGRES'!J10 | AM18: ='REKAP PROGRES'!K10 | AN18: ='REKAP PROGRES'!L10 | AO18: ='REKAP PROGRES'!M10 | AP18: ='REKAP PROGRES'!N10 | AQ18: ='REKAP PROGRES'!O10 | AR18: =SUM($AL18:$AQ18) | AS18: =IF(N(N20)=0,"",N20-AR18) | AT18: =IF(N(N20)=0,IF(AR18>0,"DITOLAK - BARIS BUKAN ITEM",""),IF(AR18>N20,"DITOLAK - MELEBIHI KONTRAK",IF(AR18=N20,"HABIS - 100%","")))
B19: =lamp1!B21 | D19: =lamp1!D21 | N19: =lamp1!H21 | O19: =lamp1!I21 | P19: =lamp1!J21 | Q19: =P19*N19 | R19: =IFERROR(Q19/$Q$38,0) | S19: =IF($AL$5<=1,0,SUM(OFFSET($AL19,0,0,1,$AL$5-1))) | T19: =IFERROR(S19/N19*R19,0) | U19: {=IFERROR(INDEX($AL19:$AQ19,$AL$5),0)} | V19: =IFERROR(U19/N19*R19,0) | W19: =S19+U19 | X19: =T19+V19 | AL19: ='REKAP PROGRES'!J11 | AM19: ='REKAP PROGRES'!K11 | AN19: ='REKAP PROGRES'!L11 | AO19: ='REKAP PROGRES'!M11 | AP19: ='REKAP PROGRES'!N11 | AQ19: ='REKAP PROGRES'!O11 | AR19: =SUM($AL19:$AQ19) | AS19: =IF(N(N21)=0,"",N21-AR19) | AT19: =IF(N(N21)=0,IF(AR19>0,"DITOLAK - BARIS BUKAN ITEM",""),IF(AR19>N21,"DITOLAK - MELEBIHI KONTRAK",IF(AR19=N21,"HABIS - 100%","")))
B20: =lamp1!B22 | D20: =lamp1!D22 | N20: =lamp1!H22 | O20: =lamp1!I22 | P20: =lamp1!J22 | Q20: =P20*N20 | R20: =IFERROR(Q20/$Q$38,0) | S20: =IF($AL$5<=1,0,SUM(OFFSET($AL20,0,0,1,$AL$5-1))) | T20: =IFERROR(S20/N20*R20,0) | U20: {=IFERROR(INDEX($AL20:$AQ20,$AL$5),0)} | V20: =IFERROR(U20/N20*R20,0) | W20: =S20+U20 | X20: =T20+V20 | AL20: ='REKAP PROGRES'!J12 | AM20: ='REKAP PROGRES'!K12 | AN20: ='REKAP PROGRES'!L12 | AO20: ='REKAP PROGRES'!M12 | AP20: ='REKAP PROGRES'!N12 | AQ20: ='REKAP PROGRES'!O12 | AR20: =SUM($AL20:$AQ20) | AS20: =IF(N(N22)=0,"",N22-AR20) | AT20: =IF(N(N22)=0,IF(AR20>0,"DITOLAK - BARIS BUKAN ITEM",""),IF(AR20>N22,"DITOLAK - MELEBIHI KONTRAK",IF(AR20=N22,"HABIS - 100%","")))
B21: =lamp1!B23 | D21: =lamp1!D23 | N21: =lamp1!H23 | O21: =lamp1!I23 | P21: =lamp1!J23 | Q21: 0 | R21: =IFERROR(Q21/$Q$38,0) | S21: =IF($AL$5<=1,0,SUM(OFFSET($AL21,0,0,1,$AL$5-1))) | T21: =IFERROR(S21/N21*R21,0) | U21: {=IFERROR(INDEX($AL21:$AQ21,$AL$5),0)} | V21: =IFERROR(U21/N21*R21,0) | W21: =S21+U21 | X21: =T21+V21 | AS21: =IF(N(N23)=0,"",N23-AR21) | AT21: =IF(N(N23)=0,IF(AR21>0,"DITOLAK - BARIS BUKAN ITEM",""),IF(AR21>N23,"DITOLAK - MELEBIHI KONTRAK",IF(AR21=N23,"HABIS - 100%","")))
B22: =lamp1!B24 | D22: =lamp1!D24 | N22: =lamp1!H24 | O22: =lamp1!I24 | P22: =lamp1!J24 | Q22: =P22*N22 | R22: =IFERROR(Q22/$Q$38,0) | S22: =IF($AL$5<=1,0,SUM(OFFSET($AL22,0,0,1,$AL$5-1))) | T22: =IFERROR(S22/N22*R22,0) | U22: {=IFERROR(INDEX($AL22:$AQ22,$AL$5),0)} | V22: =IFERROR(U22/N22*R22,0) | W22: =S22+U22 | X22: =T22+V22 | AS22: =IF(N(N24)=0,"",N24-AR22) | AT22: =IF(N(N24)=0,IF(AR22>0,"DITOLAK - BARIS BUKAN ITEM",""),IF(AR22>N24,"DITOLAK - MELEBIHI KONTRAK",IF(AR22=N24,"HABIS - 100%","")))
AS23: =IF(N(N25)=0,"",N25-AR23) | AT23: =IF(N(N25)=0,IF(AR23>0,"DITOLAK - BARIS BUKAN ITEM",""),IF(AR23>N25,"DITOLAK - MELEBIHI KONTRAK",IF(AR23=N25,"HABIS - 100%","")))
