Workbook

Sheet INPUT
A1: INPUT VARIABEL TAGIHAN PENGADAAN BARANG
A2: Isi hanya sel berwarna kuning. Seluruh sheet SPM / BAPM / BAP / REKAP mengambil nilai dari sini.
A4: A. DATA PROYEK / PIHAK PERTAMA (TETAP)
A5: Nama Pekerjaan | B5: Design and Build Perkuatan Dermaga Barat JICT Pelabuhan Tanjung Priok
A6: Nama KSO | B6: WASKITA - NINDYA, KSO
A7: Divisi | B7: DIVISI OPERASI II INFRASTRUKTUR I
A8: Alamat KSO | B8: Jl. M.T. Haryono Kavling 10 RT.11/RW.11, Cipinang Cempedak, Jatinegara, Jakarta Timur 13340
A9: Nama Pihak Pertama | B9: DEDY HARIYANTO
A10: Jabatan Pihak Pertama | B10: Kepala Proyek
A11: Jabatan pada Tanda Tangan | B11: Kepala Proyek
A12: Nama Penerima Material | B12: JOKO SUPRIYONO
A13: Jabatan Penerima Material | B13: Kasi Pengadaan, Logistik, & Peralatan
A14: Kontak Korespondensi | B14: Joko Supriyono / Hp. 085272750122
A15: NPWP KSO | B15: 1000000007845820
A16: Nama Kuasa KSO | B16: STEFANUS GUNAWAN
A17: Jabatan Kuasa KSO | B17: Kuasa KSO
A18: Batas Nilai Wajib Kuasa KSO (Rp) | B18: 3000000000
A19: Penanda Tangan Pihak Pertama (BAP) | B19: =IF(AND(ITEM!$C$107>$B$18,$B$16<>""),$B$16,$B$9)
A20: Jabatan Penanda Tangan (BAP) | B20: =IF(AND(ITEM!$C$107>$B$18,$B$16<>""),$B$17,$B$10)
A22: B. PIHAK KEDUA (VARIABEL)
A23: Nama Direktur | C23: manual
A24: Nama Perusahaan
A25: Alamat Perusahaan
A26: NPWP
A27: Nama Rekening | B27: =B24
A28: Nomor Rekening | C28: manual
A29: Bank | C29: manual
A30: Email Vendor
A31: C. DATA SPM / PEMESANAN (VARIABEL)
A32: Nomor Urut SPM
A33: Kode Proyek | B33: 1726012
A34: Tahun | B34: 2026
A35: Nomor SPM Lengkap | B35: =B32&"/SPM/WK-NK.KSO/PDBJ/"&B33&"/"&B34
A36: Tanggal Pemesanan (SPM)
A37: Tanggal Akhir Pengadaan
A38: Bulan Tagihan | B38: =TEXT(B36,"mmmm yyyy")
A39: Lokasi Serah Terima / Franco | B39: ="Proyek Pekerjaan "&B5
A40: Kota Tanda Tangan | B40: Jakarta
A42: D. SYARAT PEMBAYARAN & KEBERTERIMAAN (VARIABEL)
A43: Tempo Pembayaran (hari kerja) | B43: 60
...

Sheet ITEM
A1: DAFTAR ITEM PENGADAAN & ALOKASI PENGIRIMAN PER TERMIN
A2: ="SPM No. "&INPUT!B35&" | Vendor : "&INPUT!B24 | O2: KOLOM BANTU (jangan diubah) — harga satuan material yang diterima per termin, dipakai untuk memilih 3 material termahal di BAP
A3: NO. | B3: URAIAN | C3: SATUAN | D3: VOLUME KONTRAK | E3: HARGA SATUAN (Rp) | F3: JUMLAH HARGA (Rp) | G3: VOL. BAP-1 | H3: VOL. BAP-2 | I3: VOL. BAP-3 | J3: VOL. BAP-4 | K3: TOTAL TERKIRIM | L3: SISA VOLUME | M3: STATUS / NOTIFIKASI | N3: Catatan: alokasi pengiriman dibagi ke kolom VOL. BAP-1 s/d VOL. BAP-4 (maks. 4 termin). Setiap termin punya sheet sendiri: BAPM/BAP (termin 1), BAPM 2/BAP 2, BAPM 3/BAP 3, BAPM 4/BAP 4. Progres kumulatif otomatis berlanjut sampai 100% bila TOTAL TERKIRIM = VOLUME KONTRAK. Slot item 9-20 disembunyikan dalam grup baris pada SPM (21-32) & BAPM (34-45). | O3: HRG BAP-1 | P3: HRG BAP-2 | Q3: HRG BAP-3 | R3: HRG BAP-4
A4: =IF($B4="","",ROW()-3) | F4: =IF($B4="","",$D4*$E4) | K4: =IF($B4="","",SUM($G4:$J4)) | L4: =IF($B4="","",$D4-$K4) | M4: =IF($B4="","",IF($L4<0,"⚠ OVER "&TEXT(-$L4,"#,##0.00")&" "&$C4&" - kurangi alokasi BAP",IF($L4=0,"✓ Alokasi penuh (sisa 0)","Sisa "&TEXT($L4,"#,##0.00")&" "&$C4))) | O4: =IF(OR($B4="",N(G4)=0),"",$E4-ROW()/1000000) | P4: =IF(OR($B4="",N(H4)=0),"",$E4-ROW()/1000000) | Q4: =IF(OR($B4="",N(I4)=0),"",$E4-ROW()/1000000) | R4: =IF(OR($B4="",N(J4)=0),"",$E4-ROW()/1000000)
A5: =IF($B5="","",ROW()-3) | F5: =IF($B5="","",$D5*$E5) | K5: =IF($B5="","",SUM($G5:$J5)) | L5: =IF($B5="","",$D5-$K5) | M5: =IF($B5="","",IF($L5<0,"⚠ OVER "&TEXT(-$L5,"#,##0.00")&" "&$C5&" - kurangi alokasi BAP",IF($L5=0,"✓ Alokasi penuh (sisa 0)","Sisa "&TEXT($L5,"#,##0.00")&" "&$C5))) | O5: =IF(OR($B5="",N(G5)=0),"",$E5-ROW()/1000000) | P5: =IF(OR($B5="",N(H5)=0),"",$E5-ROW()/1000000) | Q5: =IF(OR($B5="",N(I5)=0),"",$E5-ROW()/1000000) | R5: =IF(OR($B5="",N(J5)=0),"",$E5-ROW()/1000000)
A6: =IF($B6="","",ROW()-3) | F6: =IF($B6="","",$D6*$E6) | K6: =IF($B6="","",SUM($G6:$J6)) | L6: =IF($B6="","",$D6-$K6) | M6: =IF($B6="","",IF($L6<0,"⚠ OVER "&TEXT(-$L6,"#,##0.00")&" "&$C6&" - kurangi alokasi BAP",IF($L6=0,"✓ Alokasi penuh (sisa 0)","Sisa "&TEXT($L6,"#,##0.00")&" "&$C6))) | O6: =IF(OR($B6="",N(G6)=0),"",$E6-ROW()/1000000) | P6: =IF(OR($B6="",N(H6)=0),"",$E6-ROW()/1000000) | Q6: =IF(OR($B6="",N(I6)=0),"",$E6-ROW()/1000000) | R6: =IF(OR($B6="",N(J6)=0),"",$E6-ROW()/1000000)
A7: =IF($B7="","",ROW()-3) | F7: =IF($B7="","",$D7*$E7) | K7: =IF($B7="","",SUM($G7:$J7)) | L7: =IF($B7="","",$D7-$K7) | M7: =IF($B7="","",IF($L7<0,"⚠ OVER "&TEXT(-$L7,"#,##0.00")&" "&$C7&" - kurangi alokasi BAP",IF($L7=0,"✓ Alokasi penuh (sisa 0)","Sisa "&TEXT($L7,"#,##0.00")&" "&$C7))) | O7: =IF(OR($B7="",N(G7)=0),"",$E7-ROW()/1000000) | P7: =IF(OR($B7="",N(H7)=0),"",$E7-ROW()/1000000) | Q7: =IF(OR($B7="",N(I7)=0),"",$E7-ROW()/1000000) | R7: =IF(OR($B7="",N(J7)=0),"",$E7-ROW()/1000000)
A8: =IF($B8="","",ROW()-3) | F8: =IF($B8="","",$D8*$E8) | K8: =IF($B8="","",SUM($G8:$J8)) | L8: =IF($B8="","",$D8-$K8) | M8: =IF($B8="","",IF($L8<0,"⚠ OVER "&TEXT(-$L8,"#,##0.00")&" "&$C8&" - kurangi alokasi BAP",IF($L8=0,"✓ Alokasi penuh (sisa 0)","Sisa "&TEXT($L8,"#,##0.00")&" "&$C8))) | O8: =IF(OR($B8="",N(G8)=0),"",$E8-ROW()/1000000) | P8: =IF(OR($B8="",N(H8)=0),"",$E8-ROW()/1000000) | Q8: =IF(OR($B8="",N(I8)=0),"",$E8-ROW()/1000000) | R8: =IF(OR($B8="",N(J8)=0),"",$E8-ROW()/1000000)
A9: =IF($B9="","",ROW()-3) | F9: =IF($B9="","",$D9*$E9) | K9: =IF($B9="","",SUM($G9:$J9)) | L9: =IF($B9="","",$D9-$K9) | M9: =IF($B9="","",IF($L9<0,"⚠ OVER "&TEXT(-$L9,"#,##0.00")&" "&$C9&" - kurangi alokasi BAP",IF($L9=0,"✓ Alokasi penuh (sisa 0)","Sisa "&TEXT($L9,"#,##0.00")&" "&$C9))) | O9: =IF(OR($B9="",N(G9)=0),"",$E9-ROW()/1000000) | P9: =IF(OR($B9="",N(H9)=0),"",$E9-ROW()/1000000) | Q9: =IF(OR($B9="",N(I9)=0),"",$E9-ROW()/1000000) | R9: =IF(OR($B9="",N(J9)=0),"",$E9-ROW()/1000000)
A10: =IF($B10="","",ROW()-3) | F10: =IF($B10="","",$D10*$E10) | K10: =IF($B10="","",SUM($G10:$J10)) | L10: =IF($B10="","",$D10-$K10) | M10: =IF($B10="","",IF($L10<0,"⚠ OVER "&TEXT(-$L10,"#,##0.00")&" "&$C10&" - kurangi alokasi BAP",IF($L10=0,"✓ Alokasi penuh (sisa 0)","Sisa "&TEXT($L10,"#,##0.00")&" "&$C10))) | O10: =IF(OR($B10="",N(G10)=0),"",$E10-ROW()/1000000) | P10: =IF(OR($B10="",N(H10)=0),"",$E10-ROW()/1000000) | Q10: =IF(OR($B10="",N(I10)=0),"",$E10-ROW()/1000000) | R10: =IF(OR($B10="",N(J10)=0),"",$E10-ROW()/1000000)
A11: =IF($B11="","",ROW()-3) | F11: =IF($B11="","",$D11*$E11) | K11: =IF($B11="","",SUM($G11:$J11)) | L11: =IF($B11="","",$D11-$K11) | M11: =IF($B11="","",IF($L11<0,"⚠ OVER "&TEXT(-$L11,"#,##0.00")&" "&$C11&" - kurangi alokasi BAP",IF($L11=0,"✓ Alokasi penuh (sisa 0)","Sisa "&TEXT($L11,"#,##0.00")&" "&$C11))) | O11: =IF(OR($B11="",N(G11)=0),"",$E11-ROW()/1000000) | P11: =IF(OR($B11="",N(H11)=0),"",$E11-ROW()/1000000) | Q11: =IF(OR($B11="",N(I11)=0),"",$E11-ROW()/1000000) | R11: =IF(OR($B11="",N(J11)=0),"",$E11-ROW()/1000000)
A12: =IF($B12="","",ROW()-3) | F12: =IF($B12="","",$D12*$E12) | K12: =IF($B12="","",SUM($G12:$J12)) | L12: =IF($B12="","",$D12-$K12) | M12: =IF($B12="","",IF($L12<0,"⚠ OVER "&TEXT(-$L12,"#,##0.00")&" "&$C12&" - kurangi alokasi BAP",IF($L12=0,"✓ Alokasi penuh (sisa 0)","Sisa "&TEXT($L12,"#,##0.00")&" "&$C12))) | O12: =IF(OR($B12="",N(G12)=0),"",$E12-ROW()/1000000) | P12: =IF(OR($B12="",N(H12)=0),"",$E12-ROW()/1000000) | Q12: =IF(OR($B12="",N(I12)=0),"",$E12-ROW()/1000000) | R12: =IF(OR($B12="",N(J12)=0),"",$E12-ROW()/1000000)
A13: =IF($B13="","",ROW()-3) | F13: =IF($B13="","",$D13*$E13) | K13: =IF($B13="","",SUM($G13:$J13)) | L13: =IF($B13="","",$D13-$K13) | M13: =IF($B13="","",IF($L13<0,"⚠ OVER "&TEXT(-$L13,"#,##0.00")&" "&$C13&" - kurangi alokasi BAP",IF($L13=0,"✓ Alokasi penuh (sisa 0)","Sisa "&TEXT($L13,"#,##0.00")&" "&$C13))) | O13: =IF(OR($B13="",N(G13)=0),"",$E13-ROW()/1000000) | P13: =IF(OR($B13="",N(H13)=0),"",$E13-ROW()/1000000) | Q13: =IF(OR($B13="",N(I13)=0),"",$E13-ROW()/1000000) | R13: =IF(OR($B13="",N(J13)=0),"",$E13-ROW()/1000000)
A14: =IF($B14="","",ROW()-3) | F14: =IF($B14="","",$D14*$E14) | K14: =IF($B14="","",SUM($G14:$J14)) | L14: =IF($B14="","",$D14-$K14) | M14: =IF($B14="","",IF($L14<0,"⚠ OVER "&TEXT(-$L14,"#,##0.00")&" "&$C14&" - kurangi alokasi BAP",IF($L14=0,"✓ Alokasi penuh (sisa 0)","Sisa "&TEXT($L14,"#,##0.00")&" "&$C14))) | O14: =IF(OR($B14="",N(G14)=0),"",$E14-ROW()/1000000) | P14: =IF(OR($B14="",N(H14)=0),"",$E14-ROW()/1000000) | Q14: =IF(OR($B14="",N(I14)=0),"",$E14-ROW()/1000000) | R14: =IF(OR($B14="",N(J14)=0),"",$E14-ROW()/1000000)
A15: =IF($B15="","",ROW()-3) | F15: =IF($B15="","",$D15*$E15) | K15: =IF($B15="","",SUM($G15:$J15)) | L15: =IF($B15="","",$D15-$K15) | M15: =IF($B15="","",IF($L15<0,"⚠ OVER "&TEXT(-$L15,"#,##0.00")&" "&$C15&" - kurangi alokasi BAP",IF($L15=0,"✓ Alokasi penuh (sisa 0)","Sisa "&TEXT($L15,"#,##0.00")&" "&$C15))) | O15: =IF(OR($B15="",N(G15)=0),"",$E15-ROW()/1000000) | P15: =IF(OR($B15="",N(H15)=0),"",$E15-ROW()/1000000) | Q15: =IF(OR($B15="",N(I15)=0),"",$E15-ROW()/1000000) | R15: =IF(OR($B15="",N(J15)=0),"",$E15-ROW()/1000000)
... A103: =IF($B103="","",ROW()-3) | F103: =IF($B103="","",$D103*$E103) | K103: =IF($B103="","",SUM($G103:$J103)) | L103: =IF($B103="","",$D103-$K103) | M103: =IF($B103="","",IF($L103<0,"⚠ OVER "&TEXT(-$L103,"#,##0.00")&" "&$C103&" - kurangi alokasi BAP",IF($L103=0,"✓ Alokasi penuh (sisa 0)","Sisa "&TEXT($L103,"#,##0.00")&" "&$C103))) | O103: =IF(OR($B103="",N(G103)=0),"",$E103-ROW()/1000000) | P103: =IF(OR($B103="",N(H103)=0),"",$E103-ROW()/1000000) | Q103: =IF(OR($B103="",N(I103)=0),"",$E103-ROW()/1000000) | R103: =IF(OR($B103="",N(J103)=0),"",$E103-ROW()/1000000)
B104: JUMLAH (Exclude PPN) | D104: =SUM(D4:D103) | F104: =SUM(F4:F103) | G104: =SUM(G4:G103) | H104: =SUM(H4:H103) | I104: =SUM(I4:I103) | J104: =SUM(J4:J103) | K104: =SUM(K4:K103) | L104: =SUM(L4:L103) | M104: =IF(COUNTIF($L$4:$L$103,"<0")>0,"⚠ ADA "&COUNTIF($L$4:$L$103,"<0")&" ITEM OVER ALOKASI - PENGADAAN TIDAK SESUAI PENERIMAAN","✓ Semua alokasi valid (tidak ada sisa minus)")
B106: RINGKASAN NILAI KONTRAK
B107: Nilai Kontrak (Exclude PPN) | C107: =F104
B108: PPN | C108: =ROUND(C107*INPUT!$B$45,0)
B109: TOTAL (Include PPN) | C109: =C107+C108

Sheet SPM
A4: SURAT PEMESANAN MATERIAL
A5: ="Nomor : "&INPUT!$B$35
A7: Kepada Yth,
A8: Nama Vendor | C8: =": "&INPUT!$B$24
A9: Alamat | C9: =": "&INPUT!$B$25
A10: NPWP | C10: =": "&INPUT!$B$26
A12: NO. | B12: URAIAN | D12: SATUAN | E12: VOLUME | F12: HARGA ( Rp. ) | G12: JUMLAH ( Rp. )
A13: =IF(ITEM!$B4="","",ITEM!$A4) | B13: =IF(ITEM!$B4="","",ITEM!$B4) | D13: =IF(ITEM!$B4="","",ITEM!$C4) | E13: =IF(ITEM!$B4="","",ITEM!$D4) | F13: =IF(ITEM!$B4="","",ITEM!$E4) | G13: =IF(ITEM!$B4="","",ITEM!$F4)
A14: =IF(ITEM!$B5="","",ITEM!$A5) | B14: =IF(ITEM!$B5="","",ITEM!$B5) | D14: =IF(ITEM!$B5="","",ITEM!$C5) | E14: =IF(ITEM!$B5="","",ITEM!$D5) | F14: =IF(ITEM!$B5="","",ITEM!$E5) | G14: =IF(ITEM!$B5="","",ITEM!$F5)
A15: =IF(ITEM!$B6="","",ITEM!$A6) | B15: =IF(ITEM!$B6="","",ITEM!$B6) | D15: =IF(ITEM!$B6="","",ITEM!$C6) | E15: =IF(ITEM!$B6="","",ITEM!$D6) | F15: =IF(ITEM!$B6="","",ITEM!$E6) | G15: =IF(ITEM!$B6="","",ITEM!$F6)
A16: =IF(ITEM!$B7="","",ITEM!$A7) | B16: =IF(ITEM!$B7="","",ITEM!$B7) | D16: =IF(ITEM!$B7="","",ITEM!$C7) | E16: =IF(ITEM!$B7="","",ITEM!$D7) | F16: =IF(ITEM!$B7="","",ITEM!$E7) | G16: =IF(ITEM!$B7="","",ITEM!$F7)
A17: =IF(ITEM!$B8="","",ITEM!$A8) | B17: =IF(ITEM!$B8="","",ITEM!$B8) | D17: =IF(ITEM!$B8="","",ITEM!$C8) | E17: =IF(ITEM!$B8="","",ITEM!$D8) | F17: =IF(ITEM!$B8="","",ITEM!$E8) | G17: =IF(ITEM!$B8="","",ITEM!$F8)
A18: =IF(ITEM!$B9="","",ITEM!$A9) | B18: =IF(ITEM!$B9="","",ITEM!$B9) | D18: =IF(ITEM!$B9="","",ITEM!$C9) | E18: =IF(ITEM!$B9="","",ITEM!$D9) | F18: =IF(ITEM!$B9="","",ITEM!$E9) | G18: =IF(ITEM!$B9="","",ITEM!$F9)
A19: =IF(ITEM!$B10="","",ITEM!$A10) | B19: =IF(ITEM!$B10="","",ITEM!$B10) | D19: =IF(ITEM!$B10="","",ITEM!$C10) | E19: =IF(ITEM!$B10="","",ITEM!$D10) | F19: =IF(ITEM!$B10="","",ITEM!$E10) | G19: =IF(ITEM!$B10="","",ITEM!$F10)
A20: =IF(ITEM!$B11="","",ITEM!$A11) | B20: =IF(ITEM!$B11="","",ITEM!$B11) | D20: =IF(ITEM!$B11="","",ITEM!$C11) | E20: =IF(ITEM!$B11="","",ITEM!$D11) | F20: =IF(ITEM!$B11="","",ITEM!$E11) | G20: =IF(ITEM!$B11="","",ITEM!$F11)
A21: =IF(ITEM!$B12="","",ITEM!$A12) | B21: =IF(ITEM!$B12="","",ITEM!$B12) | D21: =IF(ITEM!$B12="","",ITEM!$C12) | E21: =IF(ITEM!$B12="","",ITEM!$D12) | F21: =IF(ITEM!$B12="","",ITEM!$E12) | G21: =IF(ITEM!$B12="","",ITEM!$F12)
A22: =IF(ITEM!$B13="","",ITEM!$A13) | B22: =IF(ITEM!$B13="","",ITEM!$B13) | D22: =IF(ITEM!$B13="","",ITEM!$C13) | E22: =IF(ITEM!$B13="","",ITEM!$D13) | F22: =IF(ITEM!$B13="","",ITEM!$E13) | G22: =IF(ITEM!$B13="","",ITEM!$F13)
A23: =IF(ITEM!$B14="","",ITEM!$A14) | B23: =IF(ITEM!$B14="","",ITEM!$B14) | D23: =IF(ITEM!$B14="","",ITEM!$C14) | E23: =IF(ITEM!$B14="","",ITEM!$D14) | F23: =IF(ITEM!$B14="","",ITEM!$E14) | G23: =IF(ITEM!$B14="","",ITEM!$F14)
A24: =IF(ITEM!$B15="","",ITEM!$A15) | B24: =IF(ITEM!$B15="","",ITEM!$B15) | D24: =IF(ITEM!$B15="","",ITEM!$C15) | E24: =IF(ITEM!$B15="","",ITEM!$D15) | F24: =IF(ITEM!$B15="","",ITEM!$E15) | G24: =IF(ITEM!$B15="","",ITEM!$F15)
... A112: =IF(ITEM!$B103="","",ITEM!$A103) | B112: =IF(ITEM!$B103="","",ITEM!$B103) | D112: =IF(ITEM!$B103="","",ITEM!$C103) | E112: =IF(ITEM!$B103="","",ITEM!$D103) | F112: =IF(ITEM!$B103="","",ITEM!$E103) | G112: =IF(ITEM!$B103="","",ITEM!$F103)
A113: JUMLAH | G113: =ITEM!$C$107
A114: PPN | G114: =ITEM!$C$108
A115: TOTAL | G115: =ITEM!$C$109
A116: Terbilang | C116: =": "&HELPER!$L$4
A118: SYARAT - SYARAT :
A119: 1 | B119: Kondisi Harga / Nilai : | D119: ="Rp "&HELPER!$H$27
A120: 2 | B120: Harga tersebut diatas sudah termasuk:
B121: - Material On Site Lokasi Proyek
B122: - Termasuk PPh, dan pajak - pajak lain yang timbul akibat dari pengadaan material tersebut.
B123: - Biaya lain yang timbul baik secara langsung ataupun tidak langsung terkait pengadaan dan Pengiriman Material.
A124: 3 | B124: ="Waktu pengadaan material / alat terhitung sejak tanggal dikeluarkannya sampai dengan Tanggal. "&TEXT(INPUT!$B$37,"dd mmmm yyyy")
A125: 4 | B125: ="Lokasi Serah Terima Material / Franco : "&INPUT!$B$39
A126: 5 | B126: Rincian spesifikasi dan ukuran realisasi pengiriman material tersebut ke proyek mengacu pada spesifikasi Proyek dilaksanakan berdasarkan permintaan dari proyek, yang merupakan satu bagian yang tak terpisahkan dari SPM/ kontrak SPPM
A127: 6 | B127: Harga satuan tersebut diatas berlaku mengikat selama jangka waktu kontrak, dan volume sesuai kontrak terpenuhi seluruhnya
A128: 7 | B128: Pengadaan material / alat harus kwalitas baik dan sesuai dengan spesifikasi yang disetujui oleh konsultan/pengawas pekerjaan dan pemilik proyek
A129: 8 | B129: Material yang tidak sesuai dengan permintaan akan di tolak dan supplier harus mengganti dengan material baru sesuai permintaan atas biaya supplier
A130: 9 | B130: ="Pembayaran dilakukan dengan Reguler Tempo "&INPUT!$B$43&" ("&INPUT!$B$44&") hari Kerja, setelah invoice diterima dengan benar dan lengkap,"
B131: sesuai administrasi Waskita - NINDYA, KSO dan dilampiri Berita Acara Pembayaran yang ditandatangani oleh kedua belah pihak.
B132: Pembayaran dapat disalurkan ke rekening kami sebagai berikut :
B133: ="Ac. Name : "&INPUT!$B$27
...

Sheet BAPM
N1: TERMIN SHEET INI (jangan diubah kecuali perlu) | O1: 1
N2: Tanggal BAPM/BAP | O2: {=IF(IFERROR(INDEX(INPUT!$B$55:$B$58,$O$1),0)=0,"",INDEX(INPUT!$B$55:$B$58,$O$1))}
N3: Hari | O3: =IF($O$2="","",TEXT($O$2,"dddd"))
N4: Tanggal (huruf) | O4: =IF($O$2="","",IF(DAY($O$2)<20,VLOOKUP(DAY($O$2),HELPER!$A$3:$B$22,2,0),IF(DAY($O$2)<30,TRIM("Dua Puluh "&VLOOKUP(DAY($O$2)-20,HELPER!$A$3:$B$22,2,0)),TRIM("Tiga Puluh "&VLOOKUP(DAY($O$2)-30,HELPER!$A$3:$B$22,2,0)))))
A5: BERITA ACARA PENERIMAAN MATERIAL (BAPM) | N5: Bulan | O5: =IF($O$2="","",TEXT($O$2,"mmmm"))
A6: {=IF($O$2="","","Nomor : "&INDEX(INPUT!$C$55:$C$58,$O$1))} | N6: Tahun (huruf) | O6: =IF($O$2="","",TRIM(IF(INT(YEAR($O$2)/1000)=1,"Seribu ",IF(INT(YEAR($O$2)/1000)=0,"",IF(INT(INT(YEAR($O$2)/1000)/100)=0,"",IF(INT(INT(YEAR($O$2)/1000)/100)=1,"Seratus ",VLOOKUP(INT(INT(YEAR($O$2)/1000)/100),HELPER!$A$3:$B$22,2,0)&" Ratus "))&IF(MOD(INT(YEAR($O$2)/1000),100)=0,"",IF(MOD(INT(YEAR($O$2)/1000),100)<20,VLOOKUP(MOD(INT(YEAR($O$2)/1000),100),HELPER!$A$3:$B$22,2,0),VLOOKUP(INT(MOD(INT(YEAR($O$2)/1000),100)/10),HELPER!$A$3:$B$22,2,0)&" Puluh "&IF(MOD(INT(YEAR($O$2)/1000),10)=0,"",VLOOKUP(MOD(INT(YEAR($O$2)/1000),10),HELPER!$A$3:$B$22,2,0)))))&" Ribu ")&IF(MOD(YEAR($O$2),1000)=0,"",IF(INT(MOD(YEAR($O$2),1000)/100)=0,"",IF(INT(MOD(YEAR($O$2),1000)/100)=1,"Seratus ",VLOOKUP(INT(MOD(YEAR($O$2),1000)/100),HELPER!$A$3:$B$22,2,0)&" Ratus "))&IF(MOD(MOD(YEAR($O$2),1000),100)=0,"",IF(MOD(MOD(YEAR($O$2),1000),100)<20,VLOOKUP(MOD(MOD(YEAR($O$2),1000),100),HELPER!$A$3:$B$22,2,0),VLOOKUP(INT(MOD(MOD(YEAR($O$2),1000),100)/10),HELPER!$A$3:$B$22,2,0)&" Puluh "&IF(MOD(MOD(YEAR($O$2),1000),10)=0,"",VLOOKUP(MOD(MOD(YEAR($O$2),1000),10),HELPER!$A$3:$B$22,2,0)))))))
N7: Kalimat pembuka | O7: =IF($O$2="","","Pada hari ini "&$O$3&", tanggal "&$O$4&" bulan "&$O$5&" tahun "&$O$6&" ("&TEXT($O$2,"dd/mm/yyyy")&")")
A8: =IF($O$7="","",$O$7&", telah diterima alat :")
N9: Nilai diterima | O9: =$K$135
A10: I. | B10: Dari | C10: =": "&UPPER(INPUT!$B$24) | N10: Kelompok miliar | O10: =INT(ROUND($O$9,0)/1000000000)
C11: ="Sebagai Pihak Kedua" | N11: Kelompok juta | O11: =MOD(INT(ROUND($O$9,0)/1000000),1000)
A12: II. | B12: Kepada | C12: =": "&UPPER(INPUT!$B$6)&" Proyek Pekerjaan "&INPUT!$B$5 | N12: Kelompok ribu | O12: =MOD(INT(ROUND($O$9,0)/1000),1000)
C13: ="Sebagai Pihak Pertama" | N13: Kelompok satuan | O13: =MOD(ROUND($O$9,0),1000)
N14: Terbilang | O14: =IF(ROUND($O$9,0)=0,"== Nol Rupiah ==","== "&TRIM(IF($O$10=0,"",IF($O$10=0,"",IF(INT($O$10/100)=0,"",IF(INT($O$10/100)=1,"Seratus ",VLOOKUP(INT($O$10/100),HELPER!$A$3:$B$22,2,0)&" Ratus "))&IF(MOD($O$10,100)=0,"",IF(MOD($O$10,100)<20,VLOOKUP(MOD($O$10,100),HELPER!$A$3:$B$22,2,0),VLOOKUP(INT(MOD($O$10,100)/10),HELPER!$A$3:$B$22,2,0)&" Puluh "&IF(MOD($O$10,10)=0,"",VLOOKUP(MOD($O$10,10),HELPER!$A$3:$B$22,2,0)))))&" Miliar ")&IF($O$11=0,"",IF($O$11=1,"Satu Juta ",IF($O$11=0,"",IF(INT($O$11/100)=0,"",IF(INT($O$11/100)=1,"Seratus ",VLOOKUP(INT($O$11/100),HELPER!$A$3:$B$22,2,0)&" Ratus "))&IF(MOD($O$11,100)=0,"",IF(MOD($O$11,100)<20,VLOOKUP(MOD($O$11,100),HELPER!$A$3:$B$22,2,0),VLOOKUP(INT(MOD($O$11,100)/10),HELPER!$A$3:$B$22,2,0)&" Puluh "&IF(MOD($O$11,10)=0,"",VLOOKUP(MOD($O$11,10),HELPER!$A$3:$B$22,2,0)))))&" Juta "))&IF($O$12=0,"",IF($O$12=1,"Seribu ",IF($O$12=0,"",IF(INT($O$12/100)=0,"",IF(INT($O$12/100)=1,"Seratus ",VLOOKUP(INT($O$12/100),HELPER!$A$3:$B$22,2,0)&" Ratus "))&IF(MOD($O$12,100)=0,"",IF(MOD($O$12,100)<20,VLOOKUP(MOD($O$12,100),HELPER!$A$3:$B$22,2,0),VLOOKUP(INT(MOD($O$12,100)/10),HELPER!$A$3:$B$22,2,0)&" Puluh "&IF(MOD($O$12,10)=0,"",VLOOKUP(MOD($O$12,10),HELPER!$A$3:$B$22,2,0)))))&" Ribu "))&IF($O$13=0,"",IF(INT($O$13/100)=0,"",IF(INT($O$13/100)=1,"Seratus ",VLOOKUP(INT($O$13/100),HELPER!$A$3:$B$22,2,0)&" Ratus "))&IF(MOD($O$13,100)=0,"",IF(MOD($O$13,100)<20,VLOOKUP(MOD($O$13,100),HELPER!$A$3:$B$22,2,0),VLOOKUP(INT(MOD($O$13,100)/10),HELPER!$A$3:$B$22,2,0)&" Puluh "&IF(MOD($O$13,10)=0,"",VLOOKUP(MOD($O$13,10),HELPER!$A$3:$B$22,2,0))))))&" Rupiah ==")
A15: Menerangkan bahwa kedua belah pihak telah setuju dan sepakat melakukan pemeriksaan pengadaan dan serah terima berdasarkan :
A17: 1 | B17: Kontrak/SPM No. | C17: =": "&INPUT!$B$35&" Tanggal : "&TEXT(INPUT!$B$36,"dd mmmm yyyy")
A18: 2 | B18: Nilai Kontrak | C18: =": Rp "&HELPER!$I$28&" (Exclude PPN)"
A19: 3 | B19: Waktu Pelaksanaan | C19: =": "&TEXT(INPUT!$B$36,"dd mmmm yyyy")&" s/d "&TEXT(INPUT!$B$37,"dd mmmm yyyy")
A21: Dengan rincian sebagai berikut,
A23: NO. | B23: JENIS ITEM | D23: VOLUME KONTRAK | E23: SAT | F23: PROGRES REAL VOLUME | J23: HARGA (Rp) | K23: JUMLAH HARGA (Rp)
F24: YG LALU | G24: SAAT INI | H24: SD. SAAT INI | I24: SISA
A25: 1 | B25: 2 | D25: 3 | E25: 4 | F25: 5 | G25: 6 | H25: 7=5+6 | I25: 8=3-7 | J25: 9 | K25: 10 = 6 x 9
A26: =IF(ITEM!$B4="","",ITEM!$A4) | B26: =IF(ITEM!$B4="","",ITEM!$B4) | D26: =IF(ITEM!$B4="","",ITEM!$D4) | E26: =IF(ITEM!$B4="","",ITEM!$C4) | F26: {=IF(ITEM!$B4="","",SUMPRODUCT((COLUMN(ITEM!$G4:$J4)-COLUMN(ITEM!$G4)+1<$O$1)*ITEM!$G4:$J4))} | G26: {=IF(ITEM!$B4="","",INDEX(ITEM!$G4:$J4,1,$O$1))} | H26: =IF(ITEM!$B4="","",$F26+$G26) | I26: =IF(ITEM!$B4="","",$D26-$H26) | J26: =IF(ITEM!$B4="","",ITEM!$E4) | K26: =IF(ITEM!$B4="","",$G26*$J26)
A27: =IF(ITEM!$B5="","",ITEM!$A5) | B27: =IF(ITEM!$B5="","",ITEM!$B5) | D27: =IF(ITEM!$B5="","",ITEM!$D5) | E27: =IF(ITEM!$B5="","",ITEM!$C5) | F27: {=IF(ITEM!$B5="","",SUMPRODUCT((COLUMN(ITEM!$G5:$J5)-COLUMN(ITEM!$G5)+1<$O$1)*ITEM!$G5:$J5))} | G27: {=IF(ITEM!$B5="","",INDEX(ITEM!$G5:$J5,1,$O$1))} | H27: =IF(ITEM!$B5="","",$F27+$G27) | I27: =IF(ITEM!$B5="","",$D27-$H27) | J27: =IF(ITEM!$B5="","",ITEM!$E5) | K27: =IF(ITEM!$B5="","",$G27*$J27)
A28: =IF(ITEM!$B6="","",ITEM!$A6) | B28: =IF(ITEM!$B6="","",ITEM!$B6) | D28: =IF(ITEM!$B6="","",ITEM!$D6) | E28: =IF(ITEM!$B6="","",ITEM!$C6) | F28: {=IF(ITEM!$B6="","",SUMPRODUCT((COLUMN(ITEM!$G6:$J6)-COLUMN(ITEM!$G6)+1<$O$1)*ITEM!$G6:$J6))} | G28: {=IF(ITEM!$B6="","",INDEX(ITEM!$G6:$J6,1,$O$1))} | H28: =IF(ITEM!$B6="","",$F28+$G28) | I28: =IF(ITEM!$B6="","",$D28-$H28) | J28: =IF(ITEM!$B6="","",ITEM!$E6) | K28: =IF(ITEM!$B6="","",$G28*$J28)
A29: =IF(ITEM!$B7="","",ITEM!$A7) | B29: =IF(ITEM!$B7="","",ITEM!$B7) | D29: =IF(ITEM!$B7="","",ITEM!$D7) | E29: =IF(ITEM!$B7="","",ITEM!$C7) | F29: {=IF(ITEM!$B7="","",SUMPRODUCT((COLUMN(ITEM!$G7:$J7)-COLUMN(ITEM!$G7)+1<$O$1)*ITEM!$G7:$J7))} | G29: {=IF(ITEM!$B7="","",INDEX(ITEM!$G7:$J7,1,$O$1))} | H29: =IF(ITEM!$B7="","",$F29+$G29) | I29: =IF(ITEM!$B7="","",$D29-$H29) | J29: =IF(ITEM!$B7="","",ITEM!$E7) | K29: =IF(ITEM!$B7="","",$G29*$J29)
A30: =IF(ITEM!$B8="","",ITEM!$A8) | B30: =IF(ITEM!$B8="","",ITEM!$B8) | D30: =IF(ITEM!$B8="","",ITEM!$D8) | E30: =IF(ITEM!$B8="","",ITEM!$C8) | F30: {=IF(ITEM!$B8="","",SUMPRODUCT((COLUMN(ITEM!$G8:$J8)-COLUMN(ITEM!$G8)+1<$O$1)*ITEM!$G8:$J8))} | G30: {=IF(ITEM!$B8="","",INDEX(ITEM!$G8:$J8,1,$O$1))} | H30: =IF(ITEM!$B8="","",$F30+$G30) | I30: =IF(ITEM!$B8="","",$D30-$H30) | J30: =IF(ITEM!$B8="","",ITEM!$E8) | K30: =IF(ITEM!$B8="","",$G30*$J30)
A31: =IF(ITEM!$B9="","",ITEM!$A9) | B31: =IF(ITEM!$B9="","",ITEM!$B9) | D31: =IF(ITEM!$B9="","",ITEM!$D9) | E31: =IF(ITEM!$B9="","",ITEM!$C9) | F31: {=IF(ITEM!$B9="","",SUMPRODUCT((COLUMN(ITEM!$G9:$J9)-COLUMN(ITEM!$G9)+1<$O$1)*ITEM!$G9:$J9))} | G31: {=IF(ITEM!$B9="","",INDEX(ITEM!$G9:$J9,1,$O$1))} | H31: =IF(ITEM!$B9="","",$F31+$G31) | I31: =IF(ITEM!$B9="","",$D31-$H31) | J31: =IF(ITEM!$B9="","",ITEM!$E9) | K31: =IF(ITEM!$B9="","",$G31*$J31)
A32: =IF(ITEM!$B10="","",ITEM!$A10) | B32: =IF(ITEM!$B10="","",ITEM!$B10) | D32: =IF(ITEM!$B10="","",ITEM!$D10) | E32: =IF(ITEM!$B10="","",ITEM!$C10) | F32: {=IF(ITEM!$B10="","",SUMPRODUCT((COLUMN(ITEM!$G10:$J10)-COLUMN(ITEM!$G10)+1<$O$1)*ITEM!$G10:$J10))} | G32: {=IF(ITEM!$B10="","",INDEX(ITEM!$G10:$J10,1,$O$1))} | H32: =IF(ITEM!$B10="","",$F32+$G32) | I32: =IF(ITEM!$B10="","",$D32-$H32) | J32: =IF(ITEM!$B10="","",ITEM!$E10) | K32: =IF(ITEM!$B10="","",$G32*$J32)
A33: =IF(ITEM!$B11="","",ITEM!$A11) | B33: =IF(ITEM!$B11="","",ITEM!$B11) | D33: =IF(ITEM!$B11="","",ITEM!$D11) | E33: =IF(ITEM!$B11="","",ITEM!$C11) | F33: {=IF(ITEM!$B11="","",SUMPRODUCT((COLUMN(ITEM!$G11:$J11)-COLUMN(ITEM!$G11)+1<$O$1)*ITEM!$G11:$J11))} | G33: {=IF(ITEM!$B11="","",INDEX(ITEM!$G11:$J11,1,$O$1))} | H33: =IF(ITEM!$B11="","",$F33+$G33) | I33: =IF(ITEM!$B11="","",$D33-$H33) | J33: =IF(ITEM!$B11="","",ITEM!$E11) | K33: =IF(ITEM!$B11="","",$G33*$J33)
A34: =IF(ITEM!$B12="","",ITEM!$A12) | B34: =IF(ITEM!$B12="","",ITEM!$B12) | D34: =IF(ITEM!$B12="","",ITEM!$D12) | E34: =IF(ITEM!$B12="","",ITEM!$C12) | F34: {=IF(ITEM!$B12="","",SUMPRODUCT((COLUMN(ITEM!$G12:$J12)-COLUMN(ITEM!$G12)+1<$O$1)*ITEM!$G12:$J12))} | G34: {=IF(ITEM!$B12="","",INDEX(ITEM!$G12:$J12,1,$O$1))} | H34: =IF(ITEM!$B12="","",$F34+$G34) | I34: =IF(ITEM!$B12="","",$D34-$H34) | J34: =IF(ITEM!$B12="","",ITEM!$E12) | K34: =IF(ITEM!$B12="","",$G34*$J34)
A35: =IF(ITEM!$B13="","",ITEM!$A13) | B35: =IF(ITEM!$B13="","",ITEM!$B13) | D35: =IF(ITEM!$B13="","",ITEM!$D13) | E35: =IF(ITEM!$B13="","",ITEM!$C13) | F35: {=IF(ITEM!$B13="","",SUMPRODUCT((COLUMN(ITEM!$G13:$J13)-COLUMN(ITEM!$G13)+1<$O$1)*ITEM!$G13:$J13))} | G35: {=IF(ITEM!$B13="","",INDEX(ITEM!$G13:$J13,1,$O$1))} | H35: =IF(ITEM!$B13="","",$F35+$G35) | I35: =IF(ITEM!$B13="","",$D35-$H35) | J35: =IF(ITEM!$B13="","",ITEM!$E13) | K35: =IF(ITEM!$B13="","",$G35*$J35)
A36: =IF(ITEM!$B14="","",ITEM!$A14) | B36: =IF(ITEM!$B14="","",ITEM!$B14) | D36: =IF(ITEM!$B14="","",ITEM!$D14) | E36: =IF(ITEM!$B14="","",ITEM!$C14) | F36: {=IF(ITEM!$B14="","",SUMPRODUCT((COLUMN(ITEM!$G14:$J14)-COLUMN(ITEM!$G14)+1<$O$1)*ITEM!$G14:$J14))} | G36: {=IF(ITEM!$B14="","",INDEX(ITEM!$G14:$J14,1,$O$1))} | H36: =IF(ITEM!$B14="","",$F36+$G36) | I36: =IF(ITEM!$B14="","",$D36-$H36) | J36: =IF(ITEM!$B14="","",ITEM!$E14) | K36: =IF(ITEM!$B14="","",$G36*$J36)
A37: =IF(ITEM!$B15="","",ITEM!$A15) | B37: =IF(ITEM!$B15="","",ITEM!$B15) | D37: =IF(ITEM!$B15="","",ITEM!$D15) | E37: =IF(ITEM!$B15="","",ITEM!$C15) | F37: {=IF(ITEM!$B15="","",SUMPRODUCT((COLUMN(ITEM!$G15:$J15)-COLUMN(ITEM!$G15)+1<$O$1)*ITEM!$G15:$J15))} | G37: {=IF(ITEM!$B15="","",INDEX(ITEM!$G15:$J15,1,$O$1))} | H37: =IF(ITEM!$B15="","",$F37+$G37) | I37: =IF(ITEM!$B15="","",$D37-$H37) | J37: =IF(ITEM!$B15="","",ITEM!$E15) | K37: =IF(ITEM!$B15="","",$G37*$J37)
... A125: =IF(ITEM!$B103="","",ITEM!$A103) | B125: =IF(ITEM!$B103="","",ITEM!$B103) | D125: =IF(ITEM!$B103="","",ITEM!$D103) | E125: =IF(ITEM!$B103="","",ITEM!$C103) | F125: {=IF(ITEM!$B103="","",SUMPRODUCT((COLUMN(ITEM!$G103:$J103)-COLUMN(ITEM!$G103)+1<$O$1)*ITEM!$G103:$J103))} | G125: {=IF(ITEM!$B103="","",INDEX(ITEM!$G103:$J103,1,$O$1))} | H125: =IF(ITEM!$B103="","",$F125+$G125) | I125: =IF(ITEM!$B103="","",$D125-$H125) | J125: =IF(ITEM!$B103="","",ITEM!$E103) | K125: =IF(ITEM!$B103="","",$G125*$J125)
A126: JUMLAH | K126: =SUM(K26:K125)
A128: Maka Pihak Kedua berhak menerima pembayaran dengan perhitungan sebagai berikut :
A129: 1 | B129: Prestasi s/d saat ini | G129: : | H129: =IF(ITEM!$C$107=0,0,SUMPRODUCT($H$26:$H$125,$J$26:$J$125)/ITEM!$C$107) | I129: = | K129: =ROUND(H129*ITEM!$C$107,0)
A130: 2 | B130: Prestasi yang lalu | G130: : | H130: =IF(ITEM!$C$107=0,0,SUMPRODUCT($F$26:$F$125,$J$26:$J$125)/ITEM!$C$107) | I130: = | K130: =ROUND(H130*ITEM!$C$107,0)
A131: 3 | B131: Prestasi yang dapat dibayarkan | G131: : | H131: =H129-H130 | I131: = | K131: =K129-K130
...

Sheet BAPM 2
N1: TERMIN SHEET INI (jangan diubah kecuali perlu) | O1: 2
N2: Tanggal BAPM/BAP | O2: {=IF(IFERROR(INDEX(INPUT!$B$55:$B$58,$O$1),0)=0,"",INDEX(INPUT!$B$55:$B$58,$O$1))}
N3: Hari | O3: =IF($O$2="","",TEXT($O$2,"dddd"))
N4: Tanggal (huruf) | O4: =IF($O$2="","",IF(DAY($O$2)<20,VLOOKUP(DAY($O$2),HELPER!$A$3:$B$22,2,0),IF(DAY($O$2)<30,TRIM("Dua Puluh "&VLOOKUP(DAY($O$2)-20,HELPER!$A$3:$B$22,2,0)),TRIM("Tiga Puluh "&VLOOKUP(DAY($O$2)-30,HELPER!$A$3:$B$22,2,0)))))
A5: BERITA ACARA PENERIMAAN MATERIAL (BAPM) | N5: Bulan | O5: =IF($O$2="","",TEXT($O$2,"mmmm"))
A6: {=IF($O$2="","","Nomor : "&INDEX(INPUT!$C$55:$C$58,$O$1))} | N6: Tahun (huruf) | O6: =IF($O$2="","",TRIM(IF(INT(YEAR($O$2)/1000)=1,"Seribu ",IF(INT(YEAR($O$2)/1000)=0,"",IF(INT(INT(YEAR($O$2)/1000)/100)=0,"",IF(INT(INT(YEAR($O$2)/1000)/100)=1,"Seratus ",VLOOKUP(INT(INT(YEAR($O$2)/1000)/100),HELPER!$A$3:$B$22,2,0)&" Ratus "))&IF(MOD(INT(YEAR($O$2)/1000),100)=0,"",IF(MOD(INT(YEAR($O$2)/1000),100)<20,VLOOKUP(MOD(INT(YEAR($O$2)/1000),100),HELPER!$A$3:$B$22,2,0),VLOOKUP(INT(MOD(INT(YEAR($O$2)/1000),100)/10),HELPER!$A$3:$B$22,2,0)&" Puluh "&IF(MOD(INT(YEAR($O$2)/1000),10)=0,"",VLOOKUP(MOD(INT(YEAR($O$2)/1000),10),HELPER!$A$3:$B$22,2,0)))))&" Ribu ")&IF(MOD(YEAR($O$2),1000)=0,"",IF(INT(MOD(YEAR($O$2),1000)/100)=0,"",IF(INT(MOD(YEAR($O$2),1000)/100)=1,"Seratus ",VLOOKUP(INT(MOD(YEAR($O$2),1000)/100),HELPER!$A$3:$B$22,2,0)&" Ratus "))&IF(MOD(MOD(YEAR($O$2),1000),100)=0,"",IF(MOD(MOD(YEAR($O$2),1000),100)<20,VLOOKUP(MOD(MOD(YEAR($O$2),1000),100),HELPER!$A$3:$B$22,2,0),VLOOKUP(INT(MOD(MOD(YEAR($O$2),1000),100)/10),HELPER!$A$3:$B$22,2,0)&" Puluh "&IF(MOD(MOD(YEAR($O$2),1000),10)=0,"",VLOOKUP(MOD(MOD(YEAR($O$2),1000),10),HELPER!$A$3:$B$22,2,0)))))))
N7: Kalimat pembuka | O7: =IF($O$2="","","Pada hari ini "&$O$3&", tanggal "&$O$4&" bulan "&$O$5&" tahun "&$O$6&" ("&TEXT($O$2,"dd/mm/yyyy")&")")
A8: =IF($O$7="","",$O$7&", telah diterima alat :")
N9: Nilai diterima | O9: =$K$135
A10: I. | B10: Dari | C10: =": "&UPPER(INPUT!$B$24) | N10: Kelompok miliar | O10: =INT(ROUND($O$9,0)/1000000000)
C11: ="Sebagai Pihak Kedua" | N11: Kelompok juta | O11: =MOD(INT(ROUND($O$9,0)/1000000),1000)
A12: II. | B12: Kepada | C12: =": "&UPPER(INPUT!$B$6)&" Proyek Pekerjaan "&INPUT!$B$5 | N12: Kelompok ribu | O12: =MOD(INT(ROUND($O$9,0)/1000),1000)
C13: ="Sebagai Pihak Pertama" | N13: Kelompok satuan | O13: =MOD(ROUND($O$9,0),1000)
N14: Terbilang | O14: =IF(ROUND($O$9,0)=0,"== Nol Rupiah ==","== "&TRIM(IF($O$10=0,"",IF($O$10=0,"",IF(INT($O$10/100)=0,"",IF(INT($O$10/100)=1,"Seratus ",VLOOKUP(INT($O$10/100),HELPER!$A$3:$B$22,2,0)&" Ratus "))&IF(MOD($O$10,100)=0,"",IF(MOD($O$10,100)<20,VLOOKUP(MOD($O$10,100),HELPER!$A$3:$B$22,2,0),VLOOKUP(INT(MOD($O$10,100)/10),HELPER!$A$3:$B$22,2,0)&" Puluh "&IF(MOD($O$10,10)=0,"",VLOOKUP(MOD($O$10,10),HELPER!$A$3:$B$22,2,0)))))&" Miliar ")&IF($O$11=0,"",IF($O$11=1,"Satu Juta ",IF($O$11=0,"",IF(INT($O$11/100)=0,"",IF(INT($O$11/100)=1,"Seratus ",VLOOKUP(INT($O$11/100),HELPER!$A$3:$B$22,2,0)&" Ratus "))&IF(MOD($O$11,100)=0,"",IF(MOD($O$11,100)<20,VLOOKUP(MOD($O$11,100),HELPER!$A$3:$B$22,2,0),VLOOKUP(INT(MOD($O$11,100)/10),HELPER!$A$3:$B$22,2,0)&" Puluh "&IF(MOD($O$11,10)=0,"",VLOOKUP(MOD($O$11,10),HELPER!$A$3:$B$22,2,0)))))&" Juta "))&IF($O$12=0,"",IF($O$12=1,"Seribu ",IF($O$12=0,"",IF(INT($O$12/100)=0,"",IF(INT($O$12/100)=1,"Seratus ",VLOOKUP(INT($O$12/100),HELPER!$A$3:$B$22,2,0)&" Ratus "))&IF(MOD($O$12,100)=0,"",IF(MOD($O$12,100)<20,VLOOKUP(MOD($O$12,100),HELPER!$A$3:$B$22,2,0),VLOOKUP(INT(MOD($O$12,100)/10),HELPER!$A$3:$B$22,2,0)&" Puluh "&IF(MOD($O$12,10)=0,"",VLOOKUP(MOD($O$12,10),HELPER!$A$3:$B$22,2,0)))))&" Ribu "))&IF($O$13=0,"",IF(INT($O$13/100)=0,"",IF(INT($O$13/100)=1,"Seratus ",VLOOKUP(INT($O$13/100),HELPER!$A$3:$B$22,2,0)&" Ratus "))&IF(MOD($O$13,100)=0,"",IF(MOD($O$13,100)<20,VLOOKUP(MOD($O$13,100),HELPER!$A$3:$B$22,2,0),VLOOKUP(INT(MOD($O$13,100)/10),HELPER!$A$3:$B$22,2,0)&" Puluh "&IF(MOD($O$13,10)=0,"",VLOOKUP(MOD($O$13,10),HELPER!$A$3:$B$22,2,0))))))&" Rupiah ==")
A15: Menerangkan bahwa kedua belah pihak telah setuju dan sepakat melakukan pemeriksaan pengadaan dan serah terima berdasarkan :
A17: 1 | B17: Kontrak/SPM No. | C17: =": "&INPUT!$B$35&" Tanggal : "&TEXT(INPUT!$B$36,"dd mmmm yyyy")
A18: 2 | B18: Nilai Kontrak | C18: =": Rp "&HELPER!$I$28&" (Exclude PPN)"
A19: 3 | B19: Waktu Pelaksanaan | C19: =": "&TEXT(INPUT!$B$36,"dd mmmm yyyy")&" s/d "&TEXT(INPUT!$B$37,"dd mmmm yyyy")
A21: Dengan rincian sebagai berikut,
A23: NO. | B23: JENIS ITEM | D23: VOLUME KONTRAK | E23: SAT | F23: PROGRES REAL VOLUME | J23: HARGA (Rp) | K23: JUMLAH HARGA (Rp)
F24: YG LALU | G24: SAAT INI | H24: SD. SAAT INI | I24: SISA
A25: 1 | B25: 2 | D25: 3 | E25: 4 | F25: 5 | G25: 6 | H25: 7=5+6 | I25: 8=3-7 | J25: 9 | K25: 10 = 6 x 9
A26: =IF(ITEM!$B4="","",ITEM!$A4) | B26: =IF(ITEM!$B4="","",ITEM!$B4) | D26: =IF(ITEM!$B4="","",ITEM!$D4) | E26: =IF(ITEM!$B4="","",ITEM!$C4) | F26: {=IF(ITEM!$B4="","",SUMPRODUCT((COLUMN(ITEM!$G4:$J4)-COLUMN(ITEM!$G4)+1<$O$1)*ITEM!$G4:$J4))} | G26: {=IF(ITEM!$B4="","",INDEX(ITEM!$G4:$J4,1,$O$1))} | H26: =IF(ITEM!$B4="","",$F26+$G26) | I26: =IF(ITEM!$B4="","",$D26-$H26) | J26: =IF(ITEM!$B4="","",ITEM!$E4) | K26: =IF(ITEM!$B4="","",$G26*$J26)
A27: =IF(ITEM!$B5="","",ITEM!$A5) | B27: =IF(ITEM!$B5="","",ITEM!$B5) | D27: =IF(ITEM!$B5="","",ITEM!$D5) | E27: =IF(ITEM!$B5="","",ITEM!$C5) | F27: {=IF(ITEM!$B5="","",SUMPRODUCT((COLUMN(ITEM!$G5:$J5)-COLUMN(ITEM!$G5)+1<$O$1)*ITEM!$G5:$J5))} | G27: {=IF(ITEM!$B5="","",INDEX(ITEM!$G5:$J5,1,$O$1))} | H27: =IF(ITEM!$B5="","",$F27+$G27) | I27: =IF(ITEM!$B5="","",$D27-$H27) | J27: =IF(ITEM!$B5="","",ITEM!$E5) | K27: =IF(ITEM!$B5="","",$G27*$J27)
A28: =IF(ITEM!$B6="","",ITEM!$A6) | B28: =IF(ITEM!$B6="","",ITEM!$B6) | D28: =IF(ITEM!$B6="","",ITEM!$D6) | E28: =IF(ITEM!$B6="","",ITEM!$C6) | F28: {=IF(ITEM!$B6="","",SUMPRODUCT((COLUMN(ITEM!$G6:$J6)-COLUMN(ITEM!$G6)+1<$O$1)*ITEM!$G6:$J6))} | G28: {=IF(ITEM!$B6="","",INDEX(ITEM!$G6:$J6,1,$O$1))} | H28: =IF(ITEM!$B6="","",$F28+$G28) | I28: =IF(ITEM!$B6="","",$D28-$H28) | J28: =IF(ITEM!$B6="","",ITEM!$E6) | K28: =IF(ITEM!$B6="","",$G28*$J28)
A29: =IF(ITEM!$B7="","",ITEM!$A7) | B29: =IF(ITEM!$B7="","",ITEM!$B7) | D29: =IF(ITEM!$B7="","",ITEM!$D7) | E29: =IF(ITEM!$B7="","",ITEM!$C7) | F29: {=IF(ITEM!$B7="","",SUMPRODUCT((COLUMN(ITEM!$G7:$J7)-COLUMN(ITEM!$G7)+1<$O$1)*ITEM!$G7:$J7))} | G29: {=IF(ITEM!$B7="","",INDEX(ITEM!$G7:$J7,1,$O$1))} | H29: =IF(ITEM!$B7="","",$F29+$G29) | I29: =IF(ITEM!$B7="","",$D29-$H29) | J29: =IF(ITEM!$B7="","",ITEM!$E7) | K29: =IF(ITEM!$B7="","",$G29*$J29)
A30: =IF(ITEM!$B8="","",ITEM!$A8) | B30: =IF(ITEM!$B8="","",ITEM!$B8) | D30: =IF(ITEM!$B8="","",ITEM!$D8) | E30: =IF(ITEM!$B8="","",ITEM!$C8) | F30: {=IF(ITEM!$B8="","",SUMPRODUCT((COLUMN(ITEM!$G8:$J8)-COLUMN(ITEM!$G8)+1<$O$1)*ITEM!$G8:$J8))} | G30: {=IF(ITEM!$B8="","",INDEX(ITEM!$G8:$J8,1,$O$1))} | H30: =IF(ITEM!$B8="","",$F30+$G30) | I30: =IF(ITEM!$B8="","",$D30-$H30) | J30: =IF(ITEM!$B8="","",ITEM!$E8) | K30: =IF(ITEM!$B8="","",$G30*$J30)
A31: =IF(ITEM!$B9="","",ITEM!$A9) | B31: =IF(ITEM!$B9="","",ITEM!$B9) | D31: =IF(ITEM!$B9="","",ITEM!$D9) | E31: =IF(ITEM!$B9="","",ITEM!$C9) | F31: {=IF(ITEM!$B9="","",SUMPRODUCT((COLUMN(ITEM!$G9:$J9)-COLUMN(ITEM!$G9)+1<$O$1)*ITEM!$G9:$J9))} | G31: {=IF(ITEM!$B9="","",INDEX(ITEM!$G9:$J9,1,$O$1))} | H31: =IF(ITEM!$B9="","",$F31+$G31) | I31: =IF(ITEM!$B9="","",$D31-$H31) | J31: =IF(ITEM!$B9="","",ITEM!$E9) | K31: =IF(ITEM!$B9="","",$G31*$J31)
A32: =IF(ITEM!$B10="","",ITEM!$A10) | B32: =IF(ITEM!$B10="","",ITEM!$B10) | D32: =IF(ITEM!$B10="","",ITEM!$D10) | E32: =IF(ITEM!$B10="","",ITEM!$C10) | F32: {=IF(ITEM!$B10="","",SUMPRODUCT((COLUMN(ITEM!$G10:$J10)-COLUMN(ITEM!$G10)+1<$O$1)*ITEM!$G10:$J10))} | G32: {=IF(ITEM!$B10="","",INDEX(ITEM!$G10:$J10,1,$O$1))} | H32: =IF(ITEM!$B10="","",$F32+$G32) | I32: =IF(ITEM!$B10="","",$D32-$H32) | J32: =IF(ITEM!$B10="","",ITEM!$E10) | K32: =IF(ITEM!$B10="","",$G32*$J32)
A33: =IF(ITEM!$B11="","",ITEM!$A11) | B33: =IF(ITEM!$B11="","",ITEM!$B11) | D33: =IF(ITEM!$B11="","",ITEM!$D11) | E33: =IF(ITEM!$B11="","",ITEM!$C11) | F33: {=IF(ITEM!$B11="","",SUMPRODUCT((COLUMN(ITEM!$G11:$J11)-COLUMN(ITEM!$G11)+1<$O$1)*ITEM!$G11:$J11))} | G33: {=IF(ITEM!$B11="","",INDEX(ITEM!$G11:$J11,1,$O$1))} | H33: =IF(ITEM!$B11="","",$F33+$G33) | I33: =IF(ITEM!$B11="","",$D33-$H33) | J33: =IF(ITEM!$B11="","",ITEM!$E11) | K33: =IF(ITEM!$B11="","",$G33*$J33)
A34: =IF(ITEM!$B12="","",ITEM!$A12) | B34: =IF(ITEM!$B12="","",ITEM!$B12) | D34: =IF(ITEM!$B12="","",ITEM!$D12) | E34: =IF(ITEM!$B12="","",ITEM!$C12) | F34: {=IF(ITEM!$B12="","",SUMPRODUCT((COLUMN(ITEM!$G12:$J12)-COLUMN(ITEM!$G12)+1<$O$1)*ITEM!$G12:$J12))} | G34: {=IF(ITEM!$B12="","",INDEX(ITEM!$G12:$J12,1,$O$1))} | H34: =IF(ITEM!$B12="","",$F34+$G34) | I34: =IF(ITEM!$B12="","",$D34-$H34) | J34: =IF(ITEM!$B12="","",ITEM!$E12) | K34: =IF(ITEM!$B12="","",$G34*$J34)
A35: =IF(ITEM!$B13="","",ITEM!$A13) | B35: =IF(ITEM!$B13="","",ITEM!$B13) | D35: =IF(ITEM!$B13="","",ITEM!$D13) | E35: =IF(ITEM!$B13="","",ITEM!$C13) | F35: {=IF(ITEM!$B13="","",SUMPRODUCT((COLUMN(ITEM!$G13:$J13)-COLUMN(ITEM!$G13)+1<$O$1)*ITEM!$G13:$J13))} | G35: {=IF(ITEM!$B13="","",INDEX(ITEM!$G13:$J13,1,$O$1))} | H35: =IF(ITEM!$B13="","",$F35+$G35) | I35: =IF(ITEM!$B13="","",$D35-$H35) | J35: =IF(ITEM!$B13="","",ITEM!$E13) | K35: =IF(ITEM!$B13="","",$G35*$J35)
A36: =IF(ITEM!$B14="","",ITEM!$A14) | B36: =IF(ITEM!$B14="","",ITEM!$B14) | D36: =IF(ITEM!$B14="","",ITEM!$D14) | E36: =IF(ITEM!$B14="","",ITEM!$C14) | F36: {=IF(ITEM!$B14="","",SUMPRODUCT((COLUMN(ITEM!$G14:$J14)-COLUMN(ITEM!$G14)+1<$O$1)*ITEM!$G14:$J14))} | G36: {=IF(ITEM!$B14="","",INDEX(ITEM!$G14:$J14,1,$O$1))} | H36: =IF(ITEM!$B14="","",$F36+$G36) | I36: =IF(ITEM!$B14="","",$D36-$H36) | J36: =IF(ITEM!$B14="","",ITEM!$E14) | K36: =IF(ITEM!$B14="","",$G36*$J36)
A37: =IF(ITEM!$B15="","",ITEM!$A15) | B37: =IF(ITEM!$B15="","",ITEM!$B15) | D37: =IF(ITEM!$B15="","",ITEM!$D15) | E37: =IF(ITEM!$B15="","",ITEM!$C15) | F37: {=IF(ITEM!$B15="","",SUMPRODUCT((COLUMN(ITEM!$G15:$J15)-COLUMN(ITEM!$G15)+1<$O$1)*ITEM!$G15:$J15))} | G37: {=IF(ITEM!$B15="","",INDEX(ITEM!$G15:$J15,1,$O$1))} | H37: =IF(ITEM!$B15="","",$F37+$G37) | I37: =IF(ITEM!$B15="","",$D37-$H37) | J37: =IF(ITEM!$B15="","",ITEM!$E15) | K37: =IF(ITEM!$B15="","",$G37*$J37)
... A125: =IF(ITEM!$B103="","",ITEM!$A103) | B125: =IF(ITEM!$B103="","",ITEM!$B103) | D125: =IF(ITEM!$B103="","",ITEM!$D103) | E125: =IF(ITEM!$B103="","",ITEM!$C103) | F125: {=IF(ITEM!$B103="","",SUMPRODUCT((COLUMN(ITEM!$G103:$J103)-COLUMN(ITEM!$G103)+1<$O$1)*ITEM!$G103:$J103))} | G125: {=IF(ITEM!$B103="","",INDEX(ITEM!$G103:$J103,1,$O$1))} | H125: =IF(ITEM!$B103="","",$F125+$G125) | I125: =IF(ITEM!$B103="","",$D125-$H125) | J125: =IF(ITEM!$B103="","",ITEM!$E103) | K125: =IF(ITEM!$B103="","",$G125*$J125)
A126: JUMLAH | K126: =SUM(K26:K125)
A128: Maka Pihak Kedua berhak menerima pembayaran dengan perhitungan sebagai berikut :
A129: 1 | B129: Prestasi s/d saat ini | G129: : | H129: =IF(ITEM!$C$107=0,0,SUMPRODUCT($H$26:$H$125,$J$26:$J$125)/ITEM!$C$107) | I129: = | K129: =ROUND(H129*ITEM!$C$107,0)
A130: 2 | B130: Prestasi yang lalu | G130: : | H130: =IF(ITEM!$C$107=0,0,SUMPRODUCT($F$26:$F$125,$J$26:$J$125)/ITEM!$C$107) | I130: = | K130: =ROUND(H130*ITEM!$C$107,0)
A131: 3 | B131: Prestasi yang dapat dibayarkan | G131: : | H131: =H129-H130 | I131: = | K131: =K129-K130
...

Sheet BAPM 3
N1: TERMIN SHEET INI (jangan diubah kecuali perlu) | O1: 3
N2: Tanggal BAPM/BAP | O2: {=IF(IFERROR(INDEX(INPUT!$B$55:$B$58,$O$1),0)=0,"",INDEX(INPUT!$B$55:$B$58,$O$1))}
N3: Hari | O3: =IF($O$2="","",TEXT($O$2,"dddd"))
N4: Tanggal (huruf) | O4: =IF($O$2="","",IF(DAY($O$2)<20,VLOOKUP(DAY($O$2),HELPER!$A$3:$B$22,2,0),IF(DAY($O$2)<30,TRIM("Dua Puluh "&VLOOKUP(DAY($O$2)-20,HELPER!$A$3:$B$22,2,0)),TRIM("Tiga Puluh "&VLOOKUP(DAY($O$2)-30,HELPER!$A$3:$B$22,2,0)))))
A5: BERITA ACARA PENERIMAAN MATERIAL (BAPM) | N5: Bulan | O5: =IF($O$2="","",TEXT($O$2,"mmmm"))
A6: {=IF($O$2="","","Nomor : "&INDEX(INPUT!$C$55:$C$58,$O$1))} | N6: Tahun (huruf) | O6: =IF($O$2="","",TRIM(IF(INT(YEAR($O$2)/1000)=1,"Seribu ",IF(INT(YEAR($O$2)/1000)=0,"",IF(INT(INT(YEAR($O$2)/1000)/100)=0,"",IF(INT(INT(YEAR($O$2)/1000)/100)=1,"Seratus ",VLOOKUP(INT(INT(YEAR($O$2)/1000)/100),HELPER!$A$3:$B$22,2,0)&" Ratus "))&IF(MOD(INT(YEAR($O$2)/1000),100)=0,"",IF(MOD(INT(YEAR($O$2)/1000),100)<20,VLOOKUP(MOD(INT(YEAR($O$2)/1000),100),HELPER!$A$3:$B$22,2,0),VLOOKUP(INT(MOD(INT(YEAR($O$2)/1000),100)/10),HELPER!$A$3:$B$22,2,0)&" Puluh "&IF(MOD(INT(YEAR($O$2)/1000),10)=0,"",VLOOKUP(MOD(INT(YEAR($O$2)/1000),10),HELPER!$A$3:$B$22,2,0)))))&" Ribu ")&IF(MOD(YEAR($O$2),1000)=0,"",IF(INT(MOD(YEAR($O$2),1000)/100)=0,"",IF(INT(MOD(YEAR($O$2),1000)/100)=1,"Seratus ",VLOOKUP(INT(MOD(YEAR($O$2),1000)/100),HELPER!$A$3:$B$22,2,0)&" Ratus "))&IF(MOD(MOD(YEAR($O$2),1000),100)=0,"",IF(MOD(MOD(YEAR($O$2),1000),100)<20,VLOOKUP(MOD(MOD(YEAR($O$2),1000),100),HELPER!$A$3:$B$22,2,0),VLOOKUP(INT(MOD(MOD(YEAR($O$2),1000),100)/10),HELPER!$A$3:$B$22,2,0)&" Puluh "&IF(MOD(MOD(YEAR($O$2),1000),10)=0,"",VLOOKUP(MOD(MOD(YEAR($O$2),1000),10),HELPER!$A$3:$B$22,2,0)))))))
N7: Kalimat pembuka | O7: =IF($O$2="","","Pada hari ini "&$O$3&", tanggal "&$O$4&" bulan "&$O$5&" tahun "&$O$6&" ("&TEXT($O$2,"dd/mm/yyyy")&")")
A8: =IF($O$7="","",$O$7&", telah diterima alat :")
N9: Nilai diterima | O9: =$K$135
A10: I. | B10: Dari | C10: =": "&UPPER(INPUT!$B$24) | N10: Kelompok miliar | O10: =INT(ROUND($O$9,0)/1000000000)
C11: ="Sebagai Pihak Kedua" | N11: Kelompok juta | O11: =MOD(INT(ROUND($O$9,0)/1000000),1000)
A12: II. | B12: Kepada | C12: =": "&UPPER(INPUT!$B$6)&" Proyek Pekerjaan "&INPUT!$B$5 | N12: Kelompok ribu | O12: =MOD(INT(ROUND($O$9,0)/1000),1000)
C13: ="Sebagai Pihak Pertama" | N13: Kelompok satuan | O13: =MOD(ROUND($O$9,0),1000)
N14: Terbilang | O14: =IF(ROUND($O$9,0)=0,"== Nol Rupiah ==","== "&TRIM(IF($O$10=0,"",IF($O$10=0,"",IF(INT($O$10/100)=0,"",IF(INT($O$10/100)=1,"Seratus ",VLOOKUP(INT($O$10/100),HELPER!$A$3:$B$22,2,0)&" Ratus "))&IF(MOD($O$10,100)=0,"",IF(MOD($O$10,100)<20,VLOOKUP(MOD($O$10,100),HELPER!$A$3:$B$22,2,0),VLOOKUP(INT(MOD($O$10,100)/10),HELPER!$A$3:$B$22,2,0)&" Puluh "&IF(MOD($O$10,10)=0,"",VLOOKUP(MOD($O$10,10),HELPER!$A$3:$B$22,2,0)))))&" Miliar ")&IF($O$11=0,"",IF($O$11=1,"Satu Juta ",IF($O$11=0,"",IF(INT($O$11/100)=0,"",IF(INT($O$11/100)=1,"Seratus ",VLOOKUP(INT($O$11/100),HELPER!$A$3:$B$22,2,0)&" Ratus "))&IF(MOD($O$11,100)=0,"",IF(MOD($O$11,100)<20,VLOOKUP(MOD($O$11,100),HELPER!$A$3:$B$22,2,0),VLOOKUP(INT(MOD($O$11,100)/10),HELPER!$A$3:$B$22,2,0)&" Puluh "&IF(MOD($O$11,10)=0,"",VLOOKUP(MOD($O$11,10),HELPER!$A$3:$B$22,2,0)))))&" Juta "))&IF($O$12=0,"",IF($O$12=1,"Seribu ",IF($O$12=0,"",IF(INT($O$12/100)=0,"",IF(INT($O$12/100)=1,"Seratus ",VLOOKUP(INT($O$12/100),HELPER!$A$3:$B$22,2,0)&" Ratus "))&IF(MOD($O$12,100)=0,"",IF(MOD($O$12,100)<20,VLOOKUP(MOD($O$12,100),HELPER!$A$3:$B$22,2,0),VLOOKUP(INT(MOD($O$12,100)/10),HELPER!$A$3:$B$22,2,0)&" Puluh "&IF(MOD($O$12,10)=0,"",VLOOKUP(MOD($O$12,10),HELPER!$A$3:$B$22,2,0)))))&" Ribu "))&IF($O$13=0,"",IF(INT($O$13/100)=0,"",IF(INT($O$13/100)=1,"Seratus ",VLOOKUP(INT($O$13/100),HELPER!$A$3:$B$22,2,0)&" Ratus "))&IF(MOD($O$13,100)=0,"",IF(MOD($O$13,100)<20,VLOOKUP(MOD($O$13,100),HELPER!$A$3:$B$22,2,0),VLOOKUP(INT(MOD($O$13,100)/10),HELPER!$A$3:$B$22,2,0)&" Puluh "&IF(MOD($O$13,10)=0,"",VLOOKUP(MOD($O$13,10),HELPER!$A$3:$B$22,2,0))))))&" Rupiah ==")
A15: Menerangkan bahwa kedua belah pihak telah setuju dan sepakat melakukan pemeriksaan pengadaan dan serah terima berdasarkan :
A17: 1 | B17: Kontrak/SPM No. | C17: =": "&INPUT!$B$35&" Tanggal : "&TEXT(INPUT!$B$36,"dd mmmm yyyy")
A18: 2 | B18: Nilai Kontrak | C18: =": Rp "&HELPER!$I$28&" (Exclude PPN)"
A19: 3 | B19: Waktu Pelaksanaan | C19: =": "&TEXT(INPUT!$B$36,"dd mmmm yyyy")&" s/d "&TEXT(INPUT!$B$37,"dd mmmm yyyy")
A21: Dengan rincian sebagai berikut,
A23: NO. | B23: JENIS ITEM | D23: VOLUME KONTRAK | E23: SAT | F23: PROGRES REAL VOLUME | J23: HARGA (Rp) | K23: JUMLAH HARGA (Rp)
F24: YG LALU | G24: SAAT INI | H24: SD. SAAT INI | I24: SISA
A25: 1 | B25: 2 | D25: 3 | E25: 4 | F25: 5 | G25: 6 | H25: 7=5+6 | I25: 8=3-7 | J25: 9 | K25: 10 = 6 x 9
A26: =IF(ITEM!$B4="","",ITEM!$A4) | B26: =IF(ITEM!$B4="","",ITEM!$B4) | D26: =IF(ITEM!$B4="","",ITEM!$D4) | E26: =IF(ITEM!$B4="","",ITEM!$C4) | F26: {=IF(ITEM!$B4="","",SUMPRODUCT((COLUMN(ITEM!$G4:$J4)-COLUMN(ITEM!$G4)+1<$O$1)*ITEM!$G4:$J4))} | G26: {=IF(ITEM!$B4="","",INDEX(ITEM!$G4:$J4,1,$O$1))} | H26: =IF(ITEM!$B4="","",$F26+$G26) | I26: =IF(ITEM!$B4="","",$D26-$H26) | J26: =IF(ITEM!$B4="","",ITEM!$E4) | K26: =IF(ITEM!$B4="","",$G26*$J26)
A27: =IF(ITEM!$B5="","",ITEM!$A5) | B27: =IF(ITEM!$B5="","",ITEM!$B5) | D27: =IF(ITEM!$B5="","",ITEM!$D5) | E27: =IF(ITEM!$B5="","",ITEM!$C5) | F27: {=IF(ITEM!$B5="","",SUMPRODUCT((COLUMN(ITEM!$G5:$J5)-COLUMN(ITEM!$G5)+1<$O$1)*ITEM!$G5:$J5))} | G27: {=IF(ITEM!$B5="","",INDEX(ITEM!$G5:$J5,1,$O$1))} | H27: =IF(ITEM!$B5="","",$F27+$G27) | I27: =IF(ITEM!$B5="","",$D27-$H27) | J27: =IF(ITEM!$B5="","",ITEM!$E5) | K27: =IF(ITEM!$B5="","",$G27*$J27)
A28: =IF(ITEM!$B6="","",ITEM!$A6) | B28: =IF(ITEM!$B6="","",ITEM!$B6) | D28: =IF(ITEM!$B6="","",ITEM!$D6) | E28: =IF(ITEM!$B6="","",ITEM!$C6) | F28: {=IF(ITEM!$B6="","",SUMPRODUCT((COLUMN(ITEM!$G6:$J6)-COLUMN(ITEM!$G6)+1<$O$1)*ITEM!$G6:$J6))} | G28: {=IF(ITEM!$B6="","",INDEX(ITEM!$G6:$J6,1,$O$1))} | H28: =IF(ITEM!$B6="","",$F28+$G28) | I28: =IF(ITEM!$B6="","",$D28-$H28) | J28: =IF(ITEM!$B6="","",ITEM!$E6) | K28: =IF(ITEM!$B6="","",$G28*$J28)
A29: =IF(ITEM!$B7="","",ITEM!$A7) | B29: =IF(ITEM!$B7="","",ITEM!$B7) | D29: =IF(ITEM!$B7="","",ITEM!$D7) | E29: =IF(ITEM!$B7="","",ITEM!$C7) | F29: {=IF(ITEM!$B7="","",SUMPRODUCT((COLUMN(ITEM!$G7:$J7)-COLUMN(ITEM!$G7)+1<$O$1)*ITEM!$G7:$J7))} | G29: {=IF(ITEM!$B7="","",INDEX(ITEM!$G7:$J7,1,$O$1))} | H29: =IF(ITEM!$B7="","",$F29+$G29) | I29: =IF(ITEM!$B7="","",$D29-$H29) | J29: =IF(ITEM!$B7="","",ITEM!$E7) | K29: =IF(ITEM!$B7="","",$G29*$J29)
A30: =IF(ITEM!$B8="","",ITEM!$A8) | B30: =IF(ITEM!$B8="","",ITEM!$B8) | D30: =IF(ITEM!$B8="","",ITEM!$D8) | E30: =IF(ITEM!$B8="","",ITEM!$C8) | F30: {=IF(ITEM!$B8="","",SUMPRODUCT((COLUMN(ITEM!$G8:$J8)-COLUMN(ITEM!$G8)+1<$O$1)*ITEM!$G8:$J8))} | G30: {=IF(ITEM!$B8="","",INDEX(ITEM!$G8:$J8,1,$O$1))} | H30: =IF(ITEM!$B8="","",$F30+$G30) | I30: =IF(ITEM!$B8="","",$D30-$H30) | J30: =IF(ITEM!$B8="","",ITEM!$E8) | K30: =IF(ITEM!$B8="","",$G30*$J30)
A31: =IF(ITEM!$B9="","",ITEM!$A9) | B31: =IF(ITEM!$B9="","",ITEM!$B9) | D31: =IF(ITEM!$B9="","",ITEM!$D9) | E31: =IF(ITEM!$B9="","",ITEM!$C9) | F31: {=IF(ITEM!$B9="","",SUMPRODUCT((COLUMN(ITEM!$G9:$J9)-COLUMN(ITEM!$G9)+1<$O$1)*ITEM!$G9:$J9))} | G31: {=IF(ITEM!$B9="","",INDEX(ITEM!$G9:$J9,1,$O$1))} | H31: =IF(ITEM!$B9="","",$F31+$G31) | I31: =IF(ITEM!$B9="","",$D31-$H31) | J31: =IF(ITEM!$B9="","",ITEM!$E9) | K31: =IF(ITEM!$B9="","",$G31*$J31)
A32: =IF(ITEM!$B10="","",ITEM!$A10) | B32: =IF(ITEM!$B10="","",ITEM!$B10) | D32: =IF(ITEM!$B10="","",ITEM!$D10) | E32: =IF(ITEM!$B10="","",ITEM!$C10) | F32: {=IF(ITEM!$B10="","",SUMPRODUCT((COLUMN(ITEM!$G10:$J10)-COLUMN(ITEM!$G10)+1<$O$1)*ITEM!$G10:$J10))} | G32: {=IF(ITEM!$B10="","",INDEX(ITEM!$G10:$J10,1,$O$1))} | H32: =IF(ITEM!$B10="","",$F32+$G32) | I32: =IF(ITEM!$B10="","",$D32-$H32) | J32: =IF(ITEM!$B10="","",ITEM!$E10) | K32: =IF(ITEM!$B10="","",$G32*$J32)
A33: =IF(ITEM!$B11="","",ITEM!$A11) | B33: =IF(ITEM!$B11="","",ITEM!$B11) | D33: =IF(ITEM!$B11="","",ITEM!$D11) | E33: =IF(ITEM!$B11="","",ITEM!$C11) | F33: {=IF(ITEM!$B11="","",SUMPRODUCT((COLUMN(ITEM!$G11:$J11)-COLUMN(ITEM!$G11)+1<$O$1)*ITEM!$G11:$J11))} | G33: {=IF(ITEM!$B11="","",INDEX(ITEM!$G11:$J11,1,$O$1))} | H33: =IF(ITEM!$B11="","",$F33+$G33) | I33: =IF(ITEM!$B11="","",$D33-$H33) | J33: =IF(ITEM!$B11="","",ITEM!$E11) | K33: =IF(ITEM!$B11="","",$G33*$J33)
A34: =IF(ITEM!$B12="","",ITEM!$A12) | B34: =IF(ITEM!$B12="","",ITEM!$B12) | D34: =IF(ITEM!$B12="","",ITEM!$D12) | E34: =IF(ITEM!$B12="","",ITEM!$C12) | F34: {=IF(ITEM!$B12="","",SUMPRODUCT((COLUMN(ITEM!$G12:$J12)-COLUMN(ITEM!$G12)+1<$O$1)*ITEM!$G12:$J12))} | G34: {=IF(ITEM!$B12="","",INDEX(ITEM!$G12:$J12,1,$O$1))} | H34: =IF(ITEM!$B12="","",$F34+$G34) | I34: =IF(ITEM!$B12="","",$D34-$H34) | J34: =IF(ITEM!$B12="","",ITEM!$E12) | K34: =IF(ITEM!$B12="","",$G34*$J34)
A35: =IF(ITEM!$B13="","",ITEM!$A13) | B35: =IF(ITEM!$B13="","",ITEM!$B13) | D35: =IF(ITEM!$B13="","",ITEM!$D13) | E35: =IF(ITEM!$B13="","",ITEM!$C13) | F35: {=IF(ITEM!$B13="","",SUMPRODUCT((COLUMN(ITEM!$G13:$J13)-COLUMN(ITEM!$G13)+1<$O$1)*ITEM!$G13:$J13))} | G35: {=IF(ITEM!$B13="","",INDEX(ITEM!$G13:$J13,1,$O$1))} | H35: =IF(ITEM!$B13="","",$F35+$G35) | I35: =IF(ITEM!$B13="","",$D35-$H35) | J35: =IF(ITEM!$B13="","",ITEM!$E13) | K35: =IF(ITEM!$B13="","",$G35*$J35)
A36: =IF(ITEM!$B14="","",ITEM!$A14) | B36: =IF(ITEM!$B14="","",ITEM!$B14) | D36: =IF(ITEM!$B14="","",ITEM!$D14) | E36: =IF(ITEM!$B14="","",ITEM!$C14) | F36: {=IF(ITEM!$B14="","",SUMPRODUCT((COLUMN(ITEM!$G14:$J14)-COLUMN(ITEM!$G14)+1<$O$1)*ITEM!$G14:$J14))} | G36: {=IF(ITEM!$B14="","",INDEX(ITEM!$G14:$J14,1,$O$1))} | H36: =IF(ITEM!$B14="","",$F36+$G36) | I36: =IF(ITEM!$B14="","",$D36-$H36) | J36: =IF(ITEM!$B14="","",ITEM!$E14) | K36: =IF(ITEM!$B14="","",$G36*$J36)
A37: =IF(ITEM!$B15="","",ITEM!$A15) | B37: =IF(ITEM!$B15="","",ITEM!$B15) | D37: =IF(ITEM!$B15="","",ITEM!$D15) | E37: =IF(ITEM!$B15="","",ITEM!$C15) | F37: {=IF(ITEM!$B15="","",SUMPRODUCT((COLUMN(ITEM!$G15:$J15)-COLUMN(ITEM!$G15)+1<$O$1)*ITEM!$G15:$J15))} | G37: {=IF(ITEM!$B15="","",INDEX(ITEM!$G15:$J15,1,$O$1))} | H37: =IF(ITEM!$B15="","",$F37+$G37) | I37: =IF(ITEM!$B15="","",$D37-$H37) | J37: =IF(ITEM!$B15="","",ITEM!$E15) | K37: =IF(ITEM!$B15="","",$G37*$J37)
... A125: =IF(ITEM!$B103="","",ITEM!$A103) | B125: =IF(ITEM!$B103="","",ITEM!$B103) | D125: =IF(ITEM!$B103="","",ITEM!$D103) | E125: =IF(ITEM!$B103="","",ITEM!$C103) | F125: {=IF(ITEM!$B103="","",SUMPRODUCT((COLUMN(ITEM!$G103:$J103)-COLUMN(ITEM!$G103)+1<$O$1)*ITEM!$G103:$J103))} | G125: {=IF(ITEM!$B103="","",INDEX(ITEM!$G103:$J103,1,$O$1))} | H125: =IF(ITEM!$B103="","",$F125+$G125) | I125: =IF(ITEM!$B103="","",$D125-$H125) | J125: =IF(ITEM!$B103="","",ITEM!$E103) | K125: =IF(ITEM!$B103="","",$G125*$J125)
A126: JUMLAH | K126: =SUM(K26:K125)
A128: Maka Pihak Kedua berhak menerima pembayaran dengan perhitungan sebagai berikut :
A129: 1 | B129: Prestasi s/d saat ini | G129: : | H129: =IF(ITEM!$C$107=0,0,SUMPRODUCT($H$26:$H$125,$J$26:$J$125)/ITEM!$C$107) | I129: = | K129: =ROUND(H129*ITEM!$C$107,0)
A130: 2 | B130: Prestasi yang lalu | G130: : | H130: =IF(ITEM!$C$107=0,0,SUMPRODUCT($F$26:$F$125,$J$26:$J$125)/ITEM!$C$107) | I130: = | K130: =ROUND(H130*ITEM!$C$107,0)
A131: 3 | B131: Prestasi yang dapat dibayarkan | G131: : | H131: =H129-H130 | I131: = | K131: =K129-K130
...

Sheet BAPM 4
N1: TERMIN SHEET INI (jangan diubah kecuali perlu) | O1: 4
N2: Tanggal BAPM/BAP | O2: {=IF(IFERROR(INDEX(INPUT!$B$55:$B$58,$O$1),0)=0,"",INDEX(INPUT!$B$55:$B$58,$O$1))}
N3: Hari | O3: =IF($O$2="","",TEXT($O$2,"dddd"))
N4: Tanggal (huruf) | O4: =IF($O$2="","",IF(DAY($O$2)<20,VLOOKUP(DAY($O$2),HELPER!$A$3:$B$22,2,0),IF(DAY($O$2)<30,TRIM("Dua Puluh "&VLOOKUP(DAY($O$2)-20,HELPER!$A$3:$B$22,2,0)),TRIM("Tiga Puluh "&VLOOKUP(DAY($O$2)-30,HELPER!$A$3:$B$22,2,0)))))
A5: BERITA ACARA PENERIMAAN MATERIAL (BAPM) | N5: Bulan | O5: =IF($O$2="","",TEXT($O$2,"mmmm"))
A6: {=IF($O$2="","","Nomor : "&INDEX(INPUT!$C$55:$C$58,$O$1))} | N6: Tahun (huruf) | O6: =IF($O$2="","",TRIM(IF(INT(YEAR($O$2)/1000)=1,"Seribu ",IF(INT(YEAR($O$2)/1000)=0,"",IF(INT(INT(YEAR($O$2)/1000)/100)=0,"",IF(INT(INT(YEAR($O$2)/1000)/100)=1,"Seratus ",VLOOKUP(INT(INT(YEAR($O$2)/1000)/100),HELPER!$A$3:$B$22,2,0)&" Ratus "))&IF(MOD(INT(YEAR($O$2)/1000),100)=0,"",IF(MOD(INT(YEAR($O$2)/1000),100)<20,VLOOKUP(MOD(INT(YEAR($O$2)/1000),100),HELPER!$A$3:$B$22,2,0),VLOOKUP(INT(MOD(INT(YEAR($O$2)/1000),100)/10),HELPER!$A$3:$B$22,2,0)&" Puluh "&IF(MOD(INT(YEAR($O$2)/1000),10)=0,"",VLOOKUP(MOD(INT(YEAR($O$2)/1000),10),HELPER!$A$3:$B$22,2,0)))))&" Ribu ")&IF(MOD(YEAR($O$2),1000)=0,"",IF(INT(MOD(YEAR($O$2),1000)/100)=0,"",IF(INT(MOD(YEAR($O$2),1000)/100)=1,"Seratus ",VLOOKUP(INT(MOD(YEAR($O$2),1000)/100),HELPER!$A$3:$B$22,2,0)&" Ratus "))&IF(MOD(MOD(YEAR($O$2),1000),100)=0,"",IF(MOD(MOD(YEAR($O$2),1000),100)<20,VLOOKUP(MOD(MOD(YEAR($O$2),1000),100),HELPER!$A$3:$B$22,2,0),VLOOKUP(INT(MOD(MOD(YEAR($O$2),1000),100)/10),HELPER!$A$3:$B$22,2,0)&" Puluh "&IF(MOD(MOD(YEAR($O$2),1000),10)=0,"",VLOOKUP(MOD(MOD(YEAR($O$2),1000),10),HELPER!$A$3:$B$22,2,0)))))))
N7: Kalimat pembuka | O7: =IF($O$2="","","Pada hari ini "&$O$3&", tanggal "&$O$4&" bulan "&$O$5&" tahun "&$O$6&" ("&TEXT($O$2,"dd/mm/yyyy")&")")
A8: =IF($O$7="","",$O$7&", telah diterima alat :")
N9: Nilai diterima | O9: =$K$135
A10: I. | B10: Dari | C10: =": "&UPPER(INPUT!$B$24) | N10: Kelompok miliar | O10: =INT(ROUND($O$9,0)/1000000000)
C11: ="Sebagai Pihak Kedua" | N11: Kelompok juta | O11: =MOD(INT(ROUND($O$9,0)/1000000),1000)
A12: II. | B12: Kepada | C12: =": "&UPPER(INPUT!$B$6)&" Proyek Pekerjaan "&INPUT!$B$5 | N12: Kelompok ribu | O12: =MOD(INT(ROUND($O$9,0)/1000),1000)
C13: ="Sebagai Pihak Pertama" | N13: Kelompok satuan | O13: =MOD(ROUND($O$9,0),1000)
N14: Terbilang | O14: =IF(ROUND($O$9,0)=0,"== Nol Rupiah ==","== "&TRIM(IF($O$10=0,"",IF($O$10=0,"",IF(INT($O$10/100)=0,"",IF(INT($O$10/100)=1,"Seratus ",VLOOKUP(INT($O$10/100),HELPER!$A$3:$B$22,2,0)&" Ratus "))&IF(MOD($O$10,100)=0,"",IF(MOD($O$10,100)<20,VLOOKUP(MOD($O$10,100),HELPER!$A$3:$B$22,2,0),VLOOKUP(INT(MOD($O$10,100)/10),HELPER!$A$3:$B$22,2,0)&" Puluh "&IF(MOD($O$10,10)=0,"",VLOOKUP(MOD($O$10,10),HELPER!$A$3:$B$22,2,0)))))&" Miliar ")&IF($O$11=0,"",IF($O$11=1,"Satu Juta ",IF($O$11=0,"",IF(INT($O$11/100)=0,"",IF(INT($O$11/100)=1,"Seratus ",VLOOKUP(INT($O$11/100),HELPER!$A$3:$B$22,2,0)&" Ratus "))&IF(MOD($O$11,100)=0,"",IF(MOD($O$11,100)<20,VLOOKUP(MOD($O$11,100),HELPER!$A$3:$B$22,2,0),VLOOKUP(INT(MOD($O$11,100)/10),HELPER!$A$3:$B$22,2,0)&" Puluh "&IF(MOD($O$11,10)=0,"",VLOOKUP(MOD($O$11,10),HELPER!$A$3:$B$22,2,0)))))&" Juta "))&IF($O$12=0,"",IF($O$12=1,"Seribu ",IF($O$12=0,"",IF(INT($O$12/100)=0,"",IF(INT($O$12/100)=1,"Seratus ",VLOOKUP(INT($O$12/100),HELPER!$A$3:$B$22,2,0)&" Ratus "))&IF(MOD($O$12,100)=0,"",IF(MOD($O$12,100)<20,VLOOKUP(MOD($O$12,100),HELPER!$A$3:$B$22,2,0),VLOOKUP(INT(MOD($O$12,100)/10),HELPER!$A$3:$B$22,2,0)&" Puluh "&IF(MOD($O$12,10)=0,"",VLOOKUP(MOD($O$12,10),HELPER!$A$3:$B$22,2,0)))))&" Ribu "))&IF($O$13=0,"",IF(INT($O$13/100)=0,"",IF(INT($O$13/100)=1,"Seratus ",VLOOKUP(INT($O$13/100),HELPER!$A$3:$B$22,2,0)&" Ratus "))&IF(MOD($O$13,100)=0,"",IF(MOD($O$13,100)<20,VLOOKUP(MOD($O$13,100),HELPER!$A$3:$B$22,2,0),VLOOKUP(INT(MOD($O$13,100)/10),HELPER!$A$3:$B$22,2,0)&" Puluh "&IF(MOD($O$13,10)=0,"",VLOOKUP(MOD($O$13,10),HELPER!$A$3:$B$22,2,0))))))&" Rupiah ==")
A15: Menerangkan bahwa kedua belah pihak telah setuju dan sepakat melakukan pemeriksaan pengadaan dan serah terima berdasarkan :
A17: 1 | B17: Kontrak/SPM No. | C17: =": "&INPUT!$B$35&" Tanggal : "&TEXT(INPUT!$B$36,"dd mmmm yyyy")
A18: 2 | B18: Nilai Kontrak | C18: =": Rp "&HELPER!$I$28&" (Exclude PPN)"
A19: 3 | B19: Waktu Pelaksanaan | C19: =": "&TEXT(INPUT!$B$36,"dd mmmm yyyy")&" s/d "&TEXT(INPUT!$B$37,"dd mmmm yyyy")
A21: Dengan rincian sebagai berikut,
A23: NO. | B23: JENIS ITEM | D23: VOLUME KONTRAK | E23: SAT | F23: PROGRES REAL VOLUME | J23: HARGA (Rp) | K23: JUMLAH HARGA (Rp)
F24: YG LALU | G24: SAAT INI | H24: SD. SAAT INI | I24: SISA
A25: 1 | B25: 2 | D25: 3 | E25: 4 | F25: 5 | G25: 6 | H25: 7=5+6 | I25: 8=3-7 | J25: 9 | K25: 10 = 6 x 9
A26: =IF(ITEM!$B4="","",ITEM!$A4) | B26: =IF(ITEM!$B4="","",ITEM!$B4) | D26: =IF(ITEM!$B4="","",ITEM!$D4) | E26: =IF(ITEM!$B4="","",ITEM!$C4) | F26: {=IF(ITEM!$B4="","",SUMPRODUCT((COLUMN(ITEM!$G4:$J4)-COLUMN(ITEM!$G4)+1<$O$1)*ITEM!$G4:$J4))} | G26: {=IF(ITEM!$B4="","",INDEX(ITEM!$G4:$J4,1,$O$1))} | H26: =IF(ITEM!$B4="","",$F26+$G26) | I26: =IF(ITEM!$B4="","",$D26-$H26) | J26: =IF(ITEM!$B4="","",ITEM!$E4) | K26: =IF(ITEM!$B4="","",$G26*$J26)
A27: =IF(ITEM!$B5="","",ITEM!$A5) | B27: =IF(ITEM!$B5="","",ITEM!$B5) | D27: =IF(ITEM!$B5="","",ITEM!$D5) | E27: =IF(ITEM!$B5="","",ITEM!$C5) | F27: {=IF(ITEM!$B5="","",SUMPRODUCT((COLUMN(ITEM!$G5:$J5)-COLUMN(ITEM!$G5)+1<$O$1)*ITEM!$G5:$J5))} | G27: {=IF(ITEM!$B5="","",INDEX(ITEM!$G5:$J5,1,$O$1))} | H27: =IF(ITEM!$B5="","",$F27+$G27) | I27: =IF(ITEM!$B5="","",$D27-$H27) | J27: =IF(ITEM!$B5="","",ITEM!$E5) | K27: =IF(ITEM!$B5="","",$G27*$J27)
A28: =IF(ITEM!$B6="","",ITEM!$A6) | B28: =IF(ITEM!$B6="","",ITEM!$B6) | D28: =IF(ITEM!$B6="","",ITEM!$D6) | E28: =IF(ITEM!$B6="","",ITEM!$C6) | F28: {=IF(ITEM!$B6="","",SUMPRODUCT((COLUMN(ITEM!$G6:$J6)-COLUMN(ITEM!$G6)+1<$O$1)*ITEM!$G6:$J6))} | G28: {=IF(ITEM!$B6="","",INDEX(ITEM!$G6:$J6,1,$O$1))} | H28: =IF(ITEM!$B6="","",$F28+$G28) | I28: =IF(ITEM!$B6="","",$D28-$H28) | J28: =IF(ITEM!$B6="","",ITEM!$E6) | K28: =IF(ITEM!$B6="","",$G28*$J28)
A29: =IF(ITEM!$B7="","",ITEM!$A7) | B29: =IF(ITEM!$B7="","",ITEM!$B7) | D29: =IF(ITEM!$B7="","",ITEM!$D7) | E29: =IF(ITEM!$B7="","",ITEM!$C7) | F29: {=IF(ITEM!$B7="","",SUMPRODUCT((COLUMN(ITEM!$G7:$J7)-COLUMN(ITEM!$G7)+1<$O$1)*ITEM!$G7:$J7))} | G29: {=IF(ITEM!$B7="","",INDEX(ITEM!$G7:$J7,1,$O$1))} | H29: =IF(ITEM!$B7="","",$F29+$G29) | I29: =IF(ITEM!$B7="","",$D29-$H29) | J29: =IF(ITEM!$B7="","",ITEM!$E7) | K29: =IF(ITEM!$B7="","",$G29*$J29)
A30: =IF(ITEM!$B8="","",ITEM!$A8) | B30: =IF(ITEM!$B8="","",ITEM!$B8) | D30: =IF(ITEM!$B8="","",ITEM!$D8) | E30: =IF(ITEM!$B8="","",ITEM!$C8) | F30: {=IF(ITEM!$B8="","",SUMPRODUCT((COLUMN(ITEM!$G8:$J8)-COLUMN(ITEM!$G8)+1<$O$1)*ITEM!$G8:$J8))} | G30: {=IF(ITEM!$B8="","",INDEX(ITEM!$G8:$J8,1,$O$1))} | H30: =IF(ITEM!$B8="","",$F30+$G30) | I30: =IF(ITEM!$B8="","",$D30-$H30) | J30: =IF(ITEM!$B8="","",ITEM!$E8) | K30: =IF(ITEM!$B8="","",$G30*$J30)
A31: =IF(ITEM!$B9="","",ITEM!$A9) | B31: =IF(ITEM!$B9="","",ITEM!$B9) | D31: =IF(ITEM!$B9="","",ITEM!$D9) | E31: =IF(ITEM!$B9="","",ITEM!$C9) | F31: {=IF(ITEM!$B9="","",SUMPRODUCT((COLUMN(ITEM!$G9:$J9)-COLUMN(ITEM!$G9)+1<$O$1)*ITEM!$G9:$J9))} | G31: {=IF(ITEM!$B9="","",INDEX(ITEM!$G9:$J9,1,$O$1))} | H31: =IF(ITEM!$B9="","",$F31+$G31) | I31: =IF(ITEM!$B9="","",$D31-$H31) | J31: =IF(ITEM!$B9="","",ITEM!$E9) | K31: =IF(ITEM!$B9="","",$G31*$J31)
A32: =IF(ITEM!$B10="","",ITEM!$A10) | B32: =IF(ITEM!$B10="","",ITEM!$B10) | D32: =IF(ITEM!$B10="","",ITEM!$D10) | E32: =IF(ITEM!$B10="","",ITEM!$C10) | F32: {=IF(ITEM!$B10="","",SUMPRODUCT((COLUMN(ITEM!$G10:$J10)-COLUMN(ITEM!$G10)+1<$O$1)*ITEM!$G10:$J10))} | G32: {=IF(ITEM!$B10="","",INDEX(ITEM!$G10:$J10,1,$O$1))} | H32: =IF(ITEM!$B10="","",$F32+$G32) | I32: =IF(ITEM!$B10="","",$D32-$H32) | J32: =IF(ITEM!$B10="","",ITEM!$E10) | K32: =IF(ITEM!$B10="","",$G32*$J32)
A33: =IF(ITEM!$B11="","",ITEM!$A11) | B33: =IF(ITEM!$B11="","",ITEM!$B11) | D33: =IF(ITEM!$B11="","",ITEM!$D11) | E33: =IF(ITEM!$B11="","",ITEM!$C11) | F33: {=IF(ITEM!$B11="","",SUMPRODUCT((COLUMN(ITEM!$G11:$J11)-COLUMN(ITEM!$G11)+1<$O$1)*ITEM!$G11:$J11))} | G33: {=IF(ITEM!$B11="","",INDEX(ITEM!$G11:$J11,1,$O$1))} | H33: =IF(ITEM!$B11="","",$F33+$G33) | I33: =IF(ITEM!$B11="","",$D33-$H33) | J33: =IF(ITEM!$B11="","",ITEM!$E11) | K33: =IF(ITEM!$B11="","",$G33*$J33)
A34: =IF(ITEM!$B12="","",ITEM!$A12) | B34: =IF(ITEM!$B12="","",ITEM!$B12) | D34: =IF(ITEM!$B12="","",ITEM!$D12) | E34: =IF(ITEM!$B12="","",ITEM!$C12) | F34: {=IF(ITEM!$B12="","",SUMPRODUCT((COLUMN(ITEM!$G12:$J12)-COLUMN(ITEM!$G12)+1<$O$1)*ITEM!$G12:$J12))} | G34: {=IF(ITEM!$B12="","",INDEX(ITEM!$G12:$J12,1,$O$1))} | H34: =IF(ITEM!$B12="","",$F34+$G34) | I34: =IF(ITEM!$B12="","",$D34-$H34) | J34: =IF(ITEM!$B12="","",ITEM!$E12) | K34: =IF(ITEM!$B12="","",$G34*$J34)
A35: =IF(ITEM!$B13="","",ITEM!$A13) | B35: =IF(ITEM!$B13="","",ITEM!$B13) | D35: =IF(ITEM!$B13="","",ITEM!$D13) | E35: =IF(ITEM!$B13="","",ITEM!$C13) | F35: {=IF(ITEM!$B13="","",SUMPRODUCT((COLUMN(ITEM!$G13:$J13)-COLUMN(ITEM!$G13)+1<$O$1)*ITEM!$G13:$J13))} | G35: {=IF(ITEM!$B13="","",INDEX(ITEM!$G13:$J13,1,$O$1))} | H35: =IF(ITEM!$B13="","",$F35+$G35) | I35: =IF(ITEM!$B13="","",$D35-$H35) | J35: =IF(ITEM!$B13="","",ITEM!$E13) | K35: =IF(ITEM!$B13="","",$G35*$J35)
A36: =IF(ITEM!$B14="","",ITEM!$A14) | B36: =IF(ITEM!$B14="","",ITEM!$B14) | D36: =IF(ITEM!$B14="","",ITEM!$D14) | E36: =IF(ITEM!$B14="","",ITEM!$C14) | F36: {=IF(ITEM!$B14="","",SUMPRODUCT((COLUMN(ITEM!$G14:$J14)-COLUMN(ITEM!$G14)+1<$O$1)*ITEM!$G14:$J14))} | G36: {=IF(ITEM!$B14="","",INDEX(ITEM!$G14:$J14,1,$O$1))} | H36: =IF(ITEM!$B14="","",$F36+$G36) | I36: =IF(ITEM!$B14="","",$D36-$H36) | J36: =IF(ITEM!$B14="","",ITEM!$E14) | K36: =IF(ITEM!$B14="","",$G36*$J36)
A37: =IF(ITEM!$B15="","",ITEM!$A15) | B37: =IF(ITEM!$B15="","",ITEM!$B15) | D37: =IF(ITEM!$B15="","",ITEM!$D15) | E37: =IF(ITEM!$B15="","",ITEM!$C15) | F37: {=IF(ITEM!$B15="","",SUMPRODUCT((COLUMN(ITEM!$G15:$J15)-COLUMN(ITEM!$G15)+1<$O$1)*ITEM!$G15:$J15))} | G37: {=IF(ITEM!$B15="","",INDEX(ITEM!$G15:$J15,1,$O$1))} | H37: =IF(ITEM!$B15="","",$F37+$G37) | I37: =IF(ITEM!$B15="","",$D37-$H37) | J37: =IF(ITEM!$B15="","",ITEM!$E15) | K37: =IF(ITEM!$B15="","",$G37*$J37)
... A125: =IF(ITEM!$B103="","",ITEM!$A103) | B125: =IF(ITEM!$B103="","",ITEM!$B103) | D125: =IF(ITEM!$B103="","",ITEM!$D103) | E125: =IF(ITEM!$B103="","",ITEM!$C103) | F125: {=IF(ITEM!$B103="","",SUMPRODUCT((COLUMN(ITEM!$G103:$J103)-COLUMN(ITEM!$G103)+1<$O$1)*ITEM!$G103:$J103))} | G125: {=IF(ITEM!$B103="","",INDEX(ITEM!$G103:$J103,1,$O$1))} | H125: =IF(ITEM!$B103="","",$F125+$G125) | I125: =IF(ITEM!$B103="","",$D125-$H125) | J125: =IF(ITEM!$B103="","",ITEM!$E103) | K125: =IF(ITEM!$B103="","",$G125*$J125)
A126: JUMLAH | K126: =SUM(K26:K125)
